<?xml version="1.0"?>
<robot name="" xmlns:xi="http://www.w3.org/2001/Xinclude" xmlns:gazebo="http://playerstage.sourceforge.net/gazebo/xmlschema/#gz" xmlns:model="http://playerstage.sourceforge.net/gazebo/xmlschema/#model" xmlns:sensor="http://playerstage.sourceforge.net/gazebo/xmlschema/#sensor" xmlns:body="http://playerstage.sourceforge.net/gazebo/xmlschema/#body" xmlns:geom="http://playerstage.sourceforge.net/gazebo/xmlschema/#geom" xmlns:joint="http://playerstage.sourceforge.net/gazebo/xmlschema/#joint" xmlns:interface="http://playerstage.sourceforge.net/gazebo/xmlschema/#interface" xmlns:rendering="http://playerstage.sourceforge.net/gazebo/xmlschema/#rendering" xmlns:renderable="http://playerstage.sourceforge.net/gazebo/xmlschema/#renderable" xmlns:controller="http://playerstage.sourceforge.net/gazebo/xmlschema/#controller" xmlns:physics="http://playerstage.sourceforge.net/gazebo/xmlschema/#physics" xmlns:xacro="http://www.ros.org/wiki/xacro">
 <xacro:macro name="gz_trans_pos" params="joint_name">
  <transmission name="${joint_name}_trans">
   <type>transmission_interface/SimpleTransmission</type>
   <joint name="${joint_name}">
    <hardwareInterface>hardware_interface/PositionJointInterface</hardwareInterface>
   </joint>
   <actuator name="${joint_name}_motor">
    <hardwareInterface>hardware_interface/PositionJointInterface</hardwareInterface>
   </actuator>
  </transmission>
 </xacro:macro>
 <xacro:macro name="gz_trans_vel" params="joint_name">
  <transmission name="${joint_name}_trans">
   <type>transmission_interface/SimpleTransmission</type>
   <joint name="${joint_name}">
    <hardwareInterface>hardware_interface/VelocityJointInterface</hardwareInterface>
   </joint>
   <actuator name="${joint_name}_motor">
    <hardwareInterface>hardware_interface/VelocityJointInterface</hardwareInterface>
   </actuator>
  </transmission>
 </xacro:macro>
 <xacro:macro name="gz_trans_eff" params="joint_name">
  <transmission name="${joint_name}_trans">
   <type>transmission_interface/SimpleTransmission</type>
   <joint name="${joint_name}">
    <hardwareInterface>hardware_interface/EffortJointInterface</hardwareInterface>
   </joint>
   <actuator name="${joint_name}_motor">
    <hardwareInterface>hardware_interface/EffortJointInterface</hardwareInterface>
   </actuator>
  </transmission>
 </xacro:macro>
 <link name="base">
  <visual>
   <origin xyz="3.800000000000e-02 6.245000000000e-02 1.727000000000e-01" rpy="3.141592653590e+00 -1.224646799147e-16 3.141592653590e+00" />
   <geometry>
    <box size="5.800000000000e-02 5.800000000000e-02 2.200000000000e-02" />
   </geometry>
   <material name="mat__0">
    <color rgba="1 0.423529 0.0392157 1" />
   </material>
  </visual>
  <visual>
   <geometry>
    <mesh filename="file:///tmp/_base.dae" />
   </geometry>
  </visual>
  <collision>
   <origin xyz="0.000000000000e+00 0.000000000000e+00 8.000000000000e-02" rpy="0.000000000000e+00 -0.000000000000e+00 0.000000000000e+00" />
   <geometry>
    <box size="5.310000000000e-01 2.700000000000e-01 2.400000000000e-01" />
   </geometry>
  </collision>
  <collision>
   <origin xyz="2.270000000000e-01 1.160000000000e-01 0.000000000000e+00" rpy="-0.000000000000e+00 1.570796326790e+00 0.000000000000e+00" />
   <geometry>
    <cylinder radius="0.050000000000000003" length="0.10000000000000001" />
   </geometry>
  </collision>
  <collision>
   <origin xyz="2.270000000000e-01 -1.160000000000e-01 0.000000000000e+00" rpy="-0.000000000000e+00 1.570796326790e+00 0.000000000000e+00" />
   <geometry>
    <cylinder radius="0.050000000000000003" length="0.10000000000000001" />
   </geometry>
  </collision>
  <collision>
   <origin xyz="-2.270000000000e-01 1.160000000000e-01 0.000000000000e+00" rpy="-0.000000000000e+00 1.570796326790e+00 0.000000000000e+00" />
   <geometry>
    <cylinder radius="0.050000000000000003" length="0.10000000000000001" />
   </geometry>
  </collision>
  <collision>
   <origin xyz="-2.270000000000e-01 -1.160000000000e-01 0.000000000000e+00" rpy="-0.000000000000e+00 1.570796326790e+00 0.000000000000e+00" />
   <geometry>
    <cylinder radius="0.050000000000000003" length="0.10000000000000001" />
   </geometry>
  </collision>
  <collision>
   <origin xyz="2.155000000000e-01 0.000000000000e+00 -9.000000000000e-02" rpy="0.000000000000e+00 -0.000000000000e+00 0.000000000000e+00" />
   <geometry>
    <box size="1.000000000000e-01 1.000000000000e-01 7.000000000000e-02" />
   </geometry>
  </collision>
  <collision>
   <origin xyz="-2.155000000000e-01 0.000000000000e+00 -9.000000000000e-02" rpy="0.000000000000e+00 -0.000000000000e+00 0.000000000000e+00" />
   <geometry>
    <box size="1.000000000000e-01 1.000000000000e-01 7.000000000000e-02" />
   </geometry>
  </collision>
  <collision>
   <origin xyz="0.000000000000e+00 0.000000000000e+00 -9.000000000000e-02" rpy="0.000000000000e+00 -0.000000000000e+00 0.000000000000e+00" />
   <geometry>
    <box size="5.310000000000e-01 2.000000000000e-02 7.000000000000e-02" />
   </geometry>
  </collision>
  <collision>
   <origin xyz="3.800000000000e-02 6.245000000000e-02 1.727000000000e-01" rpy="3.141592653590e+00 -1.224646799147e-16 3.141592653590e+00" />
   <geometry>
    <box size="5.800000000000e-02 5.800000000000e-02 2.200000000000e-02" />
   </geometry>
   <material name="mat__1">
    <color rgba="1 0.423529 0.0392157 1" />
   </material>
  </collision>
  <collision>
   <origin xyz="2.692000000000e-01 0.000000000000e+00 9.038000000000e-02" rpy="0.000000000000e+00 -0.000000000000e+00 0.000000000000e+00" />
   <geometry>
    <sphere radius="0.031" />
   </geometry>
  </collision>
  <collision>
   <origin xyz="3.142000000000e-01 0.000000000000e+00 8.275400000000e-02" rpy="0.000000000000e+00 -0.000000000000e+00 0.000000000000e+00" />
   <geometry>
    <sphere radius="0.031" />
   </geometry>
  </collision>
  <collision>
   <geometry>
    <mesh filename="file:///tmp/_base.stl" />
   </geometry>
  </collision>
  <inertial>
   <mass value="17.6904" />
   <origin xyz="1.276730000000e-02 -1.165060000000e-03 5.443690000000e-02" />
   <inertia ixx="0.227714" ixy="-0.00175606" ixz="-0.0228363" iyy="0.72504500000000005" iyz="-0.00188379" izz="0.70021999999999995" />
  </inertial>
 </link>
 <link name="LF_HIP">
  <visual>
   <geometry>
    <mesh filename="file:///tmp/_LF_HIP.dae" />
   </geometry>
  </visual>
  <collision>
   <origin xyz="6.350000000000e-02 -9.000000000000e-03 0.000000000000e+00" rpy="1.570796326790e+00 -0.000000000000e+00 0.000000000000e+00" />
   <geometry>
    <cylinder radius="0.080000000000000002" length="0.10000000000000001" />
   </geometry>
  </collision>
  <collision>
   <origin xyz="6.350000000000e-02 -7.400000000000e-02 0.000000000000e+00" rpy="1.570796326790e+00 -0.000000000000e+00 0.000000000000e+00" />
   <geometry>
    <cylinder radius="0.044999999999999998" length="0.029999999999999999" />
   </geometry>
  </collision>
  <inertial>
   <mass value="1.42462" />
   <origin xyz="6.451630000000e-02 -3.787100000000e-03 -1.521840000000e-04" />
   <inertia ixx="0.0024302299999999998" ixy="-1.5302400000000001e-05" ixz="-2.1819099999999999e-05" iyy="0.0023025699999999999" iyz="2.6472999999999999e-05" izz="0.0019806799999999999" />
  </inertial>
 </link>
 <joint name="LF_HAA" type="revolute">
  <parent link="base" />
  <child link="LF_HIP" />
  <origin xyz="2.770000000000e-01 1.160000000000e-01 0.000000000000e+00" rpy="0.000000000000e+00 -0.000000000000e+00 0.000000000000e+00" />
  <axis xyz="1.000000000000e+00 0.000000000000e+00 0.000000000000e+00" />
  <limit lower="-9.4199957586189154" upper="9.4199957586189154" velocity="15.000005363462506" effort="80" />
 </joint>
 <xacro:gz_trans_pos joint_name="LF_HAA" />
 <link name="LF_THIGH">
  <visual>
   <geometry>
    <mesh filename="file:///tmp/_LF_THIGH.dae" />
   </geometry>
  </visual>
  <collision>
   <origin xyz="0.000000000000e+00 3.500000000000e-02 -1.250000000000e-01" rpy="1.450000000001e-01 -0.000000000000e+00 0.000000000000e+00" />
   <geometry>
    <box size="8.000000000000e-02 4.000000000000e-02 2.500000000000e-01" />
   </geometry>
  </collision>
  <collision>
   <origin xyz="0.000000000000e+00 6.900000000000e-02 -2.500000000000e-01" rpy="1.570796326790e+00 -0.000000000000e+00 0.000000000000e+00" />
   <geometry>
    <cylinder radius="0.059999999999999998" length="0.12" />
   </geometry>
  </collision>
  <collision>
   <origin xyz="0.000000000000e+00 -5.000000000000e-03 0.000000000000e+00" rpy="1.715796326790e+00 -0.000000000000e+00 0.000000000000e+00" />
   <geometry>
    <cylinder radius="0.066000000000000003" length="0.12" />
   </geometry>
  </collision>
  <inertial>
   <mass value="1.6349800000000001" />
   <origin xyz="-3.897970000000e-03 5.422660000000e-02 -2.145830000000e-01" />
   <inertia ixx="0.0120368" ixy="6.7620700000000001e-05" ixz="0.00028780599999999999" iyy="0.012064399999999999" iyz="-0.0014061" izz="0.0024942300000000001" />
  </inertial>
 </link>
 <joint name="LF_HFE" type="revolute">
  <parent link="LF_HIP" />
  <child link="LF_THIGH" />
  <origin xyz="6.350000000000e-02 4.100000000000e-02 0.000000000000e+00" rpy="0.000000000000e+00 -0.000000000000e+00 0.000000000000e+00" />
  <axis xyz="0.000000000000e+00 1.000000000000e+00 0.000000000000e+00" />
  <limit lower="-9.4199957586189154" upper="9.4199957586189154" velocity="15.000005363462506" effort="80" />
 </joint>
 <xacro:gz_trans_pos joint_name="LF_HFE" />
 <link name="LF_SHANK">
  <visual>
   <geometry>
    <mesh filename="file:///tmp/_LF_SHANK.dae" />
   </geometry>
  </visual>
  <collision>
   <origin xyz="6.500000000000e-02 -1.500000000000e-02 1.000000000000e-02" rpy="-0.000000000000e+00 1.570796326790e+00 0.000000000000e+00" />
   <geometry>
    <box size="8.000000000000e-02 7.000000000000e-02 1.300000000000e-01" />
   </geometry>
  </collision>
  <collision>
   <origin xyz="1.000000000000e-01 -2.000000000000e-02 -1.606250000000e-01" rpy="0.000000000000e+00 -0.000000000000e+00 0.000000000000e+00" />
   <geometry>
    <cylinder radius="0.014999999999999999" length="0.32124999999999998" />
   </geometry>
  </collision>
  <collision>
   <origin xyz="1.000000000000e-01 -2.000000000000e-02 -2.980000000000e-01" rpy="0.000000000000e+00 -0.000000000000e+00 0.000000000000e+00" />
   <geometry>
    <sphere radius="0.031" />
   </geometry>
  </collision>
  <inertial>
   <mass value="0.34837499999999999" />
   <origin xyz="5.885170000000e-02 -1.085070000000e-02 -9.870490000000e-02" />
   <inertia ixx="0.0069083800000000004" ixy="3.2606600000000001e-05" ixz="0.0014378699999999999" iyy="0.0077561699999999997" iyz="-0.00031827899999999998" izz="0.00102169" />
  </inertial>
 </link>
 <joint name="LF_KFE" type="revolute">
  <parent link="LF_THIGH" />
  <child link="LF_SHANK" />
  <origin xyz="0.000000000000e+00 1.090000000000e-01 -2.500000000000e-01" rpy="0.000000000000e+00 -0.000000000000e+00 0.000000000000e+00" />
  <axis xyz="0.000000000000e+00 1.000000000000e+00 0.000000000000e+00" />
  <limit lower="-9.4199957586189154" upper="9.4199957586189154" velocity="15.000005363462506" effort="80" />
 </joint>
 <xacro:gz_trans_pos joint_name="LF_KFE" />
 <link name="RF_HIP">
  <visual>
   <geometry>
    <mesh filename="file:///tmp/_RF_HIP.dae" />
   </geometry>
  </visual>
  <collision>
   <origin xyz="6.350000000000e-02 9.000000000000e-03 0.000000000000e+00" rpy="1.570796326790e+00 -0.000000000000e+00 0.000000000000e+00" />
   <geometry>
    <cylinder radius="0.080000000000000002" length="0.10000000000000001" />
   </geometry>
  </collision>
  <collision>
   <origin xyz="6.350000000000e-02 7.400000000000e-02 0.000000000000e+00" rpy="1.570796326790e+00 -0.000000000000e+00 0.000000000000e+00" />
   <geometry>
    <cylinder radius="0.044999999999999998" length="0.029999999999999999" />
   </geometry>
  </collision>
  <inertial>
   <mass value="1.42462" />
   <origin xyz="6.451630000000e-02 3.787100000000e-03 -1.521840000000e-04" />
   <inertia ixx="0.0024302299999999998" ixy="1.5302400000000001e-05" ixz="-2.1819099999999999e-05" iyy="0.0023025699999999999" iyz="-2.6472999999999999e-05" izz="0.0019806799999999999" />
  </inertial>
 </link>
 <joint name="RF_HAA" type="revolute">
  <parent link="base" />
  <child link="RF_HIP" />
  <origin xyz="2.770000000000e-01 -1.160000000000e-01 0.000000000000e+00" rpy="0.000000000000e+00 -0.000000000000e+00 0.000000000000e+00" />
  <axis xyz="1.000000000000e+00 0.000000000000e+00 0.000000000000e+00" />
  <limit lower="-9.4199957586189154" upper="9.4199957586189154" velocity="15.000005363462506" effort="80" />
 </joint>
 <xacro:gz_trans_pos joint_name="RF_HAA" />
 <link name="RF_THIGH">
  <visual>
   <geometry>
    <mesh filename="file:///tmp/_RF_THIGH.dae" />
   </geometry>
  </visual>
  <collision>
   <origin xyz="0.000000000000e+00 -3.500000000000e-02 -1.250000000000e-01" rpy="-1.450000000001e-01 -0.000000000000e+00 0.000000000000e+00" />
   <geometry>
    <box size="8.000000000000e-02 4.000000000000e-02 2.500000000000e-01" />
   </geometry>
  </collision>
  <collision>
   <origin xyz="0.000000000000e+00 -6.900000000000e-02 -2.500000000000e-01" rpy="1.570796326790e+00 -0.000000000000e+00 0.000000000000e+00" />
   <geometry>
    <cylinder radius="0.059999999999999998" length="0.12" />
   </geometry>
  </collision>
  <collision>
   <origin xyz="0.000000000000e+00 5.000000000000e-03 0.000000000000e+00" rpy="-1.715796326790e+00 -0.000000000000e+00 0.000000000000e+00" />
   <geometry>
    <cylinder radius="0.066000000000000003" length="0.12" />
   </geometry>
  </collision>
  <inertial>
   <mass value="1.6349800000000001" />
   <origin xyz="-3.897970000000e-03 -5.422660000000e-02 -2.145830000000e-01" />
   <inertia ixx="0.0120368" ixy="-6.7620700000000001e-05" ixz="0.00028780599999999999" iyy="0.012064399999999999" iyz="0.0014061" izz="0.0024942300000000001" />
  </inertial>
 </link>
 <joint name="RF_HFE" type="revolute">
  <parent link="RF_HIP" />
  <child link="RF_THIGH" />
  <origin xyz="6.350000000000e-02 -4.100000000000e-02 0.000000000000e+00" rpy="0.000000000000e+00 -0.000000000000e+00 0.000000000000e+00" />
  <axis xyz="0.000000000000e+00 1.000000000000e+00 0.000000000000e+00" />
  <limit lower="-9.4199957586189154" upper="9.4199957586189154" velocity="15.000005363462506" effort="80" />
 </joint>
 <xacro:gz_trans_pos joint_name="RF_HFE" />
 <link name="RF_SHANK">
  <visual>
   <geometry>
    <mesh filename="file:///tmp/_RF_SHANK.dae" />
   </geometry>
  </visual>
  <collision>
   <origin xyz="6.500000000000e-02 1.500000000000e-02 1.000000000000e-02" rpy="-0.000000000000e+00 1.570796326790e+00 0.000000000000e+00" />
   <geometry>
    <box size="8.000000000000e-02 7.000000000000e-02 1.300000000000e-01" />
   </geometry>
  </collision>
  <collision>
   <origin xyz="1.000000000000e-01 2.000000000000e-02 -1.606250000000e-01" rpy="0.000000000000e+00 -0.000000000000e+00 0.000000000000e+00" />
   <geometry>
    <cylinder radius="0.014999999999999999" length="0.32124999999999998" />
   </geometry>
  </collision>
  <collision>
   <origin xyz="1.000000000000e-01 2.000000000000e-02 -2.980000000000e-01" rpy="0.000000000000e+00 -0.000000000000e+00 0.000000000000e+00" />
   <geometry>
    <sphere radius="0.031" />
   </geometry>
  </collision>
  <inertial>
   <mass value="0.34837499999999999" />
   <origin xyz="5.885170000000e-02 1.085070000000e-02 -9.870490000000e-02" />
   <inertia ixx="0.0069083800000000004" ixy="-3.2606600000000001e-05" ixz="0.0014378699999999999" iyy="0.0077561699999999997" iyz="0.00031827899999999998" izz="0.00102169" />
  </inertial>
 </link>
 <joint name="RF_KFE" type="revolute">
  <parent link="RF_THIGH" />
  <child link="RF_SHANK" />
  <origin xyz="0.000000000000e+00 -1.090000000000e-01 -2.500000000000e-01" rpy="0.000000000000e+00 -0.000000000000e+00 0.000000000000e+00" />
  <axis xyz="0.000000000000e+00 1.000000000000e+00 0.000000000000e+00" />
  <limit lower="-9.4199957586189154" upper="9.4199957586189154" velocity="15.000005363462506" effort="80" />
 </joint>
 <xacro:gz_trans_pos joint_name="RF_KFE" />
 <link name="LH_HIP">
  <visual>
   <geometry>
    <mesh filename="file:///tmp/_LH_HIP.dae" />
   </geometry>
  </visual>
  <collision>
   <origin xyz="-6.350000000000e-02 -9.000000000000e-03 0.000000000000e+00" rpy="-1.570796326790e+00 -0.000000000000e+00 0.000000000000e+00" />
   <geometry>
    <cylinder radius="0.080000000000000002" length="0.10000000000000001" />
   </geometry>
  </collision>
  <collision>
   <origin xyz="-6.350000000000e-02 -7.400000000000e-02 0.000000000000e+00" rpy="-1.570796326790e+00 -0.000000000000e+00 0.000000000000e+00" />
   <geometry>
    <cylinder radius="0.044999999999999998" length="0.029999999999999999" />
   </geometry>
  </collision>
  <inertial>
   <mass value="1.42462" />
   <origin xyz="-6.451630000000e-02 -3.787100000000e-03 -1.521840000000e-04" />
   <inertia ixx="0.0024302299999999998" ixy="1.5302400000000001e-05" ixz="2.1819099999999999e-05" iyy="0.0023025699999999999" iyz="2.6472999999999999e-05" izz="0.0019806799999999999" />
  </inertial>
 </link>
 <joint name="LH_HAA" type="revolute">
  <parent link="base" />
  <child link="LH_HIP" />
  <origin xyz="-2.770000000000e-01 1.160000000000e-01 0.000000000000e+00" rpy="0.000000000000e+00 -0.000000000000e+00 0.000000000000e+00" />
  <axis xyz="1.000000000000e+00 0.000000000000e+00 0.000000000000e+00" />
  <limit lower="-9.4199957586189154" upper="9.4199957586189154" velocity="15.000005363462506" effort="80" />
 </joint>
 <xacro:gz_trans_pos joint_name="LH_HAA" />
 <link name="LH_THIGH">
  <visual>
   <geometry>
    <mesh filename="file:///tmp/_LH_THIGH.dae" />
   </geometry>
  </visual>
  <collision>
   <origin xyz="0.000000000000e+00 3.500000000000e-02 -1.250000000000e-01" rpy="1.450000000001e-01 -0.000000000000e+00 0.000000000000e+00" />
   <geometry>
    <box size="8.000000000000e-02 4.000000000000e-02 2.500000000000e-01" />
   </geometry>
  </collision>
  <collision>
   <origin xyz="0.000000000000e+00 6.900000000000e-02 -2.500000000000e-01" rpy="1.570796326790e+00 -0.000000000000e+00 0.000000000000e+00" />
   <geometry>
    <cylinder radius="0.059999999999999998" length="0.12" />
   </geometry>
  </collision>
  <collision>
   <origin xyz="0.000000000000e+00 -5.000000000000e-03 0.000000000000e+00" rpy="1.715796326790e+00 -0.000000000000e+00 0.000000000000e+00" />
   <geometry>
    <cylinder radius="0.066000000000000003" length="0.12" />
   </geometry>
  </collision>
  <inertial>
   <mass value="1.6349800000000001" />
   <origin xyz="3.897970000000e-03 5.422660000000e-02 -2.145830000000e-01" />
   <inertia ixx="0.0120368" ixy="-6.7620700000000001e-05" ixz="-0.00028780599999999999" iyy="0.012064399999999999" iyz="-0.0014061" izz="0.0024942300000000001" />
  </inertial>
 </link>
 <joint name="LH_HFE" type="revolute">
  <parent link="LH_HIP" />
  <child link="LH_THIGH" />
  <origin xyz="-6.350000000000e-02 4.100000000000e-02 0.000000000000e+00" rpy="0.000000000000e+00 -0.000000000000e+00 0.000000000000e+00" />
  <axis xyz="0.000000000000e+00 1.000000000000e+00 0.000000000000e+00" />
  <limit lower="-9.4199957586189154" upper="9.4199957586189154" velocity="15.000005363462506" effort="80" />
 </joint>
 <xacro:gz_trans_pos joint_name="LH_HFE" />
 <link name="LH_SHANK">
  <visual>
   <geometry>
    <mesh filename="file:///tmp/_LH_SHANK.dae" />
   </geometry>
  </visual>
  <collision>
   <origin xyz="-6.500000000000e-02 -1.500000000000e-02 1.000000000000e-02" rpy="-0.000000000000e+00 1.570796326790e+00 0.000000000000e+00" />
   <geometry>
    <box size="8.000000000000e-02 7.000000000000e-02 1.300000000000e-01" />
   </geometry>
  </collision>
  <collision>
   <origin xyz="-1.000000000000e-01 -2.000000000000e-02 -1.606250000000e-01" rpy="0.000000000000e+00 -0.000000000000e+00 0.000000000000e+00" />
   <geometry>
    <cylinder radius="0.014999999999999999" length="0.32124999999999998" />
   </geometry>
  </collision>
  <collision>
   <origin xyz="-1.000000000000e-01 -2.000000000000e-02 -2.980000000000e-01" rpy="0.000000000000e+00 -0.000000000000e+00 0.000000000000e+00" />
   <geometry>
    <sphere radius="0.031" />
   </geometry>
  </collision>
  <inertial>
   <mass value="0.34837499999999999" />
   <origin xyz="-5.885170000000e-02 -1.085070000000e-02 -9.870490000000e-02" />
   <inertia ixx="0.0069083800000000004" ixy="-3.2606600000000001e-05" ixz="-0.0014378699999999999" iyy="0.0077561699999999997" iyz="-0.00031827899999999998" izz="0.00102169" />
  </inertial>
 </link>
 <joint name="LH_KFE" type="revolute">
  <parent link="LH_THIGH" />
  <child link="LH_SHANK" />
  <origin xyz="0.000000000000e+00 1.090000000000e-01 -2.500000000000e-01" rpy="0.000000000000e+00 -0.000000000000e+00 0.000000000000e+00" />
  <axis xyz="0.000000000000e+00 1.000000000000e+00 0.000000000000e+00" />
  <limit lower="-9.4199957586189154" upper="9.4199957586189154" velocity="15.000005363462506" effort="80" />
 </joint>
 <xacro:gz_trans_pos joint_name="LH_KFE" />
 <link name="RH_HIP">
  <visual>
   <geometry>
    <mesh filename="file:///tmp/_RH_HIP.dae" />
   </geometry>
  </visual>
  <collision>
   <origin xyz="-6.350000000000e-02 9.000000000000e-03 0.000000000000e+00" rpy="-1.570796326790e+00 -0.000000000000e+00 0.000000000000e+00" />
   <geometry>
    <cylinder radius="0.080000000000000002" length="0.10000000000000001" />
   </geometry>
  </collision>
  <collision>
   <origin xyz="-6.350000000000e-02 7.400000000000e-02 0.000000000000e+00" rpy="-1.570796326790e+00 -0.000000000000e+00 0.000000000000e+00" />
   <geometry>
    <cylinder radius="0.044999999999999998" length="0.029999999999999999" />
   </geometry>
  </collision>
  <inertial>
   <mass value="1.42462" />
   <origin xyz="-6.451630000000e-02 3.787100000000e-03 -1.521840000000e-04" />
   <inertia ixx="0.0024302299999999998" ixy="-1.5302400000000001e-05" ixz="2.1819099999999999e-05" iyy="0.0023025699999999999" iyz="-2.6472999999999999e-05" izz="0.0019806799999999999" />
  </inertial>
 </link>
 <joint name="RH_HAA" type="revolute">
  <parent link="base" />
  <child link="RH_HIP" />
  <origin xyz="-2.770000000000e-01 -1.160000000000e-01 0.000000000000e+00" rpy="0.000000000000e+00 -0.000000000000e+00 0.000000000000e+00" />
  <axis xyz="1.000000000000e+00 0.000000000000e+00 0.000000000000e+00" />
  <limit lower="-9.4199957586189154" upper="9.4199957586189154" velocity="15.000005363462506" effort="80" />
 </joint>
 <xacro:gz_trans_pos joint_name="RH_HAA" />
 <link name="RH_THIGH">
  <visual>
   <geometry>
    <mesh filename="file:///tmp/_RH_THIGH.dae" />
   </geometry>
  </visual>
  <collision>
   <origin xyz="0.000000000000e+00 -3.500000000000e-02 -1.250000000000e-01" rpy="-1.450000000001e-01 -0.000000000000e+00 0.000000000000e+00" />
   <geometry>
    <box size="8.000000000000e-02 4.000000000000e-02 2.500000000000e-01" />
   </geometry>
  </collision>
  <collision>
   <origin xyz="0.000000000000e+00 -6.900000000000e-02 -2.500000000000e-01" rpy="1.570796326790e+00 -0.000000000000e+00 0.000000000000e+00" />
   <geometry>
    <cylinder radius="0.059999999999999998" length="0.12" />
   </geometry>
  </collision>
  <collision>
   <origin xyz="0.000000000000e+00 5.000000000000e-03 0.000000000000e+00" rpy="-1.715796326790e+00 -0.000000000000e+00 0.000000000000e+00" />
   <geometry>
    <cylinder radius="0.066000000000000003" length="0.12" />
   </geometry>
  </collision>
  <inertial>
   <mass value="1.6349800000000001" />
   <origin xyz="3.897970000000e-03 -5.422660000000e-02 -2.145830000000e-01" />
   <inertia ixx="0.0120368" ixy="6.7620700000000001e-05" ixz="-0.00028780599999999999" iyy="0.012064399999999999" iyz="0.0014061" izz="0.0024942300000000001" />
  </inertial>
 </link>
 <joint name="RH_HFE" type="revolute">
  <parent link="RH_HIP" />
  <child link="RH_THIGH" />
  <origin xyz="-6.350000000000e-02 -4.100000000000e-02 0.000000000000e+00" rpy="0.000000000000e+00 -0.000000000000e+00 0.000000000000e+00" />
  <axis xyz="0.000000000000e+00 1.000000000000e+00 0.000000000000e+00" />
  <limit lower="-9.4199957586189154" upper="9.4199957586189154" velocity="15.000005363462506" effort="80" />
 </joint>
 <xacro:gz_trans_pos joint_name="RH_HFE" />
 <link name="RH_SHANK">
  <visual>
   <geometry>
    <mesh filename="file:///tmp/_RH_SHANK.dae" />
   </geometry>
  </visual>
  <collision>
   <origin xyz="-6.500000000000e-02 1.500000000000e-02 1.000000000000e-02" rpy="-0.000000000000e+00 1.570796326790e+00 0.000000000000e+00" />
   <geometry>
    <box size="8.000000000000e-02 7.000000000000e-02 1.300000000000e-01" />
   </geometry>
  </collision>
  <collision>
   <origin xyz="-1.000000000000e-01 2.000000000000e-02 -1.606250000000e-01" rpy="0.000000000000e+00 -0.000000000000e+00 0.000000000000e+00" />
   <geometry>
    <cylinder radius="0.014999999999999999" length="0.32124999999999998" />
   </geometry>
  </collision>
  <collision>
   <origin xyz="-1.000000000000e-01 2.000000000000e-02 -2.980000000000e-01" rpy="0.000000000000e+00 -0.000000000000e+00 0.000000000000e+00" />
   <geometry>
    <sphere radius="0.031" />
   </geometry>
  </collision>
  <inertial>
   <mass value="0.34837499999999999" />
   <origin xyz="-5.885170000000e-02 1.085070000000e-02 -9.870490000000e-02" />
   <inertia ixx="0.0069083800000000004" ixy="3.2606600000000001e-05" ixz="-0.0014378699999999999" iyy="0.0077561699999999997" iyz="0.00031827899999999998" izz="0.00102169" />
  </inertial>
 </link>
 <joint name="RH_KFE" type="revolute">
  <parent link="RH_THIGH" />
  <child link="RH_SHANK" />
  <origin xyz="0.000000000000e+00 -1.090000000000e-01 -2.500000000000e-01" rpy="0.000000000000e+00 -0.000000000000e+00 0.000000000000e+00" />
  <axis xyz="0.000000000000e+00 1.000000000000e+00 0.000000000000e+00" />
  <limit lower="-9.4199957586189154" upper="9.4199957586189154" velocity="15.000005363462506" effort="80" />
 </joint>
 <xacro:gz_trans_pos joint_name="RH_KFE" />
 <link name="j2s6s200_link_1">
  <visual>
   <geometry>
    <mesh filename="file:///tmp/_j2s6s200_link_1.dae" />
   </geometry>
  </visual>
  <collision>
   <geometry>
    <mesh filename="file:///tmp/_j2s6s200_link_1.stl" />
   </geometry>
  </collision>
  <inertial>
   <mass value="0.74770000000000003" />
   <origin xyz="0.000000000000e+00 -2.000000000000e-03 -6.050000000000e-02" />
   <inertia ixx="0.0015203199999999999" ixy="0" ixz="0" iyy="0.0015203199999999999" iyz="0" izz="0.00059816000000000003" />
  </inertial>
 </link>
 <joint name="j2s6s200_joint_1" type="revolute">
  <parent link="base" />
  <child link="j2s6s200_link_1" />
  <origin xyz="3.142000000000e-01 0.000000000000e+00 2.162540000000e-01" rpy="-3.141592653590e+00 -1.034981019264e-13 -1.570796326795e+00" />
  <axis xyz="0.000000000000e+00 0.000000000000e+00 1.000000000000e+00" />
  <limit lower="-6.2831853071795862" upper="6.2831853071795862" velocity="0.62831853071795862" effort="40" />
 </joint>
 <xacro:gz_trans_pos joint_name="j2s6s200_joint_1" />
 <link name="j2s6s200_link_2">
  <visual>
   <geometry>
    <mesh filename="file:///tmp/_j2s6s200_link_2.dae" />
   </geometry>
  </visual>
  <collision>
   <geometry>
    <mesh filename="file:///tmp/_j2s6s200_link_2.stl" />
   </geometry>
  </collision>
  <inertial>
   <mass value="0.98999999999999999" />
   <origin xyz="0.000000000000e+00 -2.065000000000e-01 -1.000000000000e-02" />
   <inertia ixx="0.0105022" ixy="0" ixz="0" iyy="0.00079199999999999995" iyz="0" izz="0.0105022" />
  </inertial>
 </link>
 <joint name="j2s6s200_joint_2" type="revolute">
  <parent link="j2s6s200_link_1" />
  <child link="j2s6s200_link_2" />
  <origin xyz="7.105427357521e-19 1.600000000000e-03 -1.187500000000e-01" rpy="-1.570796326795e+00 -1.033249107152e-13 -3.141592653590e+00" />
  <axis xyz="0.000000000000e+00 0.000000000000e+00 1.000000000000e+00" />
  <limit lower="0.82030474843733492" upper="5.4628805587422518" velocity="0.62831853071795862" effort="80" />
 </joint>
 <xacro:gz_trans_pos joint_name="j2s6s200_joint_2" />
 <link name="j2s6s200_link_3">
  <visual>
   <geometry>
    <mesh filename="file:///tmp/_j2s6s200_link_3.dae" />
   </geometry>
  </visual>
  <collision>
   <geometry>
    <mesh filename="file:///tmp/_j2s6s200_link_3.stl" />
   </geometry>
  </collision>
  <inertial>
   <mass value="0.67630000000000001" />
   <origin xyz="0.000000000000e+00 8.100000000000e-02 -8.600000000000e-03" />
   <inertia ixx="0.00142022" ixy="0" ixz="0" iyy="0.00030433499999999998" iyz="0" izz="0.00142022" />
  </inertial>
 </link>
 <joint name="j2s6s200_joint_3" type="revolute">
  <parent link="j2s6s200_link_2" />
  <child link="j2s6s200_link_3" />
  <origin xyz="1.262177448354e-29 -4.100000000000e-01 -1.547544430292e-16" rpy="3.141592653590e+00 3.216245299246e-16 3.141592653590e+00" />
  <axis xyz="0.000000000000e+00 0.000000000000e+00 1.000000000000e+00" />
  <limit lower="0.33161255787892263" upper="5.9515727493006638" velocity="0.62831853071795862" effort="40" />
 </joint>
 <xacro:gz_trans_pos joint_name="j2s6s200_joint_3" />
 <link name="j2s6s200_link_4">
  <visual>
   <geometry>
    <mesh filename="file:///tmp/_j2s6s200_link_4.dae" />
   </geometry>
  </visual>
  <collision>
   <geometry>
    <mesh filename="file:///tmp/_j2s6s200_link_4.stl" />
   </geometry>
  </collision>
  <inertial>
   <mass value="0.46300000000000002" />
   <origin xyz="0.000000000000e+00 2.884890000000e-03 -5.419330000000e-02" />
   <inertia ixx="0.000432132" ixy="0" ixz="0" iyy="0.000432132" iyz="0" izz="9.2600000000000001e-05" />
  </inertial>
 </link>
 <joint name="j2s6s200_joint_4" type="revolute">
  <parent link="j2s6s200_link_3" />
  <child link="j2s6s200_link_4" />
  <origin xyz="-5.062616992156e-18 2.073000000000e-01 -1.140000000000e-02" rpy="-1.570796326795e+00 -1.028808215054e-13 -3.141592653590e+00" />
  <axis xyz="0.000000000000e+00 0.000000000000e+00 1.000000000000e+00" />
  <limit lower="-6.2831853071795862" upper="6.2831853071795862" velocity="0.83775804095727824" effort="20" />
 </joint>
 <xacro:gz_trans_pos joint_name="j2s6s200_joint_4" />
 <link name="j2s6s200_link_5">
  <visual>
   <geometry>
    <mesh filename="file:///tmp/_j2s6s200_link_5.dae" />
   </geometry>
  </visual>
  <collision>
   <geometry>
    <mesh filename="file:///tmp/_j2s6s200_link_5.stl" />
   </geometry>
  </collision>
  <inertial>
   <mass value="0.46300000000000002" />
   <origin xyz="0.000000000000e+00 4.972090000000e-02 -2.856280000000e-03" />
   <inertia ixx="0.000432132" ixy="0" ixz="0" iyy="9.2600000000000001e-05" iyz="0" izz="0.000432132" />
  </inertial>
 </link>
 <joint name="j2s6s200_joint_5" type="revolute">
  <parent link="j2s6s200_link_4" />
  <child link="j2s6s200_link_5" />
  <origin xyz="-1.262177448354e-29 6.307299068341e-18 -1.037500000000e-01" rpy="1.570796326795e+00 1.033249107152e-13 -3.141592653590e+00" />
  <axis xyz="0.000000000000e+00 0.000000000000e+00 1.000000000000e+00" />
  <limit lower="0.52359877559829882" upper="5.7595865315812871" velocity="0.83775804095727824" effort="20" />
 </joint>
 <xacro:gz_trans_pos joint_name="j2s6s200_joint_5" />
 <link name="j2s6s200_link_6">
  <visual>
   <geometry>
    <mesh filename="file:///tmp/_j2s6s200_link_6.dae" />
   </geometry>
  </visual>
  <collision>
   <geometry>
    <mesh filename="file:///tmp/_j2s6s200_link_6.stl" />
   </geometry>
  </collision>
  <inertial>
   <mass value="1.0309999999999999" />
   <origin xyz="-9.699320000000e-05 0.000000000000e+00 -6.320960000000e-02" />
   <inertia ixx="0.00080146799999999995" ixy="6.9797400000000005e-16" ixz="-7.7017999999999997e-06" iyy="0.00061191399999999997" iyz="-1.35525e-20" izz="0.00077812499999999995" />
  </inertial>
 </link>
 <joint name="j2s6s200_joint_6" type="revolute">
  <parent link="j2s6s200_link_5" />
  <child link="j2s6s200_link_6" />
  <origin xyz="0.000000000000e+00 1.037500000000e-01 -2.934442682820e-17" rpy="-1.570796326795e+00 -1.037689999250e-13 -3.141592653590e+00" />
  <axis xyz="0.000000000000e+00 0.000000000000e+00 1.000000000000e+00" />
  <limit lower="-6.2831853071795862" upper="6.2831853071795862" velocity="0.83775804095727824" effort="20" />
 </joint>
 <xacro:gz_trans_pos joint_name="j2s6s200_joint_6" />
</robot>

