<?xml version="1.0"?>
<robot name="" xmlns:xi="http://www.w3.org/2001/Xinclude" xmlns:gazebo="http://playerstage.sourceforge.net/gazebo/xmlschema/#gz" xmlns:model="http://playerstage.sourceforge.net/gazebo/xmlschema/#model" xmlns:sensor="http://playerstage.sourceforge.net/gazebo/xmlschema/#sensor" xmlns:body="http://playerstage.sourceforge.net/gazebo/xmlschema/#body" xmlns:geom="http://playerstage.sourceforge.net/gazebo/xmlschema/#geom" xmlns:joint="http://playerstage.sourceforge.net/gazebo/xmlschema/#joint" xmlns:interface="http://playerstage.sourceforge.net/gazebo/xmlschema/#interface" xmlns:rendering="http://playerstage.sourceforge.net/gazebo/xmlschema/#rendering" xmlns:renderable="http://playerstage.sourceforge.net/gazebo/xmlschema/#renderable" xmlns:controller="http://playerstage.sourceforge.net/gazebo/xmlschema/#controller" xmlns:physics="http://playerstage.sourceforge.net/gazebo/xmlschema/#physics" xmlns:xacro="http://www.ros.org/wiki/xacro">
 <xacro:macro name="gz_trans_pos" params="joint_name">
  <transmission name="${joint_name}_trans">
   <type>transmission_interface/SimpleTransmission</type>
   <joint name="${joint_name}">
    <hardwareInterface>hardware_interface/PositionJointInterface</hardwareInterface>
   </joint>
   <actuator name="${joint_name}_motor">
    <hardwareInterface>hardware_interface/PositionJointInterface</hardwareInterface>
   </actuator>
  </transmission>
 </xacro:macro>
 <xacro:macro name="gz_trans_vel" params="joint_name">
  <transmission name="${joint_name}_trans">
   <type>transmission_interface/SimpleTransmission</type>
   <joint name="${joint_name}">
    <hardwareInterface>hardware_interface/VelocityJointInterface</hardwareInterface>
   </joint>
   <actuator name="${joint_name}_motor">
    <hardwareInterface>hardware_interface/VelocityJointInterface</hardwareInterface>
   </actuator>
  </transmission>
 </xacro:macro>
 <xacro:macro name="gz_trans_eff" params="joint_name">
  <transmission name="${joint_name}_trans">
   <type>transmission_interface/SimpleTransmission</type>
   <joint name="${joint_name}">
    <hardwareInterface>hardware_interface/EffortJointInterface</hardwareInterface>
   </joint>
   <actuator name="${joint_name}_motor">
    <hardwareInterface>hardware_interface/EffortJointInterface</hardwareInterface>
   </actuator>
  </transmission>
 </xacro:macro>
 <link name="base_link">
  <visual>
   <geometry>
    <mesh filename="file:///tmp/_base_link.dae" />
   </geometry>
  </visual>
  <collision>
   <geometry>
    <mesh filename="file:///tmp/_base_link.stl" />
   </geometry>
  </collision>
  <inertial>
   <mass value="3.9953400000000001" />
   <origin xyz="3.220030000000e-03 -1.728820000000e-08 -1.029000000000e-02" />
   <inertia ixx="0.0452761" ixy="-1.4495e-10" ixz="0.0049909000000000004" iyy="0.043270200000000002" iyz="-0.00026688500000000002" izz="0.025888100000000001" />
  </inertial>
 </link>
 <link name="Neck">
  <visual>
   <geometry>
    <mesh filename="file:///tmp/_Neck.dae" />
   </geometry>
  </visual>
  <collision>
   <geometry>
    <mesh filename="file:///tmp/_Neck.stl" />
   </geometry>
  </collision>
  <inertial>
   <mass value="0.27390999999999999" />
   <origin xyz="-2.070000000000e-03 0.000000000000e+00 -2.636000000000e-02" />
   <inertia ixx="0.00034350100000000002" ixy="0" ixz="-1.8856300000000001e-05" iyy="0.00049389799999999999" iyz="2.0986300000000001e-06" izz="0.00021525200000000001" />
  </inertial>
 </link>
 <joint name="HeadYaw" type="revolute">
  <parent link="base_link" />
  <child link="Neck" />
  <origin xyz="-3.800000000000e-02 0.000000000000e+00 1.699000000000e-01" rpy="0.000000000000e+00 -0.000000000000e+00 0.000000000000e+00" />
  <axis xyz="0.000000000000e+00 0.000000000000e+00 1.000000000000e+00" />
  <limit lower="-2.0856684561332237" upper="2.0856684561332237" velocity="7.3399821692621527" effort="5.4279999999999999" />
 </joint>
 <xacro:gz_trans_pos joint_name="HeadYaw" />
 <link name="Head">
  <visual>
   <geometry>
    <mesh filename="file:///tmp/_Head.dae" />
   </geometry>
  </visual>
  <collision>
   <geometry>
    <mesh filename="file:///tmp/_Head.stl" />
   </geometry>
  </collision>
  <inertial>
   <mass value="1.51894" />
   <origin xyz="3.120280000000e-03 5.135160000000e-08 1.115200000000e-01" />
   <inertia ixx="0.0059721599999999998" ixy="-3.76426e-09" ixz="0.00012513800000000001" iyy="0.0059055000000000002" iyz="4.3366500000000001e-07" izz="0.0057037800000000003" />
  </inertial>
 </link>
 <joint name="HeadPitch" type="revolute">
  <parent link="Neck" />
  <child link="Head" />
  <origin xyz="0.000000000000e+00 0.000000000000e+00 0.000000000000e+00" rpy="0.000000000000e+00 -0.000000000000e+00 0.000000000000e+00" />
  <axis xyz="0.000000000000e+00 1.000000000000e+00 0.000000000000e+00" />
  <limit lower="-0.70685834705770345" upper="0.63704517697793028" velocity="9.2275557552940217" effort="2.6659999999999999" />
 </joint>
 <xacro:gz_trans_pos joint_name="HeadPitch" />
 <link name="Hip">
  <visual>
   <geometry>
    <mesh filename="file:///tmp/_Hip.dae" />
   </geometry>
  </visual>
  <collision>
   <geometry>
    <mesh filename="file:///tmp/_Hip.stl" />
   </geometry>
  </collision>
  <inertial>
   <mass value="1.02338" />
   <origin xyz="3.200000000000e-04 0.000000000000e+00 -6.039000000000e-02" />
   <inertia ixx="0.0050242200000000002" ixy="0" ixz="-2.5491100000000001e-05" iyy="0.0064097099999999999" iyz="0.00015944900000000001" izz="0.0044108200000000002" />
  </inertial>
 </link>
 <joint name="HipRoll" type="revolute">
  <parent link="base_link" />
  <child link="Hip" />
  <origin xyz="2.000000000000e-05 0.000000000000e+00 -1.390000000000e-01" rpy="0.000000000000e+00 -0.000000000000e+00 0.000000000000e+00" />
  <axis xyz="1.000000000000e+00 0.000000000000e+00 0.000000000000e+00" />
  <limit lower="-0.51487212933832727" upper="0.51487212933832727" velocity="2.2703242909942243" effort="10.1884" />
 </joint>
 <xacro:gz_trans_pos joint_name="HipRoll" />
 <link name="Pelvis">
  <visual>
   <geometry>
    <mesh filename="file:///tmp/_Pelvis.dae" />
   </geometry>
  </visual>
  <collision>
   <geometry>
    <mesh filename="file:///tmp/_Pelvis.stl" />
   </geometry>
  </collision>
  <inertial>
   <mass value="2.4591699999999999" />
   <origin xyz="2.370000000000e-03 0.000000000000e+00 -9.654000000000e-02" />
   <inertia ixx="0.034351" ixy="0" ixz="0.00022303399999999999" iyy="0.030312200000000001" iyz="-8.3754199999999998e-05" izz="0.0143771" />
  </inertial>
 </link>
 <joint name="HipPitch" type="revolute">
  <parent link="Hip" />
  <child link="Pelvis" />
  <origin xyz="0.000000000000e+00 0.000000000000e+00 -7.900000000000e-02" rpy="0.000000000000e+00 -0.000000000000e+00 0.000000000000e+00" />
  <axis xyz="0.000000000000e+00 1.000000000000e+00 0.000000000000e+00" />
  <limit lower="-1.0384691596073741" upper="1.0384691596073741" velocity="2.9327640085886717" effort="19.786999999999999" />
 </joint>
 <xacro:gz_trans_pos joint_name="HipPitch" />
 <link name="Tibia">
  <visual>
   <geometry>
    <mesh filename="file:///tmp/_Tibia.dae" />
   </geometry>
  </visual>
  <collision>
   <geometry>
    <mesh filename="file:///tmp/_Tibia.stl" />
   </geometry>
  </collision>
  <inertial>
   <mass value="11.6015" />
   <origin xyz="2.204530000000e-03 -1.465330000000e-10 -1.857290000000e-01" />
   <inertia ixx="0.12922900000000001" ixy="-0.00040194299999999998" ixz="0.000485546" iyy="0.122839" iyz="-1.02983e-08" izz="0.108168" />
  </inertial>
 </link>
 <joint name="KneePitch" type="revolute">
  <parent link="Pelvis" />
  <child link="Tibia" />
  <origin xyz="0.000000000000e+00 0.000000000000e+00 -2.680000000000e-01" rpy="0.000000000000e+00 -0.000000000000e+00 0.000000000000e+00" />
  <axis xyz="0.000000000000e+00 1.000000000000e+00 0.000000000000e+00" />
  <limit lower="-0.51487212933832727" upper="0.51487212933832727" velocity="2.9327640085886717" effort="27.702000000000002" />
 </joint>
 <xacro:gz_trans_pos joint_name="KneePitch" />
 <link name="WheelFL_link">
  <visual>
   <geometry>
    <mesh filename="file:///tmp/_WheelFL_link.dae" />
   </geometry>
  </visual>
  <collision>
   <geometry>
    <mesh filename="file:///tmp/_WheelFL_link.stl" />
   </geometry>
  </collision>
  <inertial>
   <mass value="1.5802799999999999" />
   <origin xyz="0.000000000000e+00 0.000000000000e+00 0.000000000000e+00" />
   <inertia ixx="0.0029975599999999998" ixy="6.3068000000000003e-07" ixz="5.5690299999999999e-06" iyy="0.00303229" iyz="-9.0408000000000003e-07" izz="0.0029658499999999999" />
  </inertial>
 </link>
 <joint name="WheelFL" type="continuous">
  <parent link="Tibia" />
  <child link="WheelFL_link" />
  <origin xyz="9.000000000000e-02 1.550000000000e-01 -2.640000000000e-01" rpy="0.000000000000e+00 -0.000000000000e+00 1.075169943118e+00" />
  <axis xyz="1.000000000000e+00 0.000000000000e+00 0.000000000000e+00" />
  <limit lower="-1.7976931348623157e+308" upper="1.7976931348623157e+308" velocity="6.2831853071795862" effort="3.25" />
 </joint>
 <xacro:gz_trans_pos joint_name="WheelFL" />
 <link name="WheelB_link">
  <visual>
   <geometry>
    <mesh filename="file:///tmp/_WheelB_link.dae" />
   </geometry>
  </visual>
  <collision>
   <geometry>
    <mesh filename="file:///tmp/_WheelB_link.stl" />
   </geometry>
  </collision>
  <inertial>
   <mass value="1.5802799999999999" />
   <origin xyz="0.000000000000e+00 0.000000000000e+00 0.000000000000e+00" />
   <inertia ixx="0.0029975599999999998" ixy="6.3068000000000003e-07" ixz="5.5690299999999999e-06" iyy="0.00303229" iyz="-9.0408000000000003e-07" izz="0.0029658499999999999" />
  </inertial>
 </link>
 <joint name="WheelB" type="continuous">
  <parent link="Tibia" />
  <child link="WheelB_link" />
  <origin xyz="-1.700000000000e-01 0.000000000000e+00 -2.640000000000e-01" rpy="0.000000000000e+00 -0.000000000000e+00 -3.141592653590e+00" />
  <axis xyz="1.000000000000e+00 0.000000000000e+00 0.000000000000e+00" />
  <limit lower="-1.7976931348623157e+308" upper="1.7976931348623157e+308" velocity="6.2831853071795862" effort="3.25" />
 </joint>
 <xacro:gz_trans_pos joint_name="WheelB" />
 <link name="WheelFR_link">
  <visual>
   <geometry>
    <mesh filename="file:///tmp/_WheelFR_link.dae" />
   </geometry>
  </visual>
  <collision>
   <geometry>
    <mesh filename="file:///tmp/_WheelFR_link.stl" />
   </geometry>
  </collision>
  <inertial>
   <mass value="1.5802799999999999" />
   <origin xyz="0.000000000000e+00 0.000000000000e+00 0.000000000000e+00" />
   <inertia ixx="0.0029975599999999998" ixy="6.3068000000000003e-07" ixz="5.5690299999999999e-06" iyy="0.00303229" iyz="-9.0408000000000003e-07" izz="0.0029658499999999999" />
  </inertial>
 </link>
 <joint name="WheelFR" type="continuous">
  <parent link="Tibia" />
  <child link="WheelFR_link" />
  <origin xyz="9.000000000000e-02 -1.550000000000e-01 -2.640000000000e-01" rpy="0.000000000000e+00 -0.000000000000e+00 -1.075169943118e+00" />
  <axis xyz="1.000000000000e+00 0.000000000000e+00 0.000000000000e+00" />
  <limit lower="-1.7976931348623157e+308" upper="1.7976931348623157e+308" velocity="6.2831853071795862" effort="3.25" />
 </joint>
 <xacro:gz_trans_pos joint_name="WheelFR" />
 <link name="LShoulder">
  <visual>
   <geometry>
    <mesh filename="file:///tmp/_LShoulder.dae" />
   </geometry>
  </visual>
  <collision>
   <geometry>
    <mesh filename="file:///tmp/_LShoulder.stl" />
   </geometry>
  </collision>
  <inertial>
   <mass value="0.3125" />
   <origin xyz="1.800000000000e-04 -1.856000000000e-02 9.900000000000e-04" />
   <inertia ixx="0.00036119800000000002" ixy="-1.9834700000000002e-06" ixz="6.35907e-07" iyy="0.000137229" iyz="-5.6887799999999999e-06" izz="0.00039919400000000001" />
  </inertial>
 </link>
 <joint name="LShoulderPitch" type="revolute">
  <parent link="base_link" />
  <child link="LShoulder" />
  <origin xyz="-5.700000000000e-02 1.497400000000e-01 8.682000000000e-02" rpy="0.000000000000e+00 -0.000000000000e+00 0.000000000000e+00" />
  <axis xyz="0.000000000000e+00 1.000000000000e+00 0.000000000000e+00" />
  <limit lower="-2.0856684561332237" upper="2.0856684561332237" velocity="7.3399821692621527" effort="5.4279999999999999" />
 </joint>
 <xacro:gz_trans_pos joint_name="LShoulderPitch" />
 <link name="LBicep">
  <visual>
   <geometry>
    <mesh filename="file:///tmp/_LBicep.dae" />
   </geometry>
  </visual>
  <collision>
   <geometry>
    <mesh filename="file:///tmp/_LBicep.stl" />
   </geometry>
  </collision>
  <inertial>
   <mass value="0.50527" />
   <origin xyz="8.151000000000e-02 1.284000000000e-02 -1.017000000000e-02" />
   <inertia ixx="0.00050087199999999997" ixy="-3.55918e-05" ixz="8.5126300000000005e-05" iyy="0.0012628400000000001" iyz="9.0681299999999992e-06" izz="0.0011571800000000001" />
  </inertial>
 </link>
 <joint name="LShoulderRoll" type="revolute">
  <parent link="LShoulder" />
  <child link="LBicep" />
  <origin xyz="0.000000000000e+00 0.000000000000e+00 0.000000000000e+00" rpy="0.000000000000e+00 -0.000000000000e+00 0.000000000000e+00" />
  <axis xyz="0.000000000000e+00 0.000000000000e+00 1.000000000000e+00" />
  <limit lower="0.0087266462599716477" upper="1.562069680534925" velocity="9.2275557552940217" effort="2.6659999999999999" />
 </joint>
 <xacro:gz_trans_pos joint_name="LShoulderRoll" />
 <link name="LElbow">
  <visual>
   <geometry>
    <mesh filename="file:///tmp/_LElbow.dae" />
   </geometry>
  </visual>
  <collision>
   <geometry>
    <mesh filename="file:///tmp/_LElbow.stl" />
   </geometry>
  </collision>
  <inertial>
   <mass value="0.27495000000000003" />
   <origin xyz="-2.297000000000e-02 -1.900000000000e-04 1.190000000000e-03" />
   <inertia ixx="0.00012297100000000001" ixy="9.8602399999999999e-07" ixz="-2.5583800000000001e-05" iyy="0.00033176599999999999" iyz="-1.9892500000000001e-06" izz="0.00030304699999999997" />
  </inertial>
 </link>
 <joint name="LElbowYaw" type="revolute">
  <parent link="LBicep" />
  <child link="LElbow" />
  <origin xyz="1.812000000000e-01 1.500000000000e-02 1.300000000000e-04" rpy="0.000000000000e+00 -1.570789345478e-01 0.000000000000e+00" />
  <axis xyz="1.000000000000e+00 0.000000000000e+00 0.000000000000e+00" />
  <limit lower="-2.0856684561332237" upper="2.0856684561332237" velocity="7.3399821692621527" effort="5.4279999999999999" />
 </joint>
 <xacro:gz_trans_pos joint_name="LElbowYaw" />
 <link name="LForeArm">
  <visual>
   <geometry>
    <mesh filename="file:///tmp/_LForeArm.dae" />
   </geometry>
  </visual>
  <collision>
   <geometry>
    <mesh filename="file:///tmp/_LForeArm.stl" />
   </geometry>
  </collision>
  <inertial>
   <mass value="0.16578999999999999" />
   <origin xyz="5.930000000000e-02 2.710000000000e-03 -1.014000000000e-02" />
   <inertia ixx="0.0015651300000000001" ixy="1.47517e-05" ixz="-6.0574600000000001e-05" iyy="0.00173219" iyz="-1.7618999999999999e-07" izz="0.000273081" />
  </inertial>
 </link>
 <joint name="LElbowRoll" type="revolute">
  <parent link="LElbow" />
  <child link="LForeArm" />
  <origin xyz="0.000000000000e+00 0.000000000000e+00 0.000000000000e+00" rpy="0.000000000000e+00 -0.000000000000e+00 0.000000000000e+00" />
  <axis xyz="0.000000000000e+00 0.000000000000e+00 1.000000000000e+00" />
  <limit lower="-1.562069680534925" upper="-0.0087266462599716477" velocity="9.2275557552940217" effort="2.6659999999999999" />
 </joint>
 <xacro:gz_trans_pos joint_name="LElbowRoll" />
 <link name="l_wrist">
  <visual>
   <geometry>
    <mesh filename="file:///tmp/_l_wrist.dae" />
   </geometry>
  </visual>
  <collision>
   <geometry>
    <mesh filename="file:///tmp/_l_wrist.stl" />
   </geometry>
  </collision>
  <inertial>
   <mass value="0.27555099999999999" />
   <origin xyz="3.536010000000e-02 -7.199970000000e-04 -2.069880000000e-03" />
   <inertia ixx="0.00015164399999999999" ixy="1.0662899999999999e-05" ixz="2.8945399999999998e-06" iyy="0.00043110000000000002" iyz="-3.1371699999999998e-06" izz="0.00045617200000000002" />
  </inertial>
 </link>
 <joint name="LWristYaw" type="revolute">
  <parent link="LForeArm" />
  <child link="l_wrist" />
  <origin xyz="1.500000000000e-01 0.000000000000e+00 6.938893903907e-18" rpy="0.000000000000e+00 -0.000000000000e+00 0.000000000000e+00" />
  <axis xyz="1.000000000000e+00 0.000000000000e+00 0.000000000000e+00" />
  <limit lower="-1.8238690683340744" upper="1.8238690683340744" velocity="17.383496803156042" effort="0.2014" />
 </joint>
 <xacro:gz_trans_pos joint_name="LWristYaw" />
 <link name="l_gripper">
  <inertial>
   <mass value="1.9999999999999999e-06" />
   <origin xyz="0.000000000000e+00 0.000000000000e+00 0.000000000000e+00" />
   <inertia ixx="1.0999999999999999e-09" ixy="0" ixz="0" iyy="1.0999999999999999e-09" iyz="0" izz="1.0999999999999999e-09" />
  </inertial>
 </link>
 <joint name="LHand" type="revolute">
  <parent link="l_wrist" />
  <child link="l_gripper" />
  <origin xyz="2.500000000000e-02 0.000000000000e+00 -1.734723475977e-18" rpy="0.000000000000e+00 -0.000000000000e+00 0.000000000000e+00" />
  <axis xyz="1.000000000000e+00 0.000000000000e+00 0.000000000000e+00" />
  <limit lower="0.020000076964453422" upper="0.98000062966556412" velocity="12.560000162589393" effort="0.14399999999999999" />
 </joint>
 <xacro:gz_trans_pos joint_name="LHand" />
 <link name="LFinger21_link">
  <visual>
   <geometry>
    <mesh filename="file:///tmp/_LFinger21_link.dae" />
   </geometry>
  </visual>
  <collision>
   <geometry>
    <mesh filename="file:///tmp/_LFinger21_link.stl" />
   </geometry>
  </collision>
  <inertial>
   <mass value="1.9999999999999999e-06" />
   <origin xyz="0.000000000000e+00 0.000000000000e+00 0.000000000000e+00" />
   <inertia ixx="1.0999999999999999e-09" ixy="0" ixz="0" iyy="1.0999999999999999e-09" iyz="0" izz="1.0999999999999999e-09" />
  </inertial>
 </link>
 <joint name="LFinger21" type="continuous">
  <parent link="l_wrist" />
  <child link="LFinger21_link" />
  <origin xyz="8.730000000000e-02 -7.300000000000e-03 6.000000000000e-03" rpy="1.570811171295e+00 1.047203157439e+00 -6.108084118025e-02" />
  <axis xyz="0.000000000000e+00 0.000000000000e+00 1.000000000000e+00" />
  <limit lower="-1.7976931348623157e+308" upper="1.7976931348623157e+308" velocity="1.7976931348623157e+308" effort="1.7976931348623157e+308" />
 </joint>
 <xacro:gz_trans_pos joint_name="LFinger21" />
 <link name="LFinger22_link">
  <visual>
   <geometry>
    <mesh filename="file:///tmp/_LFinger22_link.dae" />
   </geometry>
  </visual>
  <collision>
   <geometry>
    <mesh filename="file:///tmp/_LFinger22_link.stl" />
   </geometry>
  </collision>
  <inertial>
   <mass value="1.9999999999999999e-06" />
   <origin xyz="0.000000000000e+00 0.000000000000e+00 0.000000000000e+00" />
   <inertia ixx="1.0999999999999999e-09" ixy="0" ixz="0" iyy="1.0999999999999999e-09" iyz="0" izz="1.0999999999999999e-09" />
  </inertial>
 </link>
 <joint name="LFinger22" type="continuous">
  <parent link="LFinger21_link" />
  <child link="LFinger22_link" />
  <origin xyz="1.800000000000e-02 -6.938893903907e-18 7.264154555653e-18" rpy="1.249000902703e-16 -3.122502256758e-17 -1.047199296526e+00" />
  <axis xyz="0.000000000000e+00 0.000000000000e+00 1.000000000000e+00" />
  <limit lower="-1.7976931348623157e+308" upper="1.7976931348623157e+308" velocity="1.7976931348623157e+308" effort="1.7976931348623157e+308" />
 </joint>
 <xacro:gz_trans_pos joint_name="LFinger22" />
 <link name="LFinger23_link">
  <visual>
   <geometry>
    <mesh filename="file:///tmp/_LFinger23_link.dae" />
   </geometry>
  </visual>
  <collision>
   <geometry>
    <mesh filename="file:///tmp/_LFinger23_link.stl" />
   </geometry>
  </collision>
  <inertial>
   <mass value="1.9999999999999999e-06" />
   <origin xyz="0.000000000000e+00 0.000000000000e+00 0.000000000000e+00" />
   <inertia ixx="1.0999999999999999e-09" ixy="0" ixz="0" iyy="1.0999999999999999e-09" iyz="0" izz="1.0999999999999999e-09" />
  </inertial>
 </link>
 <joint name="LFinger23" type="continuous">
  <parent link="LFinger22_link" />
  <child link="LFinger23_link" />
  <origin xyz="1.800000000000e-02 -2.602085213965e-18 7.589415207399e-18" rpy="8.673617379884e-17 9.714451465470e-17 -1.047199296526e+00" />
  <axis xyz="0.000000000000e+00 0.000000000000e+00 1.000000000000e+00" />
  <limit lower="-1.7976931348623157e+308" upper="1.7976931348623157e+308" velocity="1.7976931348623157e+308" effort="1.7976931348623157e+308" />
 </joint>
 <xacro:gz_trans_pos joint_name="LFinger23" />
 <link name="LFinger11_link">
  <visual>
   <geometry>
    <mesh filename="file:///tmp/_LFinger11_link.dae" />
   </geometry>
  </visual>
  <collision>
   <geometry>
    <mesh filename="file:///tmp/_LFinger11_link.stl" />
   </geometry>
  </collision>
  <inertial>
   <mass value="1.9999999999999999e-06" />
   <origin xyz="0.000000000000e+00 0.000000000000e+00 0.000000000000e+00" />
   <inertia ixx="1.0999999999999999e-09" ixy="0" ixz="0" iyy="1.0999999999999999e-09" iyz="0" izz="1.0999999999999999e-09" />
  </inertial>
 </link>
 <joint name="LFinger11" type="continuous">
  <parent link="l_wrist" />
  <child link="LFinger11_link" />
  <origin xyz="8.210000000000e-02 -2.680000000000e-02 4.000000000000e-03" rpy="1.744008448722e+00 1.040636673270e+00 -3.343991893759e-02" />
  <axis xyz="0.000000000000e+00 0.000000000000e+00 1.000000000000e+00" />
  <limit lower="-1.7976931348623157e+308" upper="1.7976931348623157e+308" velocity="1.7976931348623157e+308" effort="1.7976931348623157e+308" />
 </joint>
 <xacro:gz_trans_pos joint_name="LFinger11" />
 <link name="LFinger12_link">
  <visual>
   <geometry>
    <mesh filename="file:///tmp/_LFinger12_link.dae" />
   </geometry>
  </visual>
  <collision>
   <geometry>
    <mesh filename="file:///tmp/_LFinger12_link.stl" />
   </geometry>
  </collision>
  <inertial>
   <mass value="1.9999999999999999e-06" />
   <origin xyz="0.000000000000e+00 0.000000000000e+00 0.000000000000e+00" />
   <inertia ixx="1.0999999999999999e-09" ixy="0" ixz="0" iyy="1.0999999999999999e-09" iyz="0" izz="1.0999999999999999e-09" />
  </inertial>
 </link>
 <joint name="LFinger12" type="continuous">
  <parent link="LFinger11_link" />
  <child link="LFinger12_link" />
  <origin xyz="1.800000000000e-02 1.040834085586e-17 -7.155734338404e-18" rpy="-8.326672684689e-17 4.163336342344e-17 -1.047199296526e+00" />
  <axis xyz="0.000000000000e+00 0.000000000000e+00 1.000000000000e+00" />
  <limit lower="-1.7976931348623157e+308" upper="1.7976931348623157e+308" velocity="1.7976931348623157e+308" effort="1.7976931348623157e+308" />
 </joint>
 <xacro:gz_trans_pos joint_name="LFinger12" />
 <link name="LFinger13_link">
  <visual>
   <geometry>
    <mesh filename="file:///tmp/_LFinger13_link.dae" />
   </geometry>
  </visual>
  <collision>
   <geometry>
    <mesh filename="file:///tmp/_LFinger13_link.stl" />
   </geometry>
  </collision>
  <inertial>
   <mass value="1.9999999999999999e-06" />
   <origin xyz="0.000000000000e+00 0.000000000000e+00 0.000000000000e+00" />
   <inertia ixx="1.0999999999999999e-09" ixy="0" ixz="0" iyy="1.0999999999999999e-09" iyz="0" izz="1.0999999999999999e-09" />
  </inertial>
 </link>
 <joint name="LFinger13" type="continuous">
  <parent link="LFinger12_link" />
  <child link="LFinger13_link" />
  <origin xyz="1.800000000000e-02 6.938893903907e-18 -5.421010862428e-18" rpy="-5.204170427930e-17 -5.551115123126e-17 -1.047199296526e+00" />
  <axis xyz="0.000000000000e+00 0.000000000000e+00 1.000000000000e+00" />
  <limit lower="-1.7976931348623157e+308" upper="1.7976931348623157e+308" velocity="1.7976931348623157e+308" effort="1.7976931348623157e+308" />
 </joint>
 <xacro:gz_trans_pos joint_name="LFinger13" />
 <link name="LFinger41_link">
  <visual>
   <geometry>
    <mesh filename="file:///tmp/_LFinger41_link.dae" />
   </geometry>
  </visual>
  <collision>
   <geometry>
    <mesh filename="file:///tmp/_LFinger41_link.stl" />
   </geometry>
  </collision>
  <inertial>
   <mass value="1.9999999999999999e-06" />
   <origin xyz="0.000000000000e+00 0.000000000000e+00 0.000000000000e+00" />
   <inertia ixx="1.0999999999999999e-09" ixy="0" ixz="0" iyy="1.0999999999999999e-09" iyz="0" izz="1.0999999999999999e-09" />
  </inertial>
 </link>
 <joint name="LFinger41" type="continuous">
  <parent link="l_wrist" />
  <child link="LFinger41_link" />
  <origin xyz="7.400000000000e-02 3.090000000000e-02 -1.734723475977e-18" rpy="1.397569922088e+00 1.040640540975e+00 6.833876297111e-02" />
  <axis xyz="0.000000000000e+00 0.000000000000e+00 1.000000000000e+00" />
  <limit lower="-1.7976931348623157e+308" upper="1.7976931348623157e+308" velocity="1.7976931348623157e+308" effort="1.7976931348623157e+308" />
 </joint>
 <xacro:gz_trans_pos joint_name="LFinger41" />
 <link name="LFinger42_link">
  <visual>
   <geometry>
    <mesh filename="file:///tmp/_LFinger42_link.dae" />
   </geometry>
  </visual>
  <collision>
   <geometry>
    <mesh filename="file:///tmp/_LFinger42_link.stl" />
   </geometry>
  </collision>
  <inertial>
   <mass value="1.9999999999999999e-06" />
   <origin xyz="0.000000000000e+00 0.000000000000e+00 0.000000000000e+00" />
   <inertia ixx="1.0999999999999999e-09" ixy="0" ixz="0" iyy="1.0999999999999999e-09" iyz="0" izz="1.0999999999999999e-09" />
  </inertial>
 </link>
 <joint name="LFinger42" type="continuous">
  <parent link="LFinger41_link" />
  <child link="LFinger42_link" />
  <origin xyz="1.800000000000e-02 -1.561251128379e-17 -1.040834085586e-17" rpy="-1.665334536938e-16 -2.775557561563e-17 -1.047199296526e+00" />
  <axis xyz="0.000000000000e+00 0.000000000000e+00 1.000000000000e+00" />
  <limit lower="-1.7976931348623157e+308" upper="1.7976931348623157e+308" velocity="1.7976931348623157e+308" effort="1.7976931348623157e+308" />
 </joint>
 <xacro:gz_trans_pos joint_name="LFinger42" />
 <link name="LFinger43_link">
  <visual>
   <geometry>
    <mesh filename="file:///tmp/_LFinger43_link.dae" />
   </geometry>
  </visual>
  <collision>
   <geometry>
    <mesh filename="file:///tmp/_LFinger43_link.stl" />
   </geometry>
  </collision>
  <inertial>
   <mass value="1.9999999999999999e-06" />
   <origin xyz="0.000000000000e+00 0.000000000000e+00 0.000000000000e+00" />
   <inertia ixx="1.0999999999999999e-09" ixy="0" ixz="0" iyy="1.0999999999999999e-09" iyz="0" izz="1.0999999999999999e-09" />
  </inertial>
 </link>
 <joint name="LFinger43" type="continuous">
  <parent link="LFinger42_link" />
  <child link="LFinger43_link" />
  <origin xyz="1.800000000000e-02 7.806255641896e-18 -3.686287386451e-18" rpy="-3.469446951954e-17 -1.942890293094e-16 -1.047199296526e+00" />
  <axis xyz="0.000000000000e+00 0.000000000000e+00 1.000000000000e+00" />
  <limit lower="-1.7976931348623157e+308" upper="1.7976931348623157e+308" velocity="1.7976931348623157e+308" effort="1.7976931348623157e+308" />
 </joint>
 <xacro:gz_trans_pos joint_name="LFinger43" />
 <link name="LFinger31_link">
  <visual>
   <geometry>
    <mesh filename="file:///tmp/_LFinger31_link.dae" />
   </geometry>
  </visual>
  <collision>
   <geometry>
    <mesh filename="file:///tmp/_LFinger31_link.stl" />
   </geometry>
  </collision>
  <inertial>
   <mass value="1.9999999999999999e-06" />
   <origin xyz="0.000000000000e+00 0.000000000000e+00 0.000000000000e+00" />
   <inertia ixx="1.0999999999999999e-09" ixy="0" ixz="0" iyy="1.0999999999999999e-09" iyz="0" izz="1.0999999999999999e-09" />
  </inertial>
 </link>
 <joint name="LFinger31" type="continuous">
  <parent link="l_wrist" />
  <child link="LFinger31_link" />
  <origin xyz="8.330000000000e-02 1.230000000000e-02 4.000000000000e-03" rpy="1.466361055886e+00 1.044829707301e+00 -2.931343755706e-02" />
  <axis xyz="0.000000000000e+00 0.000000000000e+00 1.000000000000e+00" />
  <limit lower="-1.7976931348623157e+308" upper="1.7976931348623157e+308" velocity="1.7976931348623157e+308" effort="1.7976931348623157e+308" />
 </joint>
 <xacro:gz_trans_pos joint_name="LFinger31" />
 <link name="LFinger32_link">
  <visual>
   <geometry>
    <mesh filename="file:///tmp/_LFinger32_link.dae" />
   </geometry>
  </visual>
  <collision>
   <geometry>
    <mesh filename="file:///tmp/_LFinger32_link.stl" />
   </geometry>
  </collision>
  <inertial>
   <mass value="1.9999999999999999e-06" />
   <origin xyz="0.000000000000e+00 0.000000000000e+00 0.000000000000e+00" />
   <inertia ixx="1.0999999999999999e-09" ixy="0" ixz="0" iyy="1.0999999999999999e-09" iyz="0" izz="1.0999999999999999e-09" />
  </inertial>
 </link>
 <joint name="LFinger32" type="continuous">
  <parent link="LFinger31_link" />
  <child link="LFinger32_link" />
  <origin xyz="1.800000000000e-02 -3.469446951954e-18 -4.770489558936e-18" rpy="-1.318389841742e-16 1.734723475977e-17 -1.047199296526e+00" />
  <axis xyz="0.000000000000e+00 0.000000000000e+00 1.000000000000e+00" />
  <limit lower="-1.7976931348623157e+308" upper="1.7976931348623157e+308" velocity="1.7976931348623157e+308" effort="1.7976931348623157e+308" />
 </joint>
 <xacro:gz_trans_pos joint_name="LFinger32" />
 <link name="LFinger33_link">
  <visual>
   <geometry>
    <mesh filename="file:///tmp/_LFinger33_link.dae" />
   </geometry>
  </visual>
  <collision>
   <geometry>
    <mesh filename="file:///tmp/_LFinger33_link.stl" />
   </geometry>
  </collision>
  <inertial>
   <mass value="1.9999999999999999e-06" />
   <origin xyz="0.000000000000e+00 0.000000000000e+00 0.000000000000e+00" />
   <inertia ixx="1.0999999999999999e-09" ixy="0" ixz="0" iyy="1.0999999999999999e-09" iyz="0" izz="1.0999999999999999e-09" />
  </inertial>
 </link>
 <joint name="LFinger33" type="continuous">
  <parent link="LFinger32_link" />
  <child link="LFinger33_link" />
  <origin xyz="1.800000000000e-02 1.734723475977e-17 9.107298248878e-18" rpy="-8.847089727482e-17 -1.040834085586e-16 -1.047199296526e+00" />
  <axis xyz="0.000000000000e+00 0.000000000000e+00 1.000000000000e+00" />
  <limit lower="-1.7976931348623157e+308" upper="1.7976931348623157e+308" velocity="1.7976931348623157e+308" effort="1.7976931348623157e+308" />
 </joint>
 <xacro:gz_trans_pos joint_name="LFinger33" />
 <link name="LThumb1_link">
  <visual>
   <geometry>
    <mesh filename="file:///tmp/_LThumb1_link.dae" />
   </geometry>
  </visual>
  <collision>
   <geometry>
    <mesh filename="file:///tmp/_LThumb1_link.stl" />
   </geometry>
  </collision>
  <inertial>
   <mass value="1.9999999999999999e-06" />
   <origin xyz="0.000000000000e+00 0.000000000000e+00 0.000000000000e+00" />
   <inertia ixx="1.0999999999999999e-09" ixy="0" ixz="0" iyy="1.0999999999999999e-09" iyz="0" izz="1.0999999999999999e-09" />
  </inertial>
 </link>
 <joint name="LThumb1" type="continuous">
  <parent link="l_wrist" />
  <child link="LThumb1_link" />
  <origin xyz="4.820000000000e-02 -3.570000000000e-02 -1.990000000000e-02" rpy="-1.958358915562e+00 6.062593937064e-01 5.339782022523e-01" />
  <axis xyz="0.000000000000e+00 0.000000000000e+00 1.000000000000e+00" />
  <limit lower="-1.7976931348623157e+308" upper="1.7976931348623157e+308" velocity="1.7976931348623157e+308" effort="1.7976931348623157e+308" />
 </joint>
 <xacro:gz_trans_pos joint_name="LThumb1" />
 <link name="LThumb2_link">
  <visual>
   <geometry>
    <mesh filename="file:///tmp/_LThumb2_link.dae" />
   </geometry>
  </visual>
  <collision>
   <geometry>
    <mesh filename="file:///tmp/_LThumb2_link.stl" />
   </geometry>
  </collision>
  <inertial>
   <mass value="1.9999999999999999e-06" />
   <origin xyz="0.000000000000e+00 0.000000000000e+00 0.000000000000e+00" />
   <inertia ixx="1.0999999999999999e-09" ixy="0" ixz="0" iyy="1.0999999999999999e-09" iyz="0" izz="1.0999999999999999e-09" />
  </inertial>
 </link>
 <joint name="LThumb2" type="continuous">
  <parent link="LThumb1_link" />
  <child link="LThumb2_link" />
  <origin xyz="2.200000000000e-02 1.734723475977e-18 2.428612866368e-17" rpy="2.220446049250e-16 -1.110223024625e-16 -1.047199296526e+00" />
  <axis xyz="0.000000000000e+00 0.000000000000e+00 1.000000000000e+00" />
  <limit lower="-1.7976931348623157e+308" upper="1.7976931348623157e+308" velocity="1.7976931348623157e+308" effort="1.7976931348623157e+308" />
 </joint>
 <xacro:gz_trans_pos joint_name="LThumb2" />
 <link name="RShoulder">
  <visual>
   <geometry>
    <mesh filename="file:///tmp/_RShoulder.dae" />
   </geometry>
  </visual>
  <collision>
   <geometry>
    <mesh filename="file:///tmp/_RShoulder.stl" />
   </geometry>
  </collision>
  <inertial>
   <mass value="0.3125" />
   <origin xyz="1.800000000000e-04 1.856000000000e-02 9.900000000000e-04" />
   <inertia ixx="0.00036119800000000002" ixy="1.9834700000000002e-06" ixz="6.35907e-07" iyy="0.000137229" iyz="5.6887799999999999e-06" izz="0.00039919400000000001" />
  </inertial>
 </link>
 <joint name="RShoulderPitch" type="revolute">
  <parent link="base_link" />
  <child link="RShoulder" />
  <origin xyz="-5.700000000000e-02 -1.497400000000e-01 8.682000000000e-02" rpy="0.000000000000e+00 -0.000000000000e+00 0.000000000000e+00" />
  <axis xyz="0.000000000000e+00 1.000000000000e+00 0.000000000000e+00" />
  <limit lower="-2.0856684561332237" upper="2.0856684561332237" velocity="7.3399821692621527" effort="5.4279999999999999" />
 </joint>
 <xacro:gz_trans_pos joint_name="RShoulderPitch" />
 <link name="RBicep">
  <visual>
   <geometry>
    <mesh filename="file:///tmp/_RBicep.dae" />
   </geometry>
  </visual>
  <collision>
   <geometry>
    <mesh filename="file:///tmp/_RBicep.stl" />
   </geometry>
  </collision>
  <inertial>
   <mass value="0.50527" />
   <origin xyz="8.151000000000e-02 -1.284000000000e-02 -1.017000000000e-02" />
   <inertia ixx="0.00050087199999999997" ixy="3.55918e-05" ixz="8.5126300000000005e-05" iyy="0.0012628400000000001" iyz="-9.0681299999999992e-06" izz="0.0011571800000000001" />
  </inertial>
 </link>
 <joint name="RShoulderRoll" type="revolute">
  <parent link="RShoulder" />
  <child link="RBicep" />
  <origin xyz="0.000000000000e+00 0.000000000000e+00 0.000000000000e+00" rpy="0.000000000000e+00 -0.000000000000e+00 0.000000000000e+00" />
  <axis xyz="0.000000000000e+00 0.000000000000e+00 1.000000000000e+00" />
  <limit lower="-1.562069680534925" upper="-0.0087266462599716477" velocity="9.2275557552940217" effort="2.6659999999999999" />
 </joint>
 <xacro:gz_trans_pos joint_name="RShoulderRoll" />
 <link name="RElbow">
  <visual>
   <geometry>
    <mesh filename="file:///tmp/_RElbow.dae" />
   </geometry>
  </visual>
  <collision>
   <geometry>
    <mesh filename="file:///tmp/_RElbow.stl" />
   </geometry>
  </collision>
  <inertial>
   <mass value="0.27495000000000003" />
   <origin xyz="-2.297000000000e-02 1.900000000000e-04 1.190000000000e-03" />
   <inertia ixx="0.00012297100000000001" ixy="-9.8602399999999999e-07" ixz="-2.5583800000000001e-05" iyy="0.00033176599999999999" iyz="1.9892500000000001e-06" izz="0.00030304699999999997" />
  </inertial>
 </link>
 <joint name="RElbowYaw" type="revolute">
  <parent link="RBicep" />
  <child link="RElbow" />
  <origin xyz="1.812000000000e-01 -1.500000000000e-02 1.300000000000e-04" rpy="0.000000000000e+00 -1.570789345478e-01 0.000000000000e+00" />
  <axis xyz="1.000000000000e+00 0.000000000000e+00 0.000000000000e+00" />
  <limit lower="-2.0856684561332237" upper="2.0856684561332237" velocity="7.3399821692621527" effort="5.4279999999999999" />
 </joint>
 <xacro:gz_trans_pos joint_name="RElbowYaw" />
 <link name="RForeArm">
  <visual>
   <geometry>
    <mesh filename="file:///tmp/_RForeArm.dae" />
   </geometry>
  </visual>
  <collision>
   <geometry>
    <mesh filename="file:///tmp/_RForeArm.stl" />
   </geometry>
  </collision>
  <inertial>
   <mass value="0.16578999999999999" />
   <origin xyz="5.930000000000e-02 -2.710000000000e-03 -1.014000000000e-02" />
   <inertia ixx="0.0015651300000000001" ixy="-1.47517e-05" ixz="-6.0574600000000001e-05" iyy="0.00173219" iyz="1.7618999999999999e-07" izz="0.000273081" />
  </inertial>
 </link>
 <joint name="RElbowRoll" type="revolute">
  <parent link="RElbow" />
  <child link="RForeArm" />
  <origin xyz="0.000000000000e+00 0.000000000000e+00 0.000000000000e+00" rpy="0.000000000000e+00 -0.000000000000e+00 0.000000000000e+00" />
  <axis xyz="0.000000000000e+00 0.000000000000e+00 1.000000000000e+00" />
  <limit lower="0.0087266462599716477" upper="1.562069680534925" velocity="9.2275557552940217" effort="2.6659999999999999" />
 </joint>
 <xacro:gz_trans_pos joint_name="RElbowRoll" />
 <link name="r_wrist">
  <visual>
   <geometry>
    <mesh filename="file:///tmp/_r_wrist.dae" />
   </geometry>
  </visual>
  <collision>
   <geometry>
    <mesh filename="file:///tmp/_r_wrist.stl" />
   </geometry>
  </collision>
  <inertial>
   <mass value="0.27555099999999999" />
   <origin xyz="3.536010000000e-02 7.199970000000e-04 -2.069880000000e-03" />
   <inertia ixx="0.00015164399999999999" ixy="-1.0662899999999999e-05" ixz="2.8945399999999998e-06" iyy="0.00043110000000000002" iyz="3.1371699999999998e-06" izz="0.00045617200000000002" />
  </inertial>
 </link>
 <joint name="RWristYaw" type="revolute">
  <parent link="RForeArm" />
  <child link="r_wrist" />
  <origin xyz="1.500000000000e-01 0.000000000000e+00 6.938893903907e-18" rpy="0.000000000000e+00 -0.000000000000e+00 0.000000000000e+00" />
  <axis xyz="1.000000000000e+00 0.000000000000e+00 0.000000000000e+00" />
  <limit lower="-1.8238690683340744" upper="1.8238690683340744" velocity="17.383496803156042" effort="0.2014" />
 </joint>
 <xacro:gz_trans_pos joint_name="RWristYaw" />
 <link name="r_gripper">
  <inertial>
   <mass value="1.9999999999999999e-06" />
   <origin xyz="0.000000000000e+00 0.000000000000e+00 0.000000000000e+00" />
   <inertia ixx="1.0999999999999999e-09" ixy="0" ixz="0" iyy="1.0999999999999999e-09" iyz="0" izz="1.0999999999999999e-09" />
  </inertial>
 </link>
 <joint name="RHand" type="revolute">
  <parent link="r_wrist" />
  <child link="r_gripper" />
  <origin xyz="2.500000000000e-02 0.000000000000e+00 -1.734723475977e-18" rpy="0.000000000000e+00 -0.000000000000e+00 0.000000000000e+00" />
  <axis xyz="1.000000000000e+00 0.000000000000e+00 0.000000000000e+00" />
  <limit lower="0.020000076964453422" upper="0.98000062966556412" velocity="12.560000162589393" effort="0.14399999999999999" />
 </joint>
 <xacro:gz_trans_pos joint_name="RHand" />
 <link name="RFinger41_link">
  <visual>
   <geometry>
    <mesh filename="file:///tmp/_RFinger41_link.dae" />
   </geometry>
  </visual>
  <collision>
   <geometry>
    <mesh filename="file:///tmp/_RFinger41_link.stl" />
   </geometry>
  </collision>
  <inertial>
   <mass value="1.9999999999999999e-06" />
   <origin xyz="0.000000000000e+00 0.000000000000e+00 0.000000000000e+00" />
   <inertia ixx="1.0999999999999999e-09" ixy="0" ixz="0" iyy="1.0999999999999999e-09" iyz="0" izz="1.0999999999999999e-09" />
  </inertial>
 </link>
 <joint name="RFinger41" type="continuous">
  <parent link="r_wrist" />
  <child link="RFinger41_link" />
  <origin xyz="7.400000000000e-02 -3.090000000000e-02 -1.734723475977e-18" rpy="1.744009764330e+00 1.040638240369e+00 -6.834505286385e-02" />
  <axis xyz="0.000000000000e+00 0.000000000000e+00 1.000000000000e+00" />
  <limit lower="-1.7976931348623157e+308" upper="1.7976931348623157e+308" velocity="1.7976931348623157e+308" effort="1.7976931348623157e+308" />
 </joint>
 <xacro:gz_trans_pos joint_name="RFinger41" />
 <link name="RFinger42_link">
  <visual>
   <geometry>
    <mesh filename="file:///tmp/_RFinger42_link.dae" />
   </geometry>
  </visual>
  <collision>
   <geometry>
    <mesh filename="file:///tmp/_RFinger42_link.stl" />
   </geometry>
  </collision>
  <inertial>
   <mass value="1.9999999999999999e-06" />
   <origin xyz="0.000000000000e+00 0.000000000000e+00 0.000000000000e+00" />
   <inertia ixx="1.0999999999999999e-09" ixy="0" ixz="0" iyy="1.0999999999999999e-09" iyz="0" izz="1.0999999999999999e-09" />
  </inertial>
 </link>
 <joint name="RFinger42" type="continuous">
  <parent link="RFinger41_link" />
  <child link="RFinger42_link" />
  <origin xyz="1.800000000000e-02 5.204170427930e-18 -4.336808689942e-18" rpy="2.775557561563e-17 -1.387778780781e-17 -1.047199296526e+00" />
  <axis xyz="0.000000000000e+00 0.000000000000e+00 1.000000000000e+00" />
  <limit lower="-1.7976931348623157e+308" upper="1.7976931348623157e+308" velocity="1.7976931348623157e+308" effort="1.7976931348623157e+308" />
 </joint>
 <xacro:gz_trans_pos joint_name="RFinger42" />
 <link name="RFinger43_link">
  <visual>
   <geometry>
    <mesh filename="file:///tmp/_RFinger43_link.dae" />
   </geometry>
  </visual>
  <collision>
   <geometry>
    <mesh filename="file:///tmp/_RFinger43_link.stl" />
   </geometry>
  </collision>
  <inertial>
   <mass value="1.9999999999999999e-06" />
   <origin xyz="0.000000000000e+00 0.000000000000e+00 0.000000000000e+00" />
   <inertia ixx="1.0999999999999999e-09" ixy="0" ixz="0" iyy="1.0999999999999999e-09" iyz="0" izz="1.0999999999999999e-09" />
  </inertial>
 </link>
 <joint name="RFinger43" type="continuous">
  <parent link="RFinger42_link" />
  <child link="RFinger43_link" />
  <origin xyz="1.800000000000e-02 1.734723475977e-18 -1.170938346284e-17" rpy="3.469446951954e-17 -0.000000000000e+00 -1.047199296526e+00" />
  <axis xyz="0.000000000000e+00 0.000000000000e+00 1.000000000000e+00" />
  <limit lower="-1.7976931348623157e+308" upper="1.7976931348623157e+308" velocity="1.7976931348623157e+308" effort="1.7976931348623157e+308" />
 </joint>
 <xacro:gz_trans_pos joint_name="RFinger43" />
 <link name="RFinger31_link">
  <visual>
   <geometry>
    <mesh filename="file:///tmp/_RFinger31_link.dae" />
   </geometry>
  </visual>
  <collision>
   <geometry>
    <mesh filename="file:///tmp/_RFinger31_link.stl" />
   </geometry>
  </collision>
  <inertial>
   <mass value="1.9999999999999999e-06" />
   <origin xyz="0.000000000000e+00 0.000000000000e+00 0.000000000000e+00" />
   <inertia ixx="1.0999999999999999e-09" ixy="0" ixz="0" iyy="1.0999999999999999e-09" iyz="0" izz="1.0999999999999999e-09" />
  </inertial>
 </link>
 <joint name="RFinger31" type="continuous">
  <parent link="r_wrist" />
  <child link="RFinger31_link" />
  <origin xyz="8.330000000000e-02 -1.230000000000e-02 4.000000000000e-03" rpy="1.675219392223e+00 1.044827216286e+00 2.931074453054e-02" />
  <axis xyz="0.000000000000e+00 0.000000000000e+00 1.000000000000e+00" />
  <limit lower="-1.7976931348623157e+308" upper="1.7976931348623157e+308" velocity="1.7976931348623157e+308" effort="1.7976931348623157e+308" />
 </joint>
 <xacro:gz_trans_pos joint_name="RFinger31" />
 <link name="RFinger32_link">
  <visual>
   <geometry>
    <mesh filename="file:///tmp/_RFinger32_link.dae" />
   </geometry>
  </visual>
  <collision>
   <geometry>
    <mesh filename="file:///tmp/_RFinger32_link.stl" />
   </geometry>
  </collision>
  <inertial>
   <mass value="1.9999999999999999e-06" />
   <origin xyz="0.000000000000e+00 0.000000000000e+00 0.000000000000e+00" />
   <inertia ixx="1.0999999999999999e-09" ixy="0" ixz="0" iyy="1.0999999999999999e-09" iyz="0" izz="1.0999999999999999e-09" />
  </inertial>
 </link>
 <joint name="RFinger32" type="continuous">
  <parent link="RFinger31_link" />
  <child link="RFinger32_link" />
  <origin xyz="1.800000000000e-02 -1.387778780781e-17 1.734723475977e-18" rpy="2.775557561563e-17 -5.898059818321e-17 -1.047199296526e+00" />
  <axis xyz="0.000000000000e+00 0.000000000000e+00 1.000000000000e+00" />
  <limit lower="-1.7976931348623157e+308" upper="1.7976931348623157e+308" velocity="1.7976931348623157e+308" effort="1.7976931348623157e+308" />
 </joint>
 <xacro:gz_trans_pos joint_name="RFinger32" />
 <link name="RFinger33_link">
  <visual>
   <geometry>
    <mesh filename="file:///tmp/_RFinger33_link.dae" />
   </geometry>
  </visual>
  <collision>
   <geometry>
    <mesh filename="file:///tmp/_RFinger33_link.stl" />
   </geometry>
  </collision>
  <inertial>
   <mass value="1.9999999999999999e-06" />
   <origin xyz="0.000000000000e+00 0.000000000000e+00 0.000000000000e+00" />
   <inertia ixx="1.0999999999999999e-09" ixy="0" ixz="0" iyy="1.0999999999999999e-09" iyz="0" izz="1.0999999999999999e-09" />
  </inertial>
 </link>
 <joint name="RFinger33" type="continuous">
  <parent link="RFinger32_link" />
  <child link="RFinger33_link" />
  <origin xyz="1.800000000000e-02 9.540979117872e-18 -7.155734338404e-18" rpy="6.765421556310e-17 -1.387778780781e-17 -1.047199296526e+00" />
  <axis xyz="0.000000000000e+00 0.000000000000e+00 1.000000000000e+00" />
  <limit lower="-1.7976931348623157e+308" upper="1.7976931348623157e+308" velocity="1.7976931348623157e+308" effort="1.7976931348623157e+308" />
 </joint>
 <xacro:gz_trans_pos joint_name="RFinger33" />
 <link name="RFinger21_link">
  <visual>
   <geometry>
    <mesh filename="file:///tmp/_RFinger21_link.dae" />
   </geometry>
  </visual>
  <collision>
   <geometry>
    <mesh filename="file:///tmp/_RFinger21_link.stl" />
   </geometry>
  </collision>
  <inertial>
   <mass value="1.9999999999999999e-06" />
   <origin xyz="0.000000000000e+00 0.000000000000e+00 0.000000000000e+00" />
   <inertia ixx="1.0999999999999999e-09" ixy="0" ixz="0" iyy="1.0999999999999999e-09" iyz="0" izz="1.0999999999999999e-09" />
  </inertial>
 </link>
 <joint name="RFinger21" type="continuous">
  <parent link="r_wrist" />
  <child link="RFinger21_link" />
  <origin xyz="8.730000000000e-02 7.300000000000e-03 6.000000000000e-03" rpy="1.570794998742e+00 1.047198965990e+00 6.108285428852e-02" />
  <axis xyz="0.000000000000e+00 0.000000000000e+00 1.000000000000e+00" />
  <limit lower="-1.7976931348623157e+308" upper="1.7976931348623157e+308" velocity="1.7976931348623157e+308" effort="1.7976931348623157e+308" />
 </joint>
 <xacro:gz_trans_pos joint_name="RFinger21" />
 <link name="RFinger22_link">
  <visual>
   <geometry>
    <mesh filename="file:///tmp/_RFinger22_link.dae" />
   </geometry>
  </visual>
  <collision>
   <geometry>
    <mesh filename="file:///tmp/_RFinger22_link.stl" />
   </geometry>
  </collision>
  <inertial>
   <mass value="1.9999999999999999e-06" />
   <origin xyz="0.000000000000e+00 0.000000000000e+00 0.000000000000e+00" />
   <inertia ixx="1.0999999999999999e-09" ixy="0" ixz="0" iyy="1.0999999999999999e-09" iyz="0" izz="1.0999999999999999e-09" />
  </inertial>
 </link>
 <joint name="RFinger22" type="continuous">
  <parent link="RFinger21_link" />
  <child link="RFinger22_link" />
  <origin xyz="1.800000000000e-02 6.938893903907e-18 9.215718466127e-18" rpy="1.595945597899e-16 -2.775557561563e-17 -1.047199296526e+00" />
  <axis xyz="0.000000000000e+00 0.000000000000e+00 1.000000000000e+00" />
  <limit lower="-1.7976931348623157e+308" upper="1.7976931348623157e+308" velocity="1.7976931348623157e+308" effort="1.7976931348623157e+308" />
 </joint>
 <xacro:gz_trans_pos joint_name="RFinger22" />
 <link name="RFinger23_link">
  <visual>
   <geometry>
    <mesh filename="file:///tmp/_RFinger23_link.dae" />
   </geometry>
  </visual>
  <collision>
   <geometry>
    <mesh filename="file:///tmp/_RFinger23_link.stl" />
   </geometry>
  </collision>
  <inertial>
   <mass value="1.9999999999999999e-06" />
   <origin xyz="0.000000000000e+00 0.000000000000e+00 0.000000000000e+00" />
   <inertia ixx="1.0999999999999999e-09" ixy="0" ixz="0" iyy="1.0999999999999999e-09" iyz="0" izz="1.0999999999999999e-09" />
  </inertial>
 </link>
 <joint name="RFinger23" type="continuous">
  <parent link="RFinger22_link" />
  <child link="RFinger23_link" />
  <origin xyz="1.800000000000e-02 -1.127570259385e-17 -3.794707603699e-18" rpy="1.058181320346e-16 1.249000902703e-16 -1.047199296526e+00" />
  <axis xyz="0.000000000000e+00 0.000000000000e+00 1.000000000000e+00" />
  <limit lower="-1.7976931348623157e+308" upper="1.7976931348623157e+308" velocity="1.7976931348623157e+308" effort="1.7976931348623157e+308" />
 </joint>
 <xacro:gz_trans_pos joint_name="RFinger23" />
 <link name="RFinger11_link">
  <visual>
   <geometry>
    <mesh filename="file:///tmp/_RFinger11_link.dae" />
   </geometry>
  </visual>
  <collision>
   <geometry>
    <mesh filename="file:///tmp/_RFinger11_link.stl" />
   </geometry>
  </collision>
  <inertial>
   <mass value="1.9999999999999999e-06" />
   <origin xyz="0.000000000000e+00 0.000000000000e+00 0.000000000000e+00" />
   <inertia ixx="1.0999999999999999e-09" ixy="0" ixz="0" iyy="1.0999999999999999e-09" iyz="0" izz="1.0999999999999999e-09" />
  </inertial>
 </link>
 <joint name="RFinger11" type="continuous">
  <parent link="r_wrist" />
  <child link="RFinger11_link" />
  <origin xyz="8.210000000000e-02 2.680000000000e-02 4.000000000000e-03" rpy="1.397570157839e+00 1.040641149121e+00 3.343317010763e-02" />
  <axis xyz="0.000000000000e+00 0.000000000000e+00 1.000000000000e+00" />
  <limit lower="-1.7976931348623157e+308" upper="1.7976931348623157e+308" velocity="1.7976931348623157e+308" effort="1.7976931348623157e+308" />
 </joint>
 <xacro:gz_trans_pos joint_name="RFinger11" />
 <link name="RFinger12_link">
  <visual>
   <geometry>
    <mesh filename="file:///tmp/_RFinger12_link.dae" />
   </geometry>
  </visual>
  <collision>
   <geometry>
    <mesh filename="file:///tmp/_RFinger12_link.stl" />
   </geometry>
  </collision>
  <inertial>
   <mass value="1.9999999999999999e-06" />
   <origin xyz="0.000000000000e+00 0.000000000000e+00 0.000000000000e+00" />
   <inertia ixx="1.0999999999999999e-09" ixy="0" ixz="0" iyy="1.0999999999999999e-09" iyz="0" izz="1.0999999999999999e-09" />
  </inertial>
 </link>
 <joint name="RFinger12" type="continuous">
  <parent link="RFinger11_link" />
  <child link="RFinger12_link" />
  <origin xyz="1.800000000000e-02 -8.673617379884e-18 1.084202172486e-18" rpy="-1.665334536938e-16 6.938893903907e-18 -1.047199296526e+00" />
  <axis xyz="0.000000000000e+00 0.000000000000e+00 1.000000000000e+00" />
  <limit lower="-1.7976931348623157e+308" upper="1.7976931348623157e+308" velocity="1.7976931348623157e+308" effort="1.7976931348623157e+308" />
 </joint>
 <xacro:gz_trans_pos joint_name="RFinger12" />
 <link name="RFinger13_link">
  <visual>
   <geometry>
    <mesh filename="file:///tmp/_RFinger13_link.dae" />
   </geometry>
  </visual>
  <collision>
   <geometry>
    <mesh filename="file:///tmp/_RFinger13_link.stl" />
   </geometry>
  </collision>
  <inertial>
   <mass value="1.9999999999999999e-06" />
   <origin xyz="0.000000000000e+00 0.000000000000e+00 0.000000000000e+00" />
   <inertia ixx="1.0999999999999999e-09" ixy="0" ixz="0" iyy="1.0999999999999999e-09" iyz="0" izz="1.0999999999999999e-09" />
  </inertial>
 </link>
 <joint name="RFinger13" type="continuous">
  <parent link="RFinger12_link" />
  <child link="RFinger13_link" />
  <origin xyz="1.800000000000e-02 1.994931997373e-17 9.757819552370e-18" rpy="-9.367506770275e-17 -1.110223024625e-16 -1.047199296526e+00" />
  <axis xyz="0.000000000000e+00 0.000000000000e+00 1.000000000000e+00" />
  <limit lower="-1.7976931348623157e+308" upper="1.7976931348623157e+308" velocity="1.7976931348623157e+308" effort="1.7976931348623157e+308" />
 </joint>
 <xacro:gz_trans_pos joint_name="RFinger13" />
 <link name="RThumb1_link">
  <visual>
   <geometry>
    <mesh filename="file:///tmp/_RThumb1_link.dae" />
   </geometry>
  </visual>
  <collision>
   <geometry>
    <mesh filename="file:///tmp/_RThumb1_link.stl" />
   </geometry>
  </collision>
  <inertial>
   <mass value="1.9999999999999999e-06" />
   <origin xyz="0.000000000000e+00 0.000000000000e+00 0.000000000000e+00" />
   <inertia ixx="1.0999999999999999e-09" ixy="0" ixz="0" iyy="1.0999999999999999e-09" iyz="0" izz="1.0999999999999999e-09" />
  </inertial>
 </link>
 <joint name="RThumb1" type="continuous">
  <parent link="r_wrist" />
  <child link="RThumb1_link" />
  <origin xyz="4.820000000000e-02 3.570000000000e-02 -1.990000000000e-02" rpy="-1.183229603341e+00 6.062599232588e-01 -5.339778379495e-01" />
  <axis xyz="0.000000000000e+00 0.000000000000e+00 1.000000000000e+00" />
  <limit lower="-1.7976931348623157e+308" upper="1.7976931348623157e+308" velocity="1.7976931348623157e+308" effort="1.7976931348623157e+308" />
 </joint>
 <xacro:gz_trans_pos joint_name="RThumb1" />
 <link name="RThumb2_link">
  <visual>
   <geometry>
    <mesh filename="file:///tmp/_RThumb2_link.dae" />
   </geometry>
  </visual>
  <collision>
   <geometry>
    <mesh filename="file:///tmp/_RThumb2_link.stl" />
   </geometry>
  </collision>
  <inertial>
   <mass value="1.9999999999999999e-06" />
   <origin xyz="0.000000000000e+00 0.000000000000e+00 0.000000000000e+00" />
   <inertia ixx="1.0999999999999999e-09" ixy="0" ixz="0" iyy="1.0999999999999999e-09" iyz="0" izz="1.0999999999999999e-09" />
  </inertial>
 </link>
 <joint name="RThumb2" type="continuous">
  <parent link="RThumb1_link" />
  <child link="RThumb2_link" />
  <origin xyz="2.200000000000e-02 -8.673617379884e-18 -2.428612866368e-17" rpy="5.551115123126e-17 -5.551115123126e-17 -1.047199296526e+00" />
  <axis xyz="0.000000000000e+00 0.000000000000e+00 1.000000000000e+00" />
  <limit lower="-1.7976931348623157e+308" upper="1.7976931348623157e+308" velocity="1.7976931348623157e+308" effort="1.7976931348623157e+308" />
 </joint>
 <xacro:gz_trans_pos joint_name="RThumb2" />
</robot>

