<?xml version="1.0"?>
<robot name="" xmlns:xi="http://www.w3.org/2001/Xinclude" xmlns:gazebo="http://playerstage.sourceforge.net/gazebo/xmlschema/#gz" xmlns:model="http://playerstage.sourceforge.net/gazebo/xmlschema/#model" xmlns:sensor="http://playerstage.sourceforge.net/gazebo/xmlschema/#sensor" xmlns:body="http://playerstage.sourceforge.net/gazebo/xmlschema/#body" xmlns:geom="http://playerstage.sourceforge.net/gazebo/xmlschema/#geom" xmlns:joint="http://playerstage.sourceforge.net/gazebo/xmlschema/#joint" xmlns:interface="http://playerstage.sourceforge.net/gazebo/xmlschema/#interface" xmlns:rendering="http://playerstage.sourceforge.net/gazebo/xmlschema/#rendering" xmlns:renderable="http://playerstage.sourceforge.net/gazebo/xmlschema/#renderable" xmlns:controller="http://playerstage.sourceforge.net/gazebo/xmlschema/#controller" xmlns:physics="http://playerstage.sourceforge.net/gazebo/xmlschema/#physics" xmlns:xacro="http://www.ros.org/wiki/xacro">
 <xacro:macro name="gz_trans_pos" params="joint_name">
  <transmission name="${joint_name}_trans">
   <type>transmission_interface/SimpleTransmission</type>
   <joint name="${joint_name}">
    <hardwareInterface>hardware_interface/PositionJointInterface</hardwareInterface>
   </joint>
   <actuator name="${joint_name}_motor">
    <hardwareInterface>hardware_interface/PositionJointInterface</hardwareInterface>
   </actuator>
  </transmission>
 </xacro:macro>
 <xacro:macro name="gz_trans_vel" params="joint_name">
  <transmission name="${joint_name}_trans">
   <type>transmission_interface/SimpleTransmission</type>
   <joint name="${joint_name}">
    <hardwareInterface>hardware_interface/VelocityJointInterface</hardwareInterface>
   </joint>
   <actuator name="${joint_name}_motor">
    <hardwareInterface>hardware_interface/VelocityJointInterface</hardwareInterface>
   </actuator>
  </transmission>
 </xacro:macro>
 <xacro:macro name="gz_trans_eff" params="joint_name">
  <transmission name="${joint_name}_trans">
   <type>transmission_interface/SimpleTransmission</type>
   <joint name="${joint_name}">
    <hardwareInterface>hardware_interface/EffortJointInterface</hardwareInterface>
   </joint>
   <actuator name="${joint_name}_motor">
    <hardwareInterface>hardware_interface/EffortJointInterface</hardwareInterface>
   </actuator>
  </transmission>
 </xacro:macro>
 <link name="panda_link0">
  <visual>
   <geometry>
    <mesh filename="file:///tmp/_panda_link0.dae" />
   </geometry>
  </visual>
  <collision>
   <geometry>
    <mesh filename="file:///tmp/_panda_link0.stl" />
   </geometry>
  </collision>
  <inertial>
   <mass value="0.62976900000000002" />
   <origin xyz="-4.101800000000e-02 -1.400000000000e-04 4.997400000000e-02" />
   <inertia ixx="0.00315" ixy="8.2903999999999996e-07" ixz="0.00014999999999999999" iyy="0.0038800000000000002" iyz="8.2299000000000006e-06" izz="0.0042849999999999997" />
  </inertial>
 </link>
 <link name="panda_link1">
  <visual>
   <geometry>
    <mesh filename="file:///tmp/_panda_link1.dae" />
   </geometry>
  </visual>
  <collision>
   <geometry>
    <mesh filename="file:///tmp/_panda_link1.stl" />
   </geometry>
  </collision>
  <inertial>
   <mass value="4.9706799999999998" />
   <origin xyz="3.875000000000e-03 2.081000000000e-03 -4.762000000000e-02" />
   <inertia ixx="0.70337000000000005" ixy="-0.00013899999999999999" ixz="0.0067720000000000002" iyy="0.70660999999999996" iyz="0.019168999999999999" izz="0.0091170000000000001" />
  </inertial>
 </link>
 <joint name="panda_joint1" type="revolute">
  <parent link="panda_link0" />
  <child link="panda_link1" />
  <origin xyz="0.000000000000e+00 0.000000000000e+00 3.330000000000e-01" rpy="0.000000000000e+00 -0.000000000000e+00 0.000000000000e+00" />
  <axis xyz="0.000000000000e+00 0.000000000000e+00 1.000000000000e+00" />
  <limit lower="-2.8972989181881466" upper="2.8972989181881466" velocity="2.1749944072502934" effort="87" />
 </joint>
 <xacro:gz_trans_pos joint_name="panda_joint1" />
 <link name="panda_link2">
  <visual>
   <geometry>
    <mesh filename="file:///tmp/_panda_link2.dae" />
   </geometry>
  </visual>
  <collision>
   <geometry>
    <mesh filename="file:///tmp/_panda_link2.stl" />
   </geometry>
  </collision>
  <inertial>
   <mass value="0.646926" />
   <origin xyz="-3.141000000000e-03 -2.872000000000e-02 3.495000000000e-03" />
   <inertia ixx="0.0079620000000000003" ixy="-0.0039249999999999997" ixz="0.010253999999999999" iyy="0.02811" iyz="0.00070399999999999998" izz="0.025995000000000001" />
  </inertial>
 </link>
 <joint name="panda_joint2" type="revolute">
  <parent link="panda_link1" />
  <child link="panda_link2" />
  <origin xyz="0.000000000000e+00 0.000000000000e+00 0.000000000000e+00" rpy="-1.570796326795e+00 -0.000000000000e+00 0.000000000000e+00" />
  <axis xyz="0.000000000000e+00 0.000000000000e+00 1.000000000000e+00" />
  <limit lower="-1.762799997806793" upper="1.762799997806793" velocity="2.1749944072502934" effort="87" />
 </joint>
 <xacro:gz_trans_pos joint_name="panda_joint2" />
 <link name="panda_link3">
  <visual>
   <geometry>
    <mesh filename="file:///tmp/_panda_link3.dae" />
   </geometry>
  </visual>
  <collision>
   <geometry>
    <mesh filename="file:///tmp/_panda_link3.stl" />
   </geometry>
  </collision>
  <inertial>
   <mass value="3.2286000000000001" />
   <origin xyz="2.751800000000e-02 3.925200000000e-02 -6.650200000000e-02" />
   <inertia ixx="0.037241999999999997" ixy="-0.0047609999999999996" ixz="-0.011396" iyy="0.036155" iyz="-0.012805" izz="0.010829999999999999" />
  </inertial>
 </link>
 <joint name="panda_joint3" type="revolute">
  <parent link="panda_link2" />
  <child link="panda_link3" />
  <origin xyz="0.000000000000e+00 -3.160000000000e-01 0.000000000000e+00" rpy="1.570796326795e+00 -0.000000000000e+00 0.000000000000e+00" />
  <axis xyz="0.000000000000e+00 0.000000000000e+00 1.000000000000e+00" />
  <limit lower="-2.8972989181881466" upper="2.8972989181881466" velocity="2.1749944072502934" effort="87" />
 </joint>
 <xacro:gz_trans_pos joint_name="panda_joint3" />
 <link name="panda_link4">
  <visual>
   <geometry>
    <mesh filename="file:///tmp/_panda_link4.dae" />
   </geometry>
  </visual>
  <collision>
   <geometry>
    <mesh filename="file:///tmp/_panda_link4.stl" />
   </geometry>
  </collision>
  <inertial>
   <mass value="3.5878999999999999" />
   <origin xyz="-5.317000000000e-02 1.044190000000e-01 2.745400000000e-02" />
   <inertia ixx="0.025853000000000001" ixy="0.007796" ixz="-0.0013320000000000001" iyy="0.019552" iyz="0.0086409999999999994" izz="0.028323000000000001" />
  </inertial>
 </link>
 <joint name="panda_joint4" type="revolute">
  <parent link="panda_link3" />
  <child link="panda_link4" />
  <origin xyz="8.250000000000e-02 0.000000000000e+00 0.000000000000e+00" rpy="1.570796326795e+00 -0.000000000000e+00 0.000000000000e+00" />
  <axis xyz="0.000000000000e+00 0.000000000000e+00 1.000000000000e+00" />
  <limit lower="-3.07179693680254" upper="-0.069800080110383231" velocity="2.1749944072502934" effort="87" />
 </joint>
 <xacro:gz_trans_pos joint_name="panda_joint4" />
 <link name="panda_link5">
  <visual>
   <geometry>
    <mesh filename="file:///tmp/_panda_link5.dae" />
   </geometry>
  </visual>
  <collision>
   <geometry>
    <mesh filename="file:///tmp/_panda_link5.stl" />
   </geometry>
  </collision>
  <inertial>
   <mass value="1.2259500000000001" />
   <origin xyz="-1.195300000000e-02 4.106500000000e-02 -3.843700000000e-02" />
   <inertia ixx="0.035548999999999997" ixy="-0.002117" ixz="-0.0040369999999999998" iyy="0.029474" iyz="0.00022900000000000001" izz="0.0086269999999999993" />
  </inertial>
 </link>
 <joint name="panda_joint5" type="revolute">
  <parent link="panda_link4" />
  <child link="panda_link5" />
  <origin xyz="-8.250000000000e-02 3.840000000000e-01 -6.162975822039e-33" rpy="-1.570796326795e+00 -0.000000000000e+00 0.000000000000e+00" />
  <axis xyz="0.000000000000e+00 0.000000000000e+00 1.000000000000e+00" />
  <limit lower="-2.8972989181881466" upper="2.8972989181881466" velocity="2.6100002700173603" effort="12" />
 </joint>
 <xacro:gz_trans_pos joint_name="panda_joint5" />
 <link name="panda_link6">
  <visual>
   <geometry>
    <mesh filename="file:///tmp/_panda_link6.dae" />
   </geometry>
  </visual>
  <collision>
   <geometry>
    <mesh filename="file:///tmp/_panda_link6.stl" />
   </geometry>
  </collision>
  <inertial>
   <mass value="1.66656" />
   <origin xyz="6.014900000000e-02 -1.411700000000e-02 -1.051700000000e-02" />
   <inertia ixx="0.001964" ixy="0.00010900000000000001" ixz="-0.001158" iyy="0.0043540000000000002" iyz="0.00034099999999999999" izz="0.0054330000000000003" />
  </inertial>
 </link>
 <joint name="panda_joint6" type="revolute">
  <parent link="panda_link5" />
  <child link="panda_link6" />
  <origin xyz="0.000000000000e+00 0.000000000000e+00 0.000000000000e+00" rpy="1.570796326795e+00 -0.000000000000e+00 0.000000000000e+00" />
  <axis xyz="0.000000000000e+00 0.000000000000e+00 1.000000000000e+00" />
  <limit lower="-0.017500067343896746" upper="3.7524927983728484" velocity="2.6100002700173603" effort="12" />
 </joint>
 <xacro:gz_trans_pos joint_name="panda_joint6" />
 <link name="panda_link7">
  <visual>
   <geometry>
    <mesh filename="file:///tmp/_panda_link7.dae" />
   </geometry>
  </visual>
  <collision>
   <geometry>
    <mesh filename="file:///tmp/_panda_link7.stl" />
   </geometry>
  </collision>
  <inertial>
   <mass value="1.4655199999999999" />
   <origin xyz="1.756100000000e-03 1.388200000000e-03 9.915650000000e-02" />
   <inertia ixx="0.0163961" ixy="0.00039496399999999998" ixz="-0.00071011499999999999" iyy="0.0139734" iyz="-0.0010538100000000001" izz="0.0066753100000000003" />
  </inertial>
 </link>
 <joint name="panda_joint7" type="revolute">
  <parent link="panda_link6" />
  <child link="panda_link7" />
  <origin xyz="8.800000000000e-02 0.000000000000e+00 0.000000000000e+00" rpy="1.570796326795e+00 -0.000000000000e+00 0.000000000000e+00" />
  <axis xyz="0.000000000000e+00 0.000000000000e+00 1.000000000000e+00" />
  <limit lower="-2.8972989181881466" upper="2.8972989181881466" velocity="2.6100002700173603" effort="12" />
 </joint>
 <xacro:gz_trans_pos joint_name="panda_joint7" />
 <link name="panda_leftfinger">
  <visual>
   <geometry>
    <mesh filename="file:///tmp/_panda_leftfinger.dae" />
   </geometry>
  </visual>
  <collision>
   <origin xyz="0.000000000000e+00 1.850000000000e-02 1.100000000000e-02" rpy="0.000000000000e+00 -0.000000000000e+00 0.000000000000e+00" />
   <geometry>
    <box size="2.200000000000e-02 1.500000000000e-02 2.000000000000e-02" />
   </geometry>
  </collision>
  <collision>
   <origin xyz="0.000000000000e+00 6.800000000000e-03 2.200000000000e-03" rpy="0.000000000000e+00 -0.000000000000e+00 0.000000000000e+00" />
   <geometry>
    <box size="2.200000000000e-02 8.800000000000e-03 3.800000000000e-03" />
   </geometry>
  </collision>
  <collision>
   <origin xyz="0.000000000000e+00 1.590000000000e-02 2.835000000000e-02" rpy="5.235987755983e-01 -0.000000000000e+00 0.000000000000e+00" />
   <geometry>
    <box size="1.750000000000e-02 7.000000000000e-03 2.350000000000e-02" />
   </geometry>
  </collision>
  <collision>
   <origin xyz="0.000000000000e+00 7.580000000000e-03 4.525000000000e-02" rpy="0.000000000000e+00 -0.000000000000e+00 0.000000000000e+00" />
   <geometry>
    <box size="1.750000000000e-02 1.520000000000e-02 1.850000000000e-02" />
   </geometry>
  </collision>
  <inertial>
   <mass value="0.014999999999999999" />
   <origin xyz="0.000000000000e+00 0.000000000000e+00 0.000000000000e+00" />
   <inertia ixx="2.3750000000000001e-06" ixy="0" ixz="0" iyy="2.3750000000000001e-06" iyz="0" izz="7.5000000000000002e-07" />
  </inertial>
 </link>
 <joint name="panda_finger_joint1" type="prismatic">
  <parent link="panda_link7" />
  <child link="panda_leftfinger" />
  <origin xyz="0.000000000000e+00 0.000000000000e+00 1.654000000000e-01" rpy="0.000000000000e+00 -0.000000000000e+00 -7.853981633974e-01" />
  <axis xyz="0.000000000000e+00 1.000000000000e+00 0.000000000000e+00" />
  <limit lower="0" upper="0.040000000000000001" velocity="0.20000000000000001" effort="100" />
 </joint>
 <xacro:gz_trans_pos joint_name="panda_finger_joint1" />
 <link name="panda_rightfinger">
  <visual>
   <geometry>
    <mesh filename="file:///tmp/_panda_rightfinger.dae" />
   </geometry>
  </visual>
  <collision>
   <origin xyz="0.000000000000e+00 -1.850000000000e-02 1.100000000000e-02" rpy="0.000000000000e+00 -0.000000000000e+00 0.000000000000e+00" />
   <geometry>
    <box size="2.200000000000e-02 1.500000000000e-02 2.000000000000e-02" />
   </geometry>
  </collision>
  <collision>
   <origin xyz="0.000000000000e+00 -6.800000000000e-03 2.200000000000e-03" rpy="0.000000000000e+00 -0.000000000000e+00 0.000000000000e+00" />
   <geometry>
    <box size="2.200000000000e-02 8.800000000000e-03 3.800000000000e-03" />
   </geometry>
  </collision>
  <collision>
   <origin xyz="0.000000000000e+00 -1.590000000000e-02 2.835000000000e-02" rpy="-5.235987755983e-01 -0.000000000000e+00 0.000000000000e+00" />
   <geometry>
    <box size="1.750000000000e-02 7.000000000000e-03 2.350000000000e-02" />
   </geometry>
  </collision>
  <collision>
   <origin xyz="0.000000000000e+00 -7.580000000000e-03 4.525000000000e-02" rpy="0.000000000000e+00 -0.000000000000e+00 0.000000000000e+00" />
   <geometry>
    <box size="1.750000000000e-02 1.520000000000e-02 1.850000000000e-02" />
   </geometry>
  </collision>
  <inertial>
   <mass value="0.014999999999999999" />
   <origin xyz="0.000000000000e+00 0.000000000000e+00 0.000000000000e+00" />
   <inertia ixx="2.3750000000000001e-06" ixy="0" ixz="0" iyy="2.3750000000000001e-06" iyz="0" izz="7.5000000000000002e-07" />
  </inertial>
 </link>
 <joint name="panda_finger_joint2" type="prismatic">
  <parent link="panda_link7" />
  <child link="panda_rightfinger" />
  <origin xyz="0.000000000000e+00 0.000000000000e+00 1.654000000000e-01" rpy="0.000000000000e+00 -0.000000000000e+00 -7.853981633974e-01" />
  <axis xyz="0.000000000000e+00 -1.000000000000e+00 0.000000000000e+00" />
  <limit lower="0" upper="0.040000000000000001" velocity="0.20000000000000001" effort="100" />
 </joint>
 <xacro:gz_trans_pos joint_name="panda_finger_joint2" />
</robot>

