<?xml version="1.0"?>
<robot name="" xmlns:xi="http://www.w3.org/2001/Xinclude" xmlns:gazebo="http://playerstage.sourceforge.net/gazebo/xmlschema/#gz" xmlns:model="http://playerstage.sourceforge.net/gazebo/xmlschema/#model" xmlns:sensor="http://playerstage.sourceforge.net/gazebo/xmlschema/#sensor" xmlns:body="http://playerstage.sourceforge.net/gazebo/xmlschema/#body" xmlns:geom="http://playerstage.sourceforge.net/gazebo/xmlschema/#geom" xmlns:joint="http://playerstage.sourceforge.net/gazebo/xmlschema/#joint" xmlns:interface="http://playerstage.sourceforge.net/gazebo/xmlschema/#interface" xmlns:rendering="http://playerstage.sourceforge.net/gazebo/xmlschema/#rendering" xmlns:renderable="http://playerstage.sourceforge.net/gazebo/xmlschema/#renderable" xmlns:controller="http://playerstage.sourceforge.net/gazebo/xmlschema/#controller" xmlns:physics="http://playerstage.sourceforge.net/gazebo/xmlschema/#physics" xmlns:xacro="http://www.ros.org/wiki/xacro">
	<xacro:macro name="gz_trans_pos" params="joint_name">
		<transmission name="${joint_name}_trans">
			<type>transmission_interface/SimpleTransmission</type>
			<joint name="${joint_name}">
				<hardwareInterface>hardware_interface/PositionJointInterface</hardwareInterface>
			</joint>
			<actuator name="${joint_name}_motor">
				<hardwareInterface>hardware_interface/PositionJointInterface</hardwareInterface>
			</actuator>
		</transmission>
	</xacro:macro>
	<xacro:macro name="gz_trans_vel" params="joint_name">
		<transmission name="${joint_name}_trans">
			<type>transmission_interface/SimpleTransmission</type>
			<joint name="${joint_name}">
				<hardwareInterface>hardware_interface/VelocityJointInterface</hardwareInterface>
			</joint>
			<actuator name="${joint_name}_motor">
				<hardwareInterface>hardware_interface/VelocityJointInterface</hardwareInterface>
			</actuator>
		</transmission>
	</xacro:macro>
	<xacro:macro name="gz_trans_eff" params="joint_name">
		<transmission name="${joint_name}_trans">
			<type>transmission_interface/SimpleTransmission</type>
			<joint name="${joint_name}">
				<hardwareInterface>hardware_interface/EffortJointInterface</hardwareInterface>
			</joint>
			<actuator name="${joint_name}_motor">
				<hardwareInterface>hardware_interface/EffortJointInterface</hardwareInterface>
			</actuator>
		</transmission>
	</xacro:macro>
	<link name="base">
		<visual>
			<origin xyz="1.100000000000e-01 0.000000000000e+00 7.500000000000e-01" rpy="0.000000000000e+00 -0.000000000000e+00 0.000000000000e+00" />
			<geometry>
				<sphere radius="0.001" />
			</geometry>
			<material name="mat__0">
				<color rgba="0.8 0.3 0.3 0.3" />
			</material>
		</visual>
		<visual>
			<origin xyz="1.100000000000e-01 0.000000000000e+00 7.500000000000e-01" rpy="0.000000000000e+00 -0.000000000000e+00 0.000000000000e+00" />
			<geometry>
				<sphere radius="0.001" />
			</geometry>
			<material name="mat__1">
				<color rgba="0.8 0.3 0.3 0.3" />
			</material>
		</visual>
		<visual>
			<origin xyz="6.000000000000e-02 0.000000000000e+00 8.265300000000e-01" rpy="0.000000000000e+00 -0.000000000000e+00 0.000000000000e+00" />
			<geometry>
				<cylinder radius="0.085000000000000006" length="0.01" />
			</geometry>
			<material name="mat__2">
				<color rgba="0.2 0.2 0.2 1" />
			</material>
		</visual>
		<visual>
			<geometry>
				<mesh filename="../meshes/meshes_baxter/_base.dae" />
			</geometry>
		</visual>
		<collision>
			<origin xyz="4.000000000000e-02 -4.000000000000e-02 7.500000000000e-01" rpy="0.000000000000e+00 -0.000000000000e+00 0.000000000000e+00" />
			<geometry>
				<sphere radius="0.22" />
			</geometry>
		</collision>
		<collision>
			<origin xyz="4.000000000000e-02 4.000000000000e-02 7.500000000000e-01" rpy="0.000000000000e+00 -0.000000000000e+00 0.000000000000e+00" />
			<geometry>
				<sphere radius="0.22" />
			</geometry>
		</collision>
		<collision>
			<origin xyz="9.470000000000e-02 0.000000000000e+00 8.170000000000e-01" rpy="0.000000000000e+00 -0.000000000000e+00 0.000000000000e+00" />
			<geometry>
				<sphere radius="0.001" />
			</geometry>
		</collision>
		<collision>
			<geometry>
				<mesh filename="../meshes/meshes_baxter/_base.stl" />
			</geometry>
		</collision>
		<inertial>
			<mass value="96.201099999999997" />
			<origin xyz="1.933970000000e-07 0.000000000000e+00 3.464020000000e-06" />
			<inertia ixx="6.9129699999999996" ixy="0.00068017000000000002" ixz="0.64778999999999998" iyy="7.7497800000000003" iyz="0.0043451100000000001" izz="5.7641799999999996" />
		</inertial>
	</link>
	<link name="head">
		<visual>
			<origin xyz="1.198390896220e-01 1.400870188900e-14 -1.574214698850e-02" rpy="2.012369387796e+00 3.259947867207e-12 1.570796326787e+00" />
			<geometry>
				<box size="2.180000000000e-01 1.600000000000e-01 1.000000000000e-03" />
			</geometry>
			<material name="mat__3">
				<color rgba="0 0 0 1" />
			</material>
		</visual>
		<visual>
			<geometry>
				<mesh filename="../meshes/meshes_baxter/_head.dae" />
			</geometry>
		</visual>
		<collision>
			<origin xyz="0.000000000000e+00 0.000000000000e+00 0.000000000000e+00" rpy="0.000000000000e+00 -0.000000000000e+00 0.000000000000e+00" />
			<geometry>
				<sphere radius="0.001" />
			</geometry>
		</collision>
		<collision>
			<origin xyz="1.227000000000e-01 0.000000000000e+00 0.000000000000e+00" rpy="1.750569999997e+00 3.259947867207e-12 1.570796326787e+00" />
			<geometry>
				<sphere radius="0.001" />
			</geometry>
		</collision>
		<inertial>
			<mass value="0.98823799999999995" />
			<origin xyz="5.467690000000e-02 1.417540000000e-18 4.850840000000e-06" />
			<inertia ixx="0.0062019400000000004" ixy="0.000202093" ixz="0.00049589800000000004" iyy="0.010977000000000001" iyz="-0.0010980600000000001" izz="0.0098391399999999997" />
		</inertial>
	</link>
	<joint name="head_pan" type="revolute">
		<parent link="base" />
		<child link="head" />
		<origin xyz="6.000000000000e-02 0.000000000000e+00 6.860000000000e-01" rpy="0.000000000000e+00 -0.000000000000e+00 0.000000000000e+00" />
		<axis xyz="0.000000000000e+00 0.000000000000e+00 1.000000000000e+00" />
		<limit lower="-1.3963000535097554" upper="1.3963000535097554" velocity="10000.003575641671" effort="50000" />
	</joint>
	<xacro:gz_trans_pos joint_name="head_pan" />
	<link name="right_upper_shoulder">
		<visual>
			<geometry>
				<mesh filename="../meshes/meshes_baxter/_right_upper_shoulder.dae" />
			</geometry>
		</visual>
		<collision>
			<origin xyz="0.000000000000e+00 0.000000000000e+00 1.361000000000e-01" rpy="0.000000000000e+00 -0.000000000000e+00 0.000000000000e+00" />
			<geometry>
				<cylinder radius="0.059999999999999998" length="0.2722" />
			</geometry>
		</collision>
		<inertial>
			<mass value="5.7004400000000004" />
			<origin xyz="1.783000000000e-02 8.600000000000e-04 1.912700000000e-01" />
			<inertia ixx="0.047091000000000001" ixy="0.00012787599999999999" ixz="0.0061487" iyy="0.037669800000000003" iyz="0.00078086900000000001" izz="0.035959900000000003" />
		</inertial>
	</link>
	<joint name="right_s0" type="revolute">
		<parent link="base" />
		<child link="right_upper_shoulder" />
		<origin xyz="6.402720000000e-02 -2.590270000000e-01 1.296260000000e-01" rpy="0.000000000000e+00 -0.000000000000e+00 -7.853999087267e-01" />
		<axis xyz="0.000000000000e+00 0.000000000000e+00 1.000000000000e+00" />
		<limit lower="-1.7016803127312032" upper="1.7016803127312032" velocity="1.5000005363462507" effort="50" />
	</joint>
	<xacro:gz_trans_pos joint_name="right_s0" />
	<link name="right_lower_shoulder">
		<visual>
			<geometry>
				<mesh filename="../meshes/meshes_baxter/_right_lower_shoulder.dae" />
			</geometry>
		</visual>
		<collision>
			<origin xyz="0.000000000000e+00 0.000000000000e+00 0.000000000000e+00" rpy="0.000000000000e+00 -0.000000000000e+00 0.000000000000e+00" />
			<geometry>
				<cylinder radius="0.059999999999999998" length="0.12" />
			</geometry>
		</collision>
		<collision>
			<origin xyz="2.435000000000e-01 -2.364336226801e-13 2.364260454080e-13" rpy="1.570796326793e+00 -3.463840325679e-12 1.570796326793e+00" />
			<geometry>
				<cylinder radius="0.059999999999999998" length="0.27300000000000002" />
			</geometry>
		</collision>
		<inertial>
			<mass value="3.2270799999999999" />
			<origin xyz="6.845120000000e-02 2.689920000000e-03 -5.289840000000e-03" />
			<inertia ixx="0.0117521" ixy="-0.00030095399999999998" ixz="0.0020767400000000001" iyy="0.0278861" iyz="-0.00018821899999999999" izz="0.020787699999999999" />
		</inertial>
	</link>
	<joint name="right_s1" type="revolute">
		<parent link="right_upper_shoulder" />
		<child link="right_lower_shoulder" />
		<origin xyz="6.900000000000e-02 2.081668171172e-17 2.703500000000e-01" rpy="-1.570796326795e+00 -0.000000000000e+00 0.000000000000e+00" />
		<axis xyz="0.000000000000e+00 0.000000000000e+00 1.000000000000e+00" />
		<limit lower="-2.1469993260483045" upper="1.0470003289911225" velocity="1.5000005363462507" effort="50" />
	</joint>
	<xacro:gz_trans_pos joint_name="right_s1" />
	<link name="right_upper_elbow">
		<visual>
			<geometry>
				<mesh filename="../meshes/meshes_baxter/_right_upper_elbow.dae" />
			</geometry>
		</visual>
		<collision>
			<origin xyz="0.000000000000e+00 0.000000000000e+00 -5.350000000000e-02" rpy="0.000000000000e+00 -0.000000000000e+00 0.000000000000e+00" />
			<geometry>
				<cylinder radius="0.059999999999999998" length="0.107" />
			</geometry>
		</collision>
		<inertial>
			<mass value="4.3127199999999997" />
			<origin xyz="-2.760000000000e-03 1.320000000000e-03 1.808600000000e-01" />
			<inertia ixx="0.0266173" ixy="0.000292706" ixz="0.0039218999999999999" iyy="0.028443599999999999" iyz="0.0010838899999999999" izz="0.012480099999999999" />
		</inertial>
	</link>
	<joint name="right_e0" type="revolute">
		<parent link="right_lower_shoulder" />
		<child link="right_upper_elbow" />
		<origin xyz="1.020000000000e-01 -7.703719777549e-34 -6.938893903907e-18" rpy="1.570796326795e+00 1.110223024625e-16 1.570796326795e+00" />
		<axis xyz="0.000000000000e+00 0.000000000000e+00 1.000000000000e+00" />
		<limit lower="-3.0541865646499171" upper="3.0541865646499171" velocity="1.5000005363462507" effort="50" />
	</joint>
	<xacro:gz_trans_pos joint_name="right_e0" />
	<link name="right_lower_elbow">
		<visual>
			<geometry>
				<mesh filename="../meshes/meshes_baxter/_right_lower_elbow.dae" />
			</geometry>
		</visual>
		<collision>
			<origin xyz="0.000000000000e+00 0.000000000000e+00 0.000000000000e+00" rpy="0.000000000000e+00 -0.000000000000e+00 0.000000000000e+00" />
			<geometry>
				<cylinder radius="0.059999999999999998" length="0.10000000000000001" />
			</geometry>
		</collision>
		<collision>
			<origin xyz="2.240000000000e-01 -2.355675654542e-13 2.355600159376e-13" rpy="1.570796326793e+00 -3.463840325679e-12 1.570796326793e+00" />
			<geometry>
				<cylinder radius="0.059999999999999998" length="0.27200000000000002" />
			</geometry>
		</collision>
		<inertial>
			<mass value="2.0721599999999998" />
			<origin xyz="2.611300000000e-02 1.589920000000e-03 -1.116950000000e-02" />
			<inertia ixx="0.00711585" ixy="0.00036037200000000003" ixz="0.00074587999999999998" iyy="0.0131827" iyz="-0.000196632" izz="0.00926891" />
		</inertial>
	</link>
	<joint name="right_e1" type="revolute">
		<parent link="right_upper_elbow" />
		<child link="right_lower_elbow" />
		<origin xyz="6.900000000000e-02 3.435507412855e-18 2.624200000000e-01" rpy="-1.570796326795e+00 -1.570796326795e+00 0.000000000000e+00" />
		<axis xyz="0.000000000000e+00 0.000000000000e+00 1.000000000000e+00" />
		<limit lower="-0.050000017878208354" upper="2.6179938779914944" velocity="1.5000005363462507" effort="50" />
	</joint>
	<xacro:gz_trans_pos joint_name="right_e1" />
	<link name="right_upper_forearm">
		<visual>
			<geometry>
				<mesh filename="../meshes/meshes_baxter/_right_upper_forearm.dae" />
			</geometry>
		</visual>
		<collision>
			<origin xyz="0.000000000000e+00 0.000000000000e+00 -4.400000000000e-02" rpy="0.000000000000e+00 -0.000000000000e+00 0.000000000000e+00" />
			<geometry>
				<cylinder radius="0.059999999999999998" length="0.087999999999999995" />
			</geometry>
		</collision>
		<inertial>
			<mass value="2.24675" />
			<origin xyz="-1.682440000000e-03 4.599800000000e-03 1.395190000000e-01" />
			<inertia ixx="0.016677500000000001" ixy="0.000184012" ixz="0.00018646900000000001" iyy="0.0167549" iyz="-0.00064733200000000003" izz="0.00374662" />
		</inertial>
	</link>
	<joint name="right_w0" type="revolute">
		<parent link="right_lower_elbow" />
		<child link="right_upper_forearm" />
		<origin xyz="1.035900000000e-01 -3.851859888774e-33 -1.387778780781e-17" rpy="1.570796326795e+00 1.110223024625e-16 1.570796326795e+00" />
		<axis xyz="0.000000000000e+00 0.000000000000e+00 1.000000000000e+00" />
		<limit lower="-3.0590036733854213" upper="3.0590036733854213" velocity="3.9999979395981642" effort="15" />
	</joint>
	<xacro:gz_trans_pos joint_name="right_w0" />
	<link name="right_lower_forearm">
		<visual>
			<geometry>
				<mesh filename="../meshes/meshes_baxter/_right_lower_forearm.dae" />
			</geometry>
		</visual>
		<collision>
			<origin xyz="0.000000000000e+00 0.000000000000e+00 0.000000000000e+00" rpy="0.000000000000e+00 -0.000000000000e+00 0.000000000000e+00" />
			<geometry>
				<cylinder radius="0.059999999999999998" length="0.10000000000000001" />
			</geometry>
		</collision>
		<inertial>
			<mass value="1.6097900000000001" />
			<origin xyz="6.041000000000e-02 6.970000000000e-03 6.000000000000e-03" />
			<inertia ixx="0.0038760700000000001" ixy="-0.000443848" ixz="-0.00021115000000000001" iyy="0.0070053800000000003" iyz="0.00015348099999999999" izz="0.00552755" />
		</inertial>
	</link>
	<joint name="right_w1" type="revolute">
		<parent link="right_upper_forearm" />
		<child link="right_lower_forearm" />
		<origin xyz="1.000000000000e-02 2.825347524068e-17 2.707000000000e-01" rpy="-1.570796326795e+00 -1.570796326795e+00 0.000000000000e+00" />
		<axis xyz="0.000000000000e+00 0.000000000000e+00 1.000000000000e+00" />
		<limit lower="-1.5707963267948966" upper="2.0939936766652369" velocity="3.9999979395981642" effort="15" />
	</joint>
	<xacro:gz_trans_pos joint_name="right_w1" />
	<link name="right_wrist">
		<visual>
			<origin xyz="3.825000000000e-02 1.200000000000e-02 1.289050000000e-01" rpy="0.000000000000e+00 -0.000000000000e+00 -1.570796329999e+00" />
			<geometry>
				<cylinder radius="0.02" length="0.01" />
			</geometry>
			<material name="mat__4">
				<color rgba="0 0 1 0.8" />
			</material>
		</visual>
		<visual>
			<origin xyz="3.200000000000e-02 -2.024500000000e-02 1.423500000000e-01" rpy="-1.570796326793e+00 -1.570796326791e+00 0.000000000000e+00" />
			<geometry>
				<box size="5.000000000000e-03 2.000000000000e-02 5.000000000000e-03" />
			</geometry>
			<material name="mat__5">
				<color rgba="0 0 1 0.8" />
			</material>
		</visual>
		<visual>
			<origin xyz="1.980000000000e-03 1.330000000000e-04 9.895000000000e-02" rpy="0.000000000000e+00 -0.000000000000e+00 0.000000000000e+00" />
			<geometry>
				<box size="1.000000000000e-02 1.000000000000e-02 1.000000000000e-02" />
			</geometry>
			<material name="mat__6">
				<color rgba="0 0 0 1" />
			</material>
		</visual>
		<visual>
			<geometry>
				<mesh filename="../meshes/meshes_baxter/_right_wrist.dae" />
			</geometry>
		</visual>
		<collision>
			<origin xyz="0.000000000000e+00 0.000000000000e+00 0.000000000000e+00" rpy="0.000000000000e+00 -0.000000000000e+00 0.000000000000e+00" />
			<geometry>
				<cylinder radius="0.059999999999999998" length="0.16500000000000001" />
			</geometry>
		</collision>
		<collision>
			<origin xyz="0.000000000000e+00 0.000000000000e+00 9.035000000000e-02" rpy="0.000000000000e+00 -0.000000000000e+00 0.000000000000e+00" />
			<geometry>
				<cylinder radius="0.040000000000000001" length="0.046399999999999997" />
			</geometry>
		</collision>
		<collision>
			<origin xyz="0.000000000000e+00 0.000000000000e+00 1.385500000000e-01" rpy="1.570796326799e+00 -1.034981491603e-13 3.141592653590e+00" />
			<geometry>
				<cylinder radius="0.029000000000000001" length="0.10000000000000001" />
			</geometry>
		</collision>
		<inertial>
			<mass value="0.84267999999999998" />
			<origin xyz="3.318280000000e-03 6.163390000000e-04 7.943500000000e-02" />
			<inertia ixx="0.0028505900000000001" ixy="7.17373e-06" ixz="2.52032e-05" iyy="0.00291735" iyz="2.1735299999999998e-05" izz="0.00056060799999999998" />
		</inertial>
	</link>
	<joint name="right_w2" type="revolute">
		<parent link="right_lower_forearm" />
		<child link="right_wrist" />
		<origin xyz="1.159750000000e-01 -6.162975822039e-33 -6.938893903907e-18" rpy="1.570796326795e+00 1.110223024625e-16 1.570796326795e+00" />
		<axis xyz="0.000000000000e+00 0.000000000000e+00 1.000000000000e+00" />
		<limit lower="-3.0590036733854213" upper="3.0590036733854213" velocity="3.9999979395981642" effort="15" />
	</joint>
	<xacro:gz_trans_pos joint_name="right_w2" />
	<link name="r_gripper_l_finger">
		<visual>
			<geometry>
				<mesh filename="../meshes/meshes_baxter/_r_gripper_l_finger.dae" />
			</geometry>
		</visual>
		<collision>
			<origin xyz="0.000000000000e+00 1.725000000000e-02 6.150000000000e-02" rpy="0.000000000000e+00 -0.000000000000e+00 3.141592653590e+00" />
			<geometry>
				<box size="1.000000000000e-02 1.350000000000e-02 1.127000000000e-01" />
			</geometry>
		</collision>
		<collision>
			<origin xyz="-5.000000000000e-03 -3.000000000000e-03 8.300000000000e-03" rpy="0.000000000000e+00 -0.000000000000e+00 3.141592653590e+00" />
			<geometry>
				<box size="1.000000000000e-02 5.000000000000e-02 1.700000000000e-02" />
			</geometry>
		</collision>
		<collision>
			<origin xyz="0.000000000000e+00 1.275000000000e-02 9.770000000000e-02" rpy="0.000000000000e+00 -0.000000000000e+00 -3.141592653590e+00" />
			<geometry>
				<cylinder radius="0.0080000000000000002" length="0.036999999999999998" />
			</geometry>
		</collision>
		<inertial>
			<mass value="0.029999999999999999" />
			<origin xyz="0.000000000000e+00 5.750000000000e-03 3.756670000000e-02" />
			<inertia ixx="0.020086699999999999" ixy="0" ixz="0" iyy="0.0200847" iyz="-1.2960500000000001e-05" izz="0.020001999999999999" />
		</inertial>
	</link>
	<joint name="r_gripper_l_finger_joint" type="prismatic">
		<parent link="right_wrist" />
		<child link="r_gripper_l_finger" />
		<origin xyz="1.767727099919e-17 -1.500000000000e-03 1.585500000000e-01" rpy="0.000000000000e+00 1.170965406187e-31 -6.162975822039e-33" />
		<axis xyz="0.000000000000e+00 1.000000000000e+00 0.000000000000e+00" />
		<limit lower="0" upper="0.020833000000000001" velocity="5" effort="20" />
	</joint>
	<xacro:gz_trans_pos joint_name="r_gripper_l_finger_joint" />
	<link name="r_gripper_r_finger">
		<visual>
			<geometry>
				<mesh filename="../meshes/meshes_baxter/_r_gripper_r_finger.dae" />
			</geometry>
		</visual>
		<collision>
			<origin xyz="0.000000000000e+00 -1.725000000000e-02 6.150000000000e-02" rpy="0.000000000000e+00 -0.000000000000e+00 0.000000000000e+00" />
			<geometry>
				<box size="1.000000000000e-02 1.350000000000e-02 1.127000000000e-01" />
			</geometry>
		</collision>
		<collision>
			<origin xyz="5.000000000000e-03 3.000000000000e-03 8.300000000000e-03" rpy="0.000000000000e+00 -0.000000000000e+00 0.000000000000e+00" />
			<geometry>
				<box size="1.000000000000e-02 5.000000000000e-02 1.700000000000e-02" />
			</geometry>
		</collision>
		<collision>
			<origin xyz="0.000000000000e+00 -1.275000000000e-02 9.770000000000e-02" rpy="0.000000000000e+00 -0.000000000000e+00 0.000000000000e+00" />
			<geometry>
				<cylinder radius="0.0080000000000000002" length="0.036999999999999998" />
			</geometry>
		</collision>
		<inertial>
			<mass value="0.029999999999999999" />
			<origin xyz="0.000000000000e+00 -5.750000000000e-03 3.756670000000e-02" />
			<inertia ixx="0.020086699999999999" ixy="0" ixz="0" iyy="0.0200847" iyz="1.2960500000000001e-05" izz="0.020001999999999999" />
		</inertial>
	</link>
	<joint name="r_gripper_r_finger_joint" type="prismatic">
		<parent link="right_wrist" />
		<child link="r_gripper_r_finger" />
		<origin xyz="1.752790111167e-17 1.500000000000e-03 1.585500000000e-01" rpy="0.000000000000e+00 1.170965406187e-31 -6.162975822039e-33" />
		<axis xyz="0.000000000000e+00 1.000000000000e+00 0.000000000000e+00" />
		<limit lower="-0.020833000000000001" upper="0" velocity="5" effort="20" />
	</joint>
	<xacro:gz_trans_pos joint_name="r_gripper_r_finger_joint" />
	<link name="left_upper_shoulder">
		<visual>
			<geometry>
				<mesh filename="../meshes/meshes_baxter/_left_upper_shoulder.dae" />
			</geometry>
		</visual>
		<collision>
			<origin xyz="0.000000000000e+00 0.000000000000e+00 1.361000000000e-01" rpy="0.000000000000e+00 -0.000000000000e+00 0.000000000000e+00" />
			<geometry>
				<cylinder radius="0.059999999999999998" length="0.2722" />
			</geometry>
		</collision>
		<inertial>
			<mass value="5.7004400000000004" />
			<origin xyz="1.783000000000e-02 8.600000000000e-04 1.912700000000e-01" />
			<inertia ixx="0.047091000000000001" ixy="0.00012787599999999999" ixz="0.0061487" iyy="0.037669800000000003" iyz="0.00078086900000000001" izz="0.035959900000000003" />
		</inertial>
	</link>
	<joint name="left_s0" type="revolute">
		<parent link="base" />
		<child link="left_upper_shoulder" />
		<origin xyz="6.402720000000e-02 2.590270000000e-01 1.296260000000e-01" rpy="0.000000000000e+00 -0.000000000000e+00 7.853999087267e-01" />
		<axis xyz="0.000000000000e+00 0.000000000000e+00 1.000000000000e+00" />
		<limit lower="-1.7016803127312032" upper="1.7016803127312032" velocity="1.5000005363462507" effort="50" />
	</joint>
	<xacro:gz_trans_pos joint_name="left_s0" />
	<link name="left_lower_shoulder">
		<visual>
			<geometry>
				<mesh filename="../meshes/meshes_baxter/_left_lower_shoulder.dae" />
			</geometry>
		</visual>
		<collision>
			<origin xyz="0.000000000000e+00 0.000000000000e+00 0.000000000000e+00" rpy="0.000000000000e+00 -0.000000000000e+00 0.000000000000e+00" />
			<geometry>
				<cylinder radius="0.059999999999999998" length="0.12" />
			</geometry>
		</collision>
		<collision>
			<origin xyz="2.435000000000e-01 -2.364336226801e-13 2.364260454080e-13" rpy="1.570796326793e+00 -3.463840325679e-12 1.570796326793e+00" />
			<geometry>
				<cylinder radius="0.059999999999999998" length="0.27300000000000002" />
			</geometry>
		</collision>
		<inertial>
			<mass value="3.2270799999999999" />
			<origin xyz="6.845120000000e-02 2.689920000000e-03 -5.289840000000e-03" />
			<inertia ixx="0.0117521" ixy="-0.00030095399999999998" ixz="0.0020767400000000001" iyy="0.0278861" iyz="-0.00018821899999999999" izz="0.020787699999999999" />
		</inertial>
	</link>
	<joint name="left_s1" type="revolute">
		<parent link="left_upper_shoulder" />
		<child link="left_lower_shoulder" />
		<origin xyz="6.900000000000e-02 -2.081668171172e-17 2.703500000000e-01" rpy="-1.570796326795e+00 -0.000000000000e+00 0.000000000000e+00" />
		<axis xyz="0.000000000000e+00 0.000000000000e+00 1.000000000000e+00" />
		<limit lower="-2.1469993260483045" upper="1.0470003289911225" velocity="1.5000005363462507" effort="50" />
	</joint>
	<xacro:gz_trans_pos joint_name="left_s1" />
	<link name="left_upper_elbow">
		<visual>
			<geometry>
				<mesh filename="../meshes/meshes_baxter/_left_upper_elbow.dae" />
			</geometry>
		</visual>
		<collision>
			<origin xyz="0.000000000000e+00 0.000000000000e+00 -5.350000000000e-02" rpy="0.000000000000e+00 -0.000000000000e+00 0.000000000000e+00" />
			<geometry>
				<cylinder radius="0.059999999999999998" length="0.107" />
			</geometry>
		</collision>
		<inertial>
			<mass value="4.3127199999999997" />
			<origin xyz="-2.760000000000e-03 1.320000000000e-03 1.808600000000e-01" />
			<inertia ixx="0.0266173" ixy="0.000292706" ixz="0.0039218999999999999" iyy="0.028443599999999999" iyz="0.0010838899999999999" izz="0.012480099999999999" />
		</inertial>
	</link>
	<joint name="left_e0" type="revolute">
		<parent link="left_lower_shoulder" />
		<child link="left_upper_elbow" />
		<origin xyz="1.020000000000e-01 7.703719777549e-34 6.938893903907e-18" rpy="1.570796326795e+00 1.110223024625e-16 1.570796326795e+00" />
		<axis xyz="0.000000000000e+00 0.000000000000e+00 1.000000000000e+00" />
		<limit lower="-3.0541865646499171" upper="3.0541865646499171" velocity="1.5000005363462507" effort="50" />
	</joint>
	<xacro:gz_trans_pos joint_name="left_e0" />
	<link name="left_lower_elbow">
		<visual>
			<geometry>
				<mesh filename="../meshes/meshes_baxter/_left_lower_elbow.dae" />
			</geometry>
		</visual>
		<collision>
			<origin xyz="0.000000000000e+00 0.000000000000e+00 0.000000000000e+00" rpy="0.000000000000e+00 -0.000000000000e+00 0.000000000000e+00" />
			<geometry>
				<cylinder radius="0.059999999999999998" length="0.10000000000000001" />
			</geometry>
		</collision>
		<collision>
			<origin xyz="2.240000000000e-01 -2.355675654542e-13 2.355600159376e-13" rpy="1.570796326793e+00 -3.463840325679e-12 1.570796326793e+00" />
			<geometry>
				<cylinder radius="0.059999999999999998" length="0.27200000000000002" />
			</geometry>
		</collision>
		<inertial>
			<mass value="2.0721599999999998" />
			<origin xyz="2.611300000000e-02 1.589920000000e-03 -1.116950000000e-02" />
			<inertia ixx="0.00711585" ixy="0.00036037200000000003" ixz="0.00074587999999999998" iyy="0.0131827" iyz="-0.000196632" izz="0.00926891" />
		</inertial>
	</link>
	<joint name="left_e1" type="revolute">
		<parent link="left_upper_elbow" />
		<child link="left_lower_elbow" />
		<origin xyz="6.900000000000e-02 -5.207564381840e-17 2.624200000000e-01" rpy="-1.570796326795e+00 -1.570796326795e+00 0.000000000000e+00" />
		<axis xyz="0.000000000000e+00 0.000000000000e+00 1.000000000000e+00" />
		<limit lower="-0.050000017878208354" upper="2.6179938779914944" velocity="1.5000005363462507" effort="50" />
	</joint>
	<xacro:gz_trans_pos joint_name="left_e1" />
	<link name="left_upper_forearm">
		<visual>
			<geometry>
				<mesh filename="../meshes/meshes_baxter/_left_upper_forearm.dae" />
			</geometry>
		</visual>
		<collision>
			<origin xyz="0.000000000000e+00 0.000000000000e+00 -4.400000000000e-02" rpy="0.000000000000e+00 -0.000000000000e+00 0.000000000000e+00" />
			<geometry>
				<cylinder radius="0.059999999999999998" length="0.087999999999999995" />
			</geometry>
		</collision>
		<inertial>
			<mass value="2.24675" />
			<origin xyz="-1.682440000000e-03 4.599800000000e-03 1.395190000000e-01" />
			<inertia ixx="0.016677500000000001" ixy="0.000184012" ixz="0.00018646900000000001" iyy="0.0167549" iyz="-0.00064733200000000003" izz="0.00374662" />
		</inertial>
	</link>
	<joint name="left_w0" type="revolute">
		<parent link="left_lower_elbow" />
		<child link="left_upper_forearm" />
		<origin xyz="1.035900000000e-01 3.851859888774e-34 1.387778780781e-17" rpy="1.570796326795e+00 1.110223024625e-16 1.570796326795e+00" />
		<axis xyz="0.000000000000e+00 0.000000000000e+00 1.000000000000e+00" />
		<limit lower="-3.0590036733854213" upper="3.0590036733854213" velocity="3.9999979395981642" effort="15" />
	</joint>
	<xacro:gz_trans_pos joint_name="left_w0" />
	<link name="left_lower_forearm">
		<visual>
			<geometry>
				<mesh filename="../meshes/meshes_baxter/_left_lower_forearm.dae" />
			</geometry>
		</visual>
		<collision>
			<origin xyz="0.000000000000e+00 0.000000000000e+00 0.000000000000e+00" rpy="0.000000000000e+00 -0.000000000000e+00 0.000000000000e+00" />
			<geometry>
				<cylinder radius="0.059999999999999998" length="0.10000000000000001" />
			</geometry>
		</collision>
		<inertial>
			<mass value="1.6097900000000001" />
			<origin xyz="6.041000000000e-02 6.970000000000e-03 6.000000000000e-03" />
			<inertia ixx="0.0038760700000000001" ixy="-0.000443848" ixz="-0.00021115000000000001" iyy="0.0070053800000000003" iyz="0.00015348099999999999" izz="0.00552755" />
		</inertial>
	</link>
	<joint name="left_w1" type="revolute">
		<parent link="left_upper_forearm" />
		<child link="left_lower_forearm" />
		<origin xyz="1.000000000000e-02 -5.501325160621e-17 2.707000000000e-01" rpy="-1.570796326795e+00 -1.570796326795e+00 0.000000000000e+00" />
		<axis xyz="0.000000000000e+00 0.000000000000e+00 1.000000000000e+00" />
		<limit lower="-1.5707963267948966" upper="2.0939936766652369" velocity="3.9999979395981642" effort="15" />
	</joint>
	<xacro:gz_trans_pos joint_name="left_w1" />
	<link name="left_wrist">
		<visual>
			<origin xyz="3.825000000000e-02 1.200000000000e-02 1.289050000000e-01" rpy="0.000000000000e+00 -0.000000000000e+00 -1.570796329999e+00" />
			<geometry>
				<cylinder radius="0.02" length="0.01" />
			</geometry>
			<material name="mat__7">
				<color rgba="0 0 1 0.8" />
			</material>
		</visual>
		<visual>
			<origin xyz="3.200000000000e-02 -2.024500000000e-02 1.423500000000e-01" rpy="-1.570796326793e+00 -1.570796326791e+00 0.000000000000e+00" />
			<geometry>
				<box size="5.000000000000e-03 2.000000000000e-02 5.000000000000e-03" />
			</geometry>
			<material name="mat__8">
				<color rgba="0 0 1 0.8" />
			</material>
		</visual>
		<visual>
			<origin xyz="1.980000000000e-03 1.330000000000e-04 9.895000000000e-02" rpy="0.000000000000e+00 -0.000000000000e+00 0.000000000000e+00" />
			<geometry>
				<box size="1.000000000000e-02 1.000000000000e-02 1.000000000000e-02" />
			</geometry>
			<material name="mat__9">
				<color rgba="0 0 0 1" />
			</material>
		</visual>
		<visual>
			<geometry>
				<mesh filename="../meshes/meshes_baxter/_left_wrist.dae" />
			</geometry>
		</visual>
		<collision>
			<origin xyz="0.000000000000e+00 0.000000000000e+00 0.000000000000e+00" rpy="0.000000000000e+00 -0.000000000000e+00 0.000000000000e+00" />
			<geometry>
				<cylinder radius="0.059999999999999998" length="0.16500000000000001" />
			</geometry>
		</collision>
		<collision>
			<origin xyz="0.000000000000e+00 0.000000000000e+00 9.035000000000e-02" rpy="0.000000000000e+00 -0.000000000000e+00 0.000000000000e+00" />
			<geometry>
				<cylinder radius="0.040000000000000001" length="0.046399999999999997" />
			</geometry>
		</collision>
		<collision>
			<origin xyz="0.000000000000e+00 0.000000000000e+00 1.385500000000e-01" rpy="1.570796326799e+00 -1.034981491603e-13 3.141592653590e+00" />
			<geometry>
				<cylinder radius="0.029000000000000001" length="0.10000000000000001" />
			</geometry>
		</collision>
		<inertial>
			<mass value="0.84267999999999998" />
			<origin xyz="3.318280000000e-03 6.163390000000e-04 7.943500000000e-02" />
			<inertia ixx="0.0028505900000000001" ixy="7.17373e-06" ixz="2.52032e-05" iyy="0.00291735" iyz="2.1735299999999998e-05" izz="0.00056060799999999998" />
		</inertial>
	</link>
	<joint name="left_w2" type="revolute">
		<parent link="left_lower_forearm" />
		<child link="left_wrist" />
		<origin xyz="1.159750000000e-01 -2.311115933265e-33 6.938893903907e-18" rpy="1.570796326795e+00 1.110223024625e-16 1.570796326795e+00" />
		<axis xyz="0.000000000000e+00 0.000000000000e+00 1.000000000000e+00" />
		<limit lower="-3.0590036733854213" upper="3.0590036733854213" velocity="3.9999979395981642" effort="15" />
	</joint>
	<xacro:gz_trans_pos joint_name="left_w2" />
	<link name="l_gripper_l_finger">
		<visual>
			<geometry>
				<mesh filename="../meshes/meshes_baxter/_l_gripper_l_finger.dae" />
			</geometry>
		</visual>
		<collision>
			<origin xyz="0.000000000000e+00 1.725000000000e-02 6.150000000000e-02" rpy="0.000000000000e+00 -0.000000000000e+00 3.141592653590e+00" />
			<geometry>
				<box size="1.000000000000e-02 1.350000000000e-02 1.127000000000e-01" />
			</geometry>
		</collision>
		<collision>
			<origin xyz="-5.000000000000e-03 -3.000000000000e-03 8.300000000000e-03" rpy="0.000000000000e+00 -0.000000000000e+00 3.141592653590e+00" />
			<geometry>
				<box size="1.000000000000e-02 5.000000000000e-02 1.700000000000e-02" />
			</geometry>
		</collision>
		<collision>
			<origin xyz="0.000000000000e+00 1.275000000000e-02 9.770000000000e-02" rpy="0.000000000000e+00 -0.000000000000e+00 -3.141592653590e+00" />
			<geometry>
				<box size="4.200000000000e-02 6.500000000000e-03 3.700000000000e-02" />
			</geometry>
		</collision>
		<inertial>
			<mass value="0.029999999999999999" />
			<origin xyz="0.000000000000e+00 5.750000000000e-03 3.756670000000e-02" />
			<inertia ixx="0.020086699999999999" ixy="0" ixz="0" iyy="0.0200847" iyz="-1.2960500000000001e-05" izz="0.020001999999999999" />
		</inertial>
	</link>
	<joint name="l_gripper_l_finger_joint" type="prismatic">
		<parent link="left_wrist" />
		<child link="l_gripper_l_finger" />
		<origin xyz="1.767727099919e-17 -1.500000000000e-03 1.585500000000e-01" rpy="0.000000000000e+00 8.628166150855e-32 -1.232595164408e-32" />
		<axis xyz="0.000000000000e+00 1.000000000000e+00 0.000000000000e+00" />
		<limit lower="0" upper="0.020833000000000001" velocity="5" effort="20" />
	</joint>
	<xacro:gz_trans_pos joint_name="l_gripper_l_finger_joint" />
	<link name="l_gripper_r_finger">
		<visual>
			<geometry>
				<mesh filename="../meshes/meshes_baxter/_l_gripper_r_finger.dae" />
			</geometry>
		</visual>
		<collision>
			<origin xyz="0.000000000000e+00 -1.725000000000e-02 6.150000000000e-02" rpy="0.000000000000e+00 -0.000000000000e+00 0.000000000000e+00" />
			<geometry>
				<box size="1.000000000000e-02 1.350000000000e-02 1.127000000000e-01" />
			</geometry>
		</collision>
		<collision>
			<origin xyz="5.000000000000e-03 3.000000000000e-03 8.300000000000e-03" rpy="0.000000000000e+00 -0.000000000000e+00 0.000000000000e+00" />
			<geometry>
				<box size="1.000000000000e-02 5.000000000000e-02 1.700000000000e-02" />
			</geometry>
		</collision>
		<collision>
			<origin xyz="0.000000000000e+00 -1.275000000000e-02 9.770000000000e-02" rpy="0.000000000000e+00 -0.000000000000e+00 0.000000000000e+00" />
			<geometry>
				<box size="4.200000000000e-02 6.500000000000e-03 3.700000000000e-02" />
			</geometry>
		</collision>
		<inertial>
			<mass value="0.029999999999999999" />
			<origin xyz="0.000000000000e+00 -5.750000000000e-03 3.756670000000e-02" />
			<inertia ixx="0.020086699999999999" ixy="0" ixz="0" iyy="0.0200847" iyz="1.2960500000000001e-05" izz="0.020001999999999999" />
		</inertial>
	</link>
	<joint name="l_gripper_r_finger_joint" type="prismatic">
		<parent link="left_wrist" />
		<child link="l_gripper_r_finger" />
		<origin xyz="1.752790111167e-17 1.500000000000e-03 1.585500000000e-01" rpy="0.000000000000e+00 8.628166150855e-32 -1.232595164408e-32" />
		<axis xyz="0.000000000000e+00 1.000000000000e+00 0.000000000000e+00" />
		<limit lower="-0.020833000000000001" upper="0" velocity="5" effort="20" />
	</joint>
	<xacro:gz_trans_pos joint_name="l_gripper_r_finger_joint" />
</robot>
