<?xml version="1.0"?>
<robot name="" xmlns:xi="http://www.w3.org/2001/Xinclude" xmlns:gazebo="http://playerstage.sourceforge.net/gazebo/xmlschema/#gz" xmlns:model="http://playerstage.sourceforge.net/gazebo/xmlschema/#model" xmlns:sensor="http://playerstage.sourceforge.net/gazebo/xmlschema/#sensor" xmlns:body="http://playerstage.sourceforge.net/gazebo/xmlschema/#body" xmlns:geom="http://playerstage.sourceforge.net/gazebo/xmlschema/#geom" xmlns:joint="http://playerstage.sourceforge.net/gazebo/xmlschema/#joint" xmlns:interface="http://playerstage.sourceforge.net/gazebo/xmlschema/#interface" xmlns:rendering="http://playerstage.sourceforge.net/gazebo/xmlschema/#rendering" xmlns:renderable="http://playerstage.sourceforge.net/gazebo/xmlschema/#renderable" xmlns:controller="http://playerstage.sourceforge.net/gazebo/xmlschema/#controller" xmlns:physics="http://playerstage.sourceforge.net/gazebo/xmlschema/#physics" xmlns:xacro="http://www.ros.org/wiki/xacro">
 <xacro:macro name="gz_trans_pos" params="joint_name">
  <transmission name="${joint_name}_trans">
   <type>transmission_interface/SimpleTransmission</type>
   <joint name="${joint_name}">
    <hardwareInterface>hardware_interface/PositionJointInterface</hardwareInterface>
   </joint>
   <actuator name="${joint_name}_motor">
    <hardwareInterface>hardware_interface/PositionJointInterface</hardwareInterface>
   </actuator>
  </transmission>
 </xacro:macro>
 <xacro:macro name="gz_trans_vel" params="joint_name">
  <transmission name="${joint_name}_trans">
   <type>transmission_interface/SimpleTransmission</type>
   <joint name="${joint_name}">
    <hardwareInterface>hardware_interface/VelocityJointInterface</hardwareInterface>
   </joint>
   <actuator name="${joint_name}_motor">
    <hardwareInterface>hardware_interface/VelocityJointInterface</hardwareInterface>
   </actuator>
  </transmission>
 </xacro:macro>
 <xacro:macro name="gz_trans_eff" params="joint_name">
  <transmission name="${joint_name}_trans">
   <type>transmission_interface/SimpleTransmission</type>
   <joint name="${joint_name}">
    <hardwareInterface>hardware_interface/EffortJointInterface</hardwareInterface>
   </joint>
   <actuator name="${joint_name}_motor">
    <hardwareInterface>hardware_interface/EffortJointInterface</hardwareInterface>
   </actuator>
  </transmission>
 </xacro:macro>
 <link name="base">
  <visual>
   <origin xyz="3.800000000000e-02 6.245000000000e-02 1.727000000000e-01" rpy="3.141592653590e+00 -1.224646799147e-16 3.141592653590e+00" />
   <geometry>
    <box size="5.800000000000e-02 5.800000000000e-02 2.200000000000e-02" />
   </geometry>
   <material name="mat__0">
    <color rgba="1 0.423529 0.0392157 1" />
   </material>
  </visual>
  <visual>
   <geometry>
    <mesh filename="file:///tmp/_base.dae" />
   </geometry>
  </visual>
  <collision>
   <origin xyz="0.000000000000e+00 0.000000000000e+00 8.000000000000e-02" rpy="0.000000000000e+00 -0.000000000000e+00 0.000000000000e+00" />
   <geometry>
    <box size="5.310000000000e-01 2.700000000000e-01 2.400000000000e-01" />
   </geometry>
  </collision>
  <collision>
   <origin xyz="2.270000000000e-01 1.160000000000e-01 0.000000000000e+00" rpy="-0.000000000000e+00 1.570796326790e+00 0.000000000000e+00" />
   <geometry>
    <cylinder radius="0.050000000000000003" length="0.10000000000000001" />
   </geometry>
  </collision>
  <collision>
   <origin xyz="2.270000000000e-01 -1.160000000000e-01 0.000000000000e+00" rpy="-0.000000000000e+00 1.570796326790e+00 0.000000000000e+00" />
   <geometry>
    <cylinder radius="0.050000000000000003" length="0.10000000000000001" />
   </geometry>
  </collision>
  <collision>
   <origin xyz="-2.270000000000e-01 1.160000000000e-01 0.000000000000e+00" rpy="-0.000000000000e+00 1.570796326790e+00 0.000000000000e+00" />
   <geometry>
    <cylinder radius="0.050000000000000003" length="0.10000000000000001" />
   </geometry>
  </collision>
  <collision>
   <origin xyz="-2.270000000000e-01 -1.160000000000e-01 0.000000000000e+00" rpy="-0.000000000000e+00 1.570796326790e+00 0.000000000000e+00" />
   <geometry>
    <cylinder radius="0.050000000000000003" length="0.10000000000000001" />
   </geometry>
  </collision>
  <collision>
   <origin xyz="2.155000000000e-01 0.000000000000e+00 -9.000000000000e-02" rpy="0.000000000000e+00 -0.000000000000e+00 0.000000000000e+00" />
   <geometry>
    <box size="1.000000000000e-01 1.000000000000e-01 7.000000000000e-02" />
   </geometry>
  </collision>
  <collision>
   <origin xyz="-2.155000000000e-01 0.000000000000e+00 -9.000000000000e-02" rpy="0.000000000000e+00 -0.000000000000e+00 0.000000000000e+00" />
   <geometry>
    <box size="1.000000000000e-01 1.000000000000e-01 7.000000000000e-02" />
   </geometry>
  </collision>
  <collision>
   <origin xyz="0.000000000000e+00 0.000000000000e+00 -9.000000000000e-02" rpy="0.000000000000e+00 -0.000000000000e+00 0.000000000000e+00" />
   <geometry>
    <box size="5.310000000000e-01 2.000000000000e-02 7.000000000000e-02" />
   </geometry>
  </collision>
  <collision>
   <origin xyz="3.800000000000e-02 6.245000000000e-02 1.727000000000e-01" rpy="3.141592653590e+00 -1.224646799147e-16 3.141592653590e+00" />
   <geometry>
    <box size="5.800000000000e-02 5.800000000000e-02 2.200000000000e-02" />
   </geometry>
   <material name="mat__1">
    <color rgba="1 0.423529 0.0392157 1" />
   </material>
  </collision>
  <inertial>
   <mass value="16.843499999999999" />
   <origin xyz="-1.841940000000e-03 -1.223640000000e-03 5.060340000000e-02" />
   <inertia ixx="0.2185" ixy="-0.00145495" ixz="-0.0025469300000000002" iyy="0.64043000000000005" iyz="-0.00180478" izz="0.62444100000000002" />
  </inertial>
 </link>
 <link name="LF_HIP">
  <visual>
   <geometry>
    <mesh filename="file:///tmp/_LF_HIP.dae" />
   </geometry>
  </visual>
  <collision>
   <origin xyz="6.350000000000e-02 -9.000000000000e-03 0.000000000000e+00" rpy="1.570796326790e+00 -0.000000000000e+00 0.000000000000e+00" />
   <geometry>
    <cylinder radius="0.080000000000000002" length="0.10000000000000001" />
   </geometry>
  </collision>
  <collision>
   <origin xyz="6.350000000000e-02 -7.400000000000e-02 0.000000000000e+00" rpy="1.570796326790e+00 -0.000000000000e+00 0.000000000000e+00" />
   <geometry>
    <cylinder radius="0.044999999999999998" length="0.029999999999999999" />
   </geometry>
  </collision>
  <inertial>
   <mass value="1.42462" />
   <origin xyz="6.451630000000e-02 -3.787100000000e-03 -1.521840000000e-04" />
   <inertia ixx="0.0024302299999999998" ixy="-1.5302400000000001e-05" ixz="-2.1819099999999999e-05" iyy="0.0023025699999999999" iyz="2.6472999999999999e-05" izz="0.0019806799999999999" />
  </inertial>
 </link>
 <joint name="LF_HAA" type="revolute">
  <parent link="base" />
  <child link="LF_HIP" />
  <origin xyz="2.770000000000e-01 1.160000000000e-01 0.000000000000e+00" rpy="0.000000000000e+00 -0.000000000000e+00 0.000000000000e+00" />
  <axis xyz="1.000000000000e+00 0.000000000000e+00 0.000000000000e+00" />
  <limit lower="-9.4199957586189154" upper="9.4199957586189154" velocity="15.000005363462506" effort="80" />
 </joint>
 <xacro:gz_trans_pos joint_name="LF_HAA" />
 <link name="LF_THIGH">
  <visual>
   <geometry>
    <mesh filename="file:///tmp/_LF_THIGH.dae" />
   </geometry>
  </visual>
  <collision>
   <origin xyz="0.000000000000e+00 3.500000000000e-02 -1.250000000000e-01" rpy="1.450000000001e-01 -0.000000000000e+00 0.000000000000e+00" />
   <geometry>
    <box size="8.000000000000e-02 4.000000000000e-02 2.500000000000e-01" />
   </geometry>
  </collision>
  <collision>
   <origin xyz="0.000000000000e+00 6.900000000000e-02 -2.500000000000e-01" rpy="1.570796326790e+00 -0.000000000000e+00 0.000000000000e+00" />
   <geometry>
    <cylinder radius="0.059999999999999998" length="0.12" />
   </geometry>
  </collision>
  <collision>
   <origin xyz="0.000000000000e+00 -5.000000000000e-03 0.000000000000e+00" rpy="1.715796326790e+00 -0.000000000000e+00 0.000000000000e+00" />
   <geometry>
    <cylinder radius="0.066000000000000003" length="0.12" />
   </geometry>
  </collision>
  <inertial>
   <mass value="1.6349800000000001" />
   <origin xyz="-3.897970000000e-03 5.422660000000e-02 -2.145830000000e-01" />
   <inertia ixx="0.0120368" ixy="6.7620700000000001e-05" ixz="0.00028780599999999999" iyy="0.012064399999999999" iyz="-0.0014061" izz="0.0024942300000000001" />
  </inertial>
 </link>
 <joint name="LF_HFE" type="revolute">
  <parent link="LF_HIP" />
  <child link="LF_THIGH" />
  <origin xyz="6.350000000000e-02 4.100000000000e-02 0.000000000000e+00" rpy="0.000000000000e+00 -0.000000000000e+00 0.000000000000e+00" />
  <axis xyz="0.000000000000e+00 1.000000000000e+00 0.000000000000e+00" />
  <limit lower="-9.4199957586189154" upper="9.4199957586189154" velocity="15.000005363462506" effort="80" />
 </joint>
 <xacro:gz_trans_pos joint_name="LF_HFE" />
 <link name="LF_SHANK">
  <visual>
   <geometry>
    <mesh filename="file:///tmp/_LF_SHANK.dae" />
   </geometry>
  </visual>
  <collision>
   <origin xyz="6.500000000000e-02 -1.500000000000e-02 1.000000000000e-02" rpy="-0.000000000000e+00 1.570796326790e+00 0.000000000000e+00" />
   <geometry>
    <box size="8.000000000000e-02 7.000000000000e-02 1.300000000000e-01" />
   </geometry>
  </collision>
  <collision>
   <origin xyz="1.000000000000e-01 -2.000000000000e-02 -1.606250000000e-01" rpy="0.000000000000e+00 -0.000000000000e+00 0.000000000000e+00" />
   <geometry>
    <cylinder radius="0.014999999999999999" length="0.32124999999999998" />
   </geometry>
  </collision>
  <collision>
   <origin xyz="1.000000000000e-01 -2.000000000000e-02 -2.980000000000e-01" rpy="0.000000000000e+00 -0.000000000000e+00 0.000000000000e+00" />
   <geometry>
    <sphere radius="0.031" />
   </geometry>
  </collision>
  <inertial>
   <mass value="0.34837499999999999" />
   <origin xyz="5.885170000000e-02 -1.085070000000e-02 -9.870490000000e-02" />
   <inertia ixx="0.0069083800000000004" ixy="3.2606600000000001e-05" ixz="0.0014378699999999999" iyy="0.0077561699999999997" iyz="-0.00031827899999999998" izz="0.00102169" />
  </inertial>
 </link>
 <joint name="LF_KFE" type="revolute">
  <parent link="LF_THIGH" />
  <child link="LF_SHANK" />
  <origin xyz="0.000000000000e+00 1.090000000000e-01 -2.500000000000e-01" rpy="0.000000000000e+00 -0.000000000000e+00 0.000000000000e+00" />
  <axis xyz="0.000000000000e+00 1.000000000000e+00 0.000000000000e+00" />
  <limit lower="-9.4199957586189154" upper="9.4199957586189154" velocity="15.000005363462506" effort="80" />
 </joint>
 <xacro:gz_trans_pos joint_name="LF_KFE" />
 <link name="RF_HIP">
  <visual>
   <geometry>
    <mesh filename="file:///tmp/_RF_HIP.dae" />
   </geometry>
  </visual>
  <collision>
   <origin xyz="6.350000000000e-02 9.000000000000e-03 0.000000000000e+00" rpy="1.570796326790e+00 -0.000000000000e+00 0.000000000000e+00" />
   <geometry>
    <cylinder radius="0.080000000000000002" length="0.10000000000000001" />
   </geometry>
  </collision>
  <collision>
   <origin xyz="6.350000000000e-02 7.400000000000e-02 0.000000000000e+00" rpy="1.570796326790e+00 -0.000000000000e+00 0.000000000000e+00" />
   <geometry>
    <cylinder radius="0.044999999999999998" length="0.029999999999999999" />
   </geometry>
  </collision>
  <inertial>
   <mass value="1.42462" />
   <origin xyz="6.451630000000e-02 3.787100000000e-03 -1.521840000000e-04" />
   <inertia ixx="0.0024302299999999998" ixy="1.5302400000000001e-05" ixz="-2.1819099999999999e-05" iyy="0.0023025699999999999" iyz="-2.6472999999999999e-05" izz="0.0019806799999999999" />
  </inertial>
 </link>
 <joint name="RF_HAA" type="revolute">
  <parent link="base" />
  <child link="RF_HIP" />
  <origin xyz="2.770000000000e-01 -1.160000000000e-01 0.000000000000e+00" rpy="0.000000000000e+00 -0.000000000000e+00 0.000000000000e+00" />
  <axis xyz="1.000000000000e+00 0.000000000000e+00 0.000000000000e+00" />
  <limit lower="-9.4199957586189154" upper="9.4199957586189154" velocity="15.000005363462506" effort="80" />
 </joint>
 <xacro:gz_trans_pos joint_name="RF_HAA" />
 <link name="RF_THIGH">
  <visual>
   <geometry>
    <mesh filename="file:///tmp/_RF_THIGH.dae" />
   </geometry>
  </visual>
  <collision>
   <origin xyz="0.000000000000e+00 -3.500000000000e-02 -1.250000000000e-01" rpy="-1.450000000001e-01 -0.000000000000e+00 0.000000000000e+00" />
   <geometry>
    <box size="8.000000000000e-02 4.000000000000e-02 2.500000000000e-01" />
   </geometry>
  </collision>
  <collision>
   <origin xyz="0.000000000000e+00 -6.900000000000e-02 -2.500000000000e-01" rpy="1.570796326790e+00 -0.000000000000e+00 0.000000000000e+00" />
   <geometry>
    <cylinder radius="0.059999999999999998" length="0.12" />
   </geometry>
  </collision>
  <collision>
   <origin xyz="0.000000000000e+00 5.000000000000e-03 0.000000000000e+00" rpy="-1.715796326790e+00 -0.000000000000e+00 0.000000000000e+00" />
   <geometry>
    <cylinder radius="0.066000000000000003" length="0.12" />
   </geometry>
  </collision>
  <inertial>
   <mass value="1.6349800000000001" />
   <origin xyz="-3.897970000000e-03 -5.422660000000e-02 -2.145830000000e-01" />
   <inertia ixx="0.0120368" ixy="-6.7620700000000001e-05" ixz="0.00028780599999999999" iyy="0.012064399999999999" iyz="0.0014061" izz="0.0024942300000000001" />
  </inertial>
 </link>
 <joint name="RF_HFE" type="revolute">
  <parent link="RF_HIP" />
  <child link="RF_THIGH" />
  <origin xyz="6.350000000000e-02 -4.100000000000e-02 0.000000000000e+00" rpy="0.000000000000e+00 -0.000000000000e+00 0.000000000000e+00" />
  <axis xyz="0.000000000000e+00 1.000000000000e+00 0.000000000000e+00" />
  <limit lower="-9.4199957586189154" upper="9.4199957586189154" velocity="15.000005363462506" effort="80" />
 </joint>
 <xacro:gz_trans_pos joint_name="RF_HFE" />
 <link name="RF_SHANK">
  <visual>
   <geometry>
    <mesh filename="file:///tmp/_RF_SHANK.dae" />
   </geometry>
  </visual>
  <collision>
   <origin xyz="6.500000000000e-02 1.500000000000e-02 1.000000000000e-02" rpy="-0.000000000000e+00 1.570796326790e+00 0.000000000000e+00" />
   <geometry>
    <box size="8.000000000000e-02 7.000000000000e-02 1.300000000000e-01" />
   </geometry>
  </collision>
  <collision>
   <origin xyz="1.000000000000e-01 2.000000000000e-02 -1.606250000000e-01" rpy="0.000000000000e+00 -0.000000000000e+00 0.000000000000e+00" />
   <geometry>
    <cylinder radius="0.014999999999999999" length="0.32124999999999998" />
   </geometry>
  </collision>
  <collision>
   <origin xyz="1.000000000000e-01 2.000000000000e-02 -2.980000000000e-01" rpy="0.000000000000e+00 -0.000000000000e+00 0.000000000000e+00" />
   <geometry>
    <sphere radius="0.031" />
   </geometry>
  </collision>
  <inertial>
   <mass value="0.34837499999999999" />
   <origin xyz="5.885170000000e-02 1.085070000000e-02 -9.870490000000e-02" />
   <inertia ixx="0.0069083800000000004" ixy="-3.2606600000000001e-05" ixz="0.0014378699999999999" iyy="0.0077561699999999997" iyz="0.00031827899999999998" izz="0.00102169" />
  </inertial>
 </link>
 <joint name="RF_KFE" type="revolute">
  <parent link="RF_THIGH" />
  <child link="RF_SHANK" />
  <origin xyz="0.000000000000e+00 -1.090000000000e-01 -2.500000000000e-01" rpy="0.000000000000e+00 -0.000000000000e+00 0.000000000000e+00" />
  <axis xyz="0.000000000000e+00 1.000000000000e+00 0.000000000000e+00" />
  <limit lower="-9.4199957586189154" upper="9.4199957586189154" velocity="15.000005363462506" effort="80" />
 </joint>
 <xacro:gz_trans_pos joint_name="RF_KFE" />
 <link name="LH_HIP">
  <visual>
   <geometry>
    <mesh filename="file:///tmp/_LH_HIP.dae" />
   </geometry>
  </visual>
  <collision>
   <origin xyz="-6.350000000000e-02 -9.000000000000e-03 0.000000000000e+00" rpy="-1.570796326790e+00 -0.000000000000e+00 0.000000000000e+00" />
   <geometry>
    <cylinder radius="0.080000000000000002" length="0.10000000000000001" />
   </geometry>
  </collision>
  <collision>
   <origin xyz="-6.350000000000e-02 -7.400000000000e-02 0.000000000000e+00" rpy="-1.570796326790e+00 -0.000000000000e+00 0.000000000000e+00" />
   <geometry>
    <cylinder radius="0.044999999999999998" length="0.029999999999999999" />
   </geometry>
  </collision>
  <inertial>
   <mass value="1.42462" />
   <origin xyz="-6.451630000000e-02 -3.787100000000e-03 -1.521840000000e-04" />
   <inertia ixx="0.0024302299999999998" ixy="1.5302400000000001e-05" ixz="2.1819099999999999e-05" iyy="0.0023025699999999999" iyz="2.6472999999999999e-05" izz="0.0019806799999999999" />
  </inertial>
 </link>
 <joint name="LH_HAA" type="revolute">
  <parent link="base" />
  <child link="LH_HIP" />
  <origin xyz="-2.770000000000e-01 1.160000000000e-01 0.000000000000e+00" rpy="0.000000000000e+00 -0.000000000000e+00 0.000000000000e+00" />
  <axis xyz="1.000000000000e+00 0.000000000000e+00 0.000000000000e+00" />
  <limit lower="-9.4199957586189154" upper="9.4199957586189154" velocity="15.000005363462506" effort="80" />
 </joint>
 <xacro:gz_trans_pos joint_name="LH_HAA" />
 <link name="LH_THIGH">
  <visual>
   <geometry>
    <mesh filename="file:///tmp/_LH_THIGH.dae" />
   </geometry>
  </visual>
  <collision>
   <origin xyz="0.000000000000e+00 3.500000000000e-02 -1.250000000000e-01" rpy="1.450000000001e-01 -0.000000000000e+00 0.000000000000e+00" />
   <geometry>
    <box size="8.000000000000e-02 4.000000000000e-02 2.500000000000e-01" />
   </geometry>
  </collision>
  <collision>
   <origin xyz="0.000000000000e+00 6.900000000000e-02 -2.500000000000e-01" rpy="1.570796326790e+00 -0.000000000000e+00 0.000000000000e+00" />
   <geometry>
    <cylinder radius="0.059999999999999998" length="0.12" />
   </geometry>
  </collision>
  <collision>
   <origin xyz="0.000000000000e+00 -5.000000000000e-03 0.000000000000e+00" rpy="1.715796326790e+00 -0.000000000000e+00 0.000000000000e+00" />
   <geometry>
    <cylinder radius="0.066000000000000003" length="0.12" />
   </geometry>
  </collision>
  <inertial>
   <mass value="1.6349800000000001" />
   <origin xyz="3.897970000000e-03 5.422660000000e-02 -2.145830000000e-01" />
   <inertia ixx="0.0120368" ixy="-6.7620700000000001e-05" ixz="-0.00028780599999999999" iyy="0.012064399999999999" iyz="-0.0014061" izz="0.0024942300000000001" />
  </inertial>
 </link>
 <joint name="LH_HFE" type="revolute">
  <parent link="LH_HIP" />
  <child link="LH_THIGH" />
  <origin xyz="-6.350000000000e-02 4.100000000000e-02 0.000000000000e+00" rpy="0.000000000000e+00 -0.000000000000e+00 0.000000000000e+00" />
  <axis xyz="0.000000000000e+00 1.000000000000e+00 0.000000000000e+00" />
  <limit lower="-9.4199957586189154" upper="9.4199957586189154" velocity="15.000005363462506" effort="80" />
 </joint>
 <xacro:gz_trans_pos joint_name="LH_HFE" />
 <link name="LH_SHANK">
  <visual>
   <geometry>
    <mesh filename="file:///tmp/_LH_SHANK.dae" />
   </geometry>
  </visual>
  <collision>
   <origin xyz="-6.500000000000e-02 -1.500000000000e-02 1.000000000000e-02" rpy="-0.000000000000e+00 1.570796326790e+00 0.000000000000e+00" />
   <geometry>
    <box size="8.000000000000e-02 7.000000000000e-02 1.300000000000e-01" />
   </geometry>
  </collision>
  <collision>
   <origin xyz="-1.000000000000e-01 -2.000000000000e-02 -1.606250000000e-01" rpy="0.000000000000e+00 -0.000000000000e+00 0.000000000000e+00" />
   <geometry>
    <cylinder radius="0.014999999999999999" length="0.32124999999999998" />
   </geometry>
  </collision>
  <collision>
   <origin xyz="-1.000000000000e-01 -2.000000000000e-02 -2.980000000000e-01" rpy="0.000000000000e+00 -0.000000000000e+00 0.000000000000e+00" />
   <geometry>
    <sphere radius="0.031" />
   </geometry>
  </collision>
  <inertial>
   <mass value="0.34837499999999999" />
   <origin xyz="-5.885170000000e-02 -1.085070000000e-02 -9.870490000000e-02" />
   <inertia ixx="0.0069083800000000004" ixy="-3.2606600000000001e-05" ixz="-0.0014378699999999999" iyy="0.0077561699999999997" iyz="-0.00031827899999999998" izz="0.00102169" />
  </inertial>
 </link>
 <joint name="LH_KFE" type="revolute">
  <parent link="LH_THIGH" />
  <child link="LH_SHANK" />
  <origin xyz="0.000000000000e+00 1.090000000000e-01 -2.500000000000e-01" rpy="0.000000000000e+00 -0.000000000000e+00 0.000000000000e+00" />
  <axis xyz="0.000000000000e+00 1.000000000000e+00 0.000000000000e+00" />
  <limit lower="-9.4199957586189154" upper="9.4199957586189154" velocity="15.000005363462506" effort="80" />
 </joint>
 <xacro:gz_trans_pos joint_name="LH_KFE" />
 <link name="RH_HIP">
  <visual>
   <geometry>
    <mesh filename="file:///tmp/_RH_HIP.dae" />
   </geometry>
  </visual>
  <collision>
   <origin xyz="-6.350000000000e-02 9.000000000000e-03 0.000000000000e+00" rpy="-1.570796326790e+00 -0.000000000000e+00 0.000000000000e+00" />
   <geometry>
    <cylinder radius="0.080000000000000002" length="0.10000000000000001" />
   </geometry>
  </collision>
  <collision>
   <origin xyz="-6.350000000000e-02 7.400000000000e-02 0.000000000000e+00" rpy="-1.570796326790e+00 -0.000000000000e+00 0.000000000000e+00" />
   <geometry>
    <cylinder radius="0.044999999999999998" length="0.029999999999999999" />
   </geometry>
  </collision>
  <inertial>
   <mass value="1.42462" />
   <origin xyz="-6.451630000000e-02 3.787100000000e-03 -1.521840000000e-04" />
   <inertia ixx="0.0024302299999999998" ixy="-1.5302400000000001e-05" ixz="2.1819099999999999e-05" iyy="0.0023025699999999999" iyz="-2.6472999999999999e-05" izz="0.0019806799999999999" />
  </inertial>
 </link>
 <joint name="RH_HAA" type="revolute">
  <parent link="base" />
  <child link="RH_HIP" />
  <origin xyz="-2.770000000000e-01 -1.160000000000e-01 0.000000000000e+00" rpy="0.000000000000e+00 -0.000000000000e+00 0.000000000000e+00" />
  <axis xyz="1.000000000000e+00 0.000000000000e+00 0.000000000000e+00" />
  <limit lower="-9.4199957586189154" upper="9.4199957586189154" velocity="15.000005363462506" effort="80" />
 </joint>
 <xacro:gz_trans_pos joint_name="RH_HAA" />
 <link name="RH_THIGH">
  <visual>
   <geometry>
    <mesh filename="file:///tmp/_RH_THIGH.dae" />
   </geometry>
  </visual>
  <collision>
   <origin xyz="0.000000000000e+00 -3.500000000000e-02 -1.250000000000e-01" rpy="-1.450000000001e-01 -0.000000000000e+00 0.000000000000e+00" />
   <geometry>
    <box size="8.000000000000e-02 4.000000000000e-02 2.500000000000e-01" />
   </geometry>
  </collision>
  <collision>
   <origin xyz="0.000000000000e+00 -6.900000000000e-02 -2.500000000000e-01" rpy="1.570796326790e+00 -0.000000000000e+00 0.000000000000e+00" />
   <geometry>
    <cylinder radius="0.059999999999999998" length="0.12" />
   </geometry>
  </collision>
  <collision>
   <origin xyz="0.000000000000e+00 5.000000000000e-03 0.000000000000e+00" rpy="-1.715796326790e+00 -0.000000000000e+00 0.000000000000e+00" />
   <geometry>
    <cylinder radius="0.066000000000000003" length="0.12" />
   </geometry>
  </collision>
  <inertial>
   <mass value="1.6349800000000001" />
   <origin xyz="3.897970000000e-03 -5.422660000000e-02 -2.145830000000e-01" />
   <inertia ixx="0.0120368" ixy="6.7620700000000001e-05" ixz="-0.00028780599999999999" iyy="0.012064399999999999" iyz="0.0014061" izz="0.0024942300000000001" />
  </inertial>
 </link>
 <joint name="RH_HFE" type="revolute">
  <parent link="RH_HIP" />
  <child link="RH_THIGH" />
  <origin xyz="-6.350000000000e-02 -4.100000000000e-02 0.000000000000e+00" rpy="0.000000000000e+00 -0.000000000000e+00 0.000000000000e+00" />
  <axis xyz="0.000000000000e+00 1.000000000000e+00 0.000000000000e+00" />
  <limit lower="-9.4199957586189154" upper="9.4199957586189154" velocity="15.000005363462506" effort="80" />
 </joint>
 <xacro:gz_trans_pos joint_name="RH_HFE" />
 <link name="RH_SHANK">
  <visual>
   <geometry>
    <mesh filename="file:///tmp/_RH_SHANK.dae" />
   </geometry>
  </visual>
  <collision>
   <origin xyz="-6.500000000000e-02 1.500000000000e-02 1.000000000000e-02" rpy="-0.000000000000e+00 1.570796326790e+00 0.000000000000e+00" />
   <geometry>
    <box size="8.000000000000e-02 7.000000000000e-02 1.300000000000e-01" />
   </geometry>
  </collision>
  <collision>
   <origin xyz="-1.000000000000e-01 2.000000000000e-02 -1.606250000000e-01" rpy="0.000000000000e+00 -0.000000000000e+00 0.000000000000e+00" />
   <geometry>
    <cylinder radius="0.014999999999999999" length="0.32124999999999998" />
   </geometry>
  </collision>
  <collision>
   <origin xyz="-1.000000000000e-01 2.000000000000e-02 -2.980000000000e-01" rpy="0.000000000000e+00 -0.000000000000e+00 0.000000000000e+00" />
   <geometry>
    <sphere radius="0.031" />
   </geometry>
  </collision>
  <inertial>
   <mass value="0.34837499999999999" />
   <origin xyz="-5.885170000000e-02 1.085070000000e-02 -9.870490000000e-02" />
   <inertia ixx="0.0069083800000000004" ixy="3.2606600000000001e-05" ixz="-0.0014378699999999999" iyy="0.0077561699999999997" iyz="0.00031827899999999998" izz="0.00102169" />
  </inertial>
 </link>
 <joint name="RH_KFE" type="revolute">
  <parent link="RH_THIGH" />
  <child link="RH_SHANK" />
  <origin xyz="0.000000000000e+00 -1.090000000000e-01 -2.500000000000e-01" rpy="0.000000000000e+00 -0.000000000000e+00 0.000000000000e+00" />
  <axis xyz="0.000000000000e+00 1.000000000000e+00 0.000000000000e+00" />
  <limit lower="-9.4199957586189154" upper="9.4199957586189154" velocity="15.000005363462506" effort="80" />
 </joint>
 <xacro:gz_trans_pos joint_name="RH_KFE" />
</robot>

