<?xml version="1.0"?>
<robot name="" xmlns:xi="http://www.w3.org/2001/Xinclude" xmlns:gazebo="http://playerstage.sourceforge.net/gazebo/xmlschema/#gz" xmlns:model="http://playerstage.sourceforge.net/gazebo/xmlschema/#model" xmlns:sensor="http://playerstage.sourceforge.net/gazebo/xmlschema/#sensor" xmlns:body="http://playerstage.sourceforge.net/gazebo/xmlschema/#body" xmlns:geom="http://playerstage.sourceforge.net/gazebo/xmlschema/#geom" xmlns:joint="http://playerstage.sourceforge.net/gazebo/xmlschema/#joint" xmlns:interface="http://playerstage.sourceforge.net/gazebo/xmlschema/#interface" xmlns:rendering="http://playerstage.sourceforge.net/gazebo/xmlschema/#rendering" xmlns:renderable="http://playerstage.sourceforge.net/gazebo/xmlschema/#renderable" xmlns:controller="http://playerstage.sourceforge.net/gazebo/xmlschema/#controller" xmlns:physics="http://playerstage.sourceforge.net/gazebo/xmlschema/#physics" xmlns:xacro="http://www.ros.org/wiki/xacro">
 <xacro:macro name="gz_trans_pos" params="joint_name">
  <transmission name="${joint_name}_trans">
   <type>transmission_interface/SimpleTransmission</type>
   <joint name="${joint_name}">
    <hardwareInterface>hardware_interface/PositionJointInterface</hardwareInterface>
   </joint>
   <actuator name="${joint_name}_motor">
    <hardwareInterface>hardware_interface/PositionJointInterface</hardwareInterface>
   </actuator>
  </transmission>
 </xacro:macro>
 <xacro:macro name="gz_trans_vel" params="joint_name">
  <transmission name="${joint_name}_trans">
   <type>transmission_interface/SimpleTransmission</type>
   <joint name="${joint_name}">
    <hardwareInterface>hardware_interface/VelocityJointInterface</hardwareInterface>
   </joint>
   <actuator name="${joint_name}_motor">
    <hardwareInterface>hardware_interface/VelocityJointInterface</hardwareInterface>
   </actuator>
  </transmission>
 </xacro:macro>
 <xacro:macro name="gz_trans_eff" params="joint_name">
  <transmission name="${joint_name}_trans">
   <type>transmission_interface/SimpleTransmission</type>
   <joint name="${joint_name}">
    <hardwareInterface>hardware_interface/EffortJointInterface</hardwareInterface>
   </joint>
   <actuator name="${joint_name}_motor">
    <hardwareInterface>hardware_interface/EffortJointInterface</hardwareInterface>
   </actuator>
  </transmission>
 </xacro:macro>
 <link name="base">
  <visual>
   <origin xyz="2.488000000000e-01 8.350000000000e-03 5.128000000000e-02" rpy="0.000000000000e+00 -0.000000000000e+00 1.570796326790e+00" />
   <geometry>
    <box size="2.400000000000e-02 2.400000000000e-02 1.000000000000e-02" />
   </geometry>
  </visual>
  <visual>
   <geometry>
    <mesh filename="file:///tmp/_base.dae" />
   </geometry>
  </visual>
  <collision>
   <origin xyz="0.000000000000e+00 0.000000000000e+00 0.000000000000e+00" rpy="0.000000000000e+00 -0.000000000000e+00 0.000000000000e+00" />
   <geometry>
    <box size="5.800000000000e-01 1.400000000000e-01 1.800000000000e-01" />
   </geometry>
  </collision>
  <collision>
   <origin xyz="2.175000000000e-01 7.000000000000e-02 0.000000000000e+00" rpy="-0.000000000000e+00 1.570796326790e+00 0.000000000000e+00" />
   <geometry>
    <cylinder radius="0.089999999999999997" length="0.14499999999999999" />
   </geometry>
  </collision>
  <collision>
   <origin xyz="-2.175000000000e-01 7.000000000000e-02 0.000000000000e+00" rpy="-0.000000000000e+00 1.570796326790e+00 0.000000000000e+00" />
   <geometry>
    <cylinder radius="0.089999999999999997" length="0.14499999999999999" />
   </geometry>
  </collision>
  <collision>
   <origin xyz="2.175000000000e-01 -7.000000000000e-02 0.000000000000e+00" rpy="-0.000000000000e+00 1.570796326790e+00 0.000000000000e+00" />
   <geometry>
    <cylinder radius="0.089999999999999997" length="0.14499999999999999" />
   </geometry>
  </collision>
  <collision>
   <origin xyz="-2.175000000000e-01 -7.000000000000e-02 0.000000000000e+00" rpy="-0.000000000000e+00 1.570796326790e+00 0.000000000000e+00" />
   <geometry>
    <cylinder radius="0.089999999999999997" length="0.14499999999999999" />
   </geometry>
  </collision>
  <collision>
   <origin xyz="4.695000000000e-01 0.000000000000e+00 0.000000000000e+00" rpy="0.000000000000e+00 -0.000000000000e+00 0.000000000000e+00" />
   <geometry>
    <box size="1.100000000000e-01 1.400000000000e-01 1.800000000000e-01" />
   </geometry>
  </collision>
  <collision>
   <origin xyz="4.695000000000e-01 7.000000000000e-02 0.000000000000e+00" rpy="-0.000000000000e+00 1.570796326790e+00 0.000000000000e+00" />
   <geometry>
    <cylinder radius="0.089999999999999997" length="0.11" />
   </geometry>
  </collision>
  <collision>
   <origin xyz="4.695000000000e-01 -7.000000000000e-02 0.000000000000e+00" rpy="-0.000000000000e+00 1.570796326790e+00 0.000000000000e+00" />
   <geometry>
    <cylinder radius="0.089999999999999997" length="0.11" />
   </geometry>
  </collision>
  <collision>
   <origin xyz="-4.695000000000e-01 -6.735557395310e-18 0.000000000000e+00" rpy="0.000000000000e+00 -0.000000000000e+00 -3.141592653590e+00" />
   <geometry>
    <box size="1.100000000000e-01 1.400000000000e-01 1.800000000000e-01" />
   </geometry>
  </collision>
  <collision>
   <origin xyz="-4.695000000000e-01 -7.000000000000e-02 0.000000000000e+00" rpy="3.141592653590e+00 1.570796326790e+00 0.000000000000e+00" />
   <geometry>
    <cylinder radius="0.089999999999999997" length="0.11" />
   </geometry>
  </collision>
  <collision>
   <origin xyz="-4.695000000000e-01 7.000000000000e-02 0.000000000000e+00" rpy="3.141592653590e+00 1.570796326790e+00 0.000000000000e+00" />
   <geometry>
    <cylinder radius="0.089999999999999997" length="0.11" />
   </geometry>
  </collision>
  <collision>
   <origin xyz="2.488000000000e-01 8.350000000000e-03 5.128000000000e-02" rpy="0.000000000000e+00 -0.000000000000e+00 1.570796326790e+00" />
   <geometry>
    <box size="2.400000000000e-02 2.400000000000e-02 1.000000000000e-02" />
   </geometry>
  </collision>
  <collision>
   <origin xyz="-3.640000000000e-01 0.000000000000e+00 1.335000000000e-01" rpy="0.000000000000e+00 -0.000000000000e+00 0.000000000000e+00" />
   <geometry>
    <cylinder radius="0.070000000000000007" length="0.12" />
   </geometry>
  </collision>
  <inertial>
   <mass value="27.3733" />
   <origin xyz="-1.714380000000e-02 -1.716600000000e-04 8.193540000000e-03" />
   <inertia ixx="1.21678" ixy="0.0092199900000000008" ixz="0.059079" iyy="2.7855599999999998" iyz="-0.000162318" izz="2.8340299999999998" />
  </inertial>
 </link>
 <link name="LF_HIP">
  <visual>
   <geometry>
    <mesh filename="file:///tmp/_LF_HIP.dae" />
   </geometry>
  </visual>
  <collision>
   <origin xyz="5.989999999961e-02 -1.195981082617e-02 -6.905000000135e-03" rpy="-3.141592653586e+00 -1.047197551192e+00 -1.570796326793e+00" />
   <geometry>
    <cylinder radius="0.050000000000000003" length="0.14000000000000001" />
   </geometry>
  </collision>
  <inertial>
   <mass value="2.7810000000000001" />
   <origin xyz="5.666060000000e-02 -1.529400000000e-02 -8.297840000000e-03" />
   <inertia ixx="0.0032955300000000001" ixy="-1.03882e-05" ixz="0.000107062" iyy="0.0050443500000000004" iyz="-0.000319492" izz="0.0057269" />
  </inertial>
 </link>
 <joint name="LF_HAA" type="revolute">
  <parent link="base" />
  <child link="LF_HIP" />
  <origin xyz="2.999000000000e-01 1.040000000000e-01 0.000000000000e+00" rpy="2.617993877991e+00 -0.000000000000e+00 0.000000000000e+00" />
  <axis xyz="1.000000000000e+00 0.000000000000e+00 0.000000000000e+00" />
  <limit lower="-0.7200006763252208" upper="0.489999442168156" velocity="7.4999939550849932" effort="80" />
 </joint>
 <xacro:gz_trans_pos joint_name="LF_HAA" />
 <link name="LF_THIGH">
  <visual>
   <geometry>
    <mesh filename="file:///tmp/_LF_THIGH.dae" />
   </geometry>
  </visual>
  <collision>
   <origin xyz="4.000000000000e-02 2.094438024431e-13 0.000000000000e+00" rpy="1.570796326790e+00 -0.000000000000e+00 -1.570796326790e+00" />
   <geometry>
    <cylinder radius="0.065000000000000002" length="0.080000000000000002" />
   </geometry>
  </collision>
  <collision>
   <origin xyz="3.000000000000e-02 1.570828518323e-13 -1.413135000000e-01" rpy="0.000000000000e+00 -0.000000000000e+00 -1.570796326790e+00" />
   <geometry>
    <box size="7.500000000000e-02 6.000000000000e-02 2.826270000000e-01" />
   </geometry>
  </collision>
  <collision>
   <origin xyz="3.030000000000e-02 4.911278626730e-13 -2.850000000000e-01" rpy="-0.000000000000e+00 1.570796326790e+00 0.000000000000e+00" />
   <geometry>
    <cylinder radius="0.050000000000000003" length="0.14000000000000001" />
   </geometry>
  </collision>
  <inertial>
   <mass value="3.0710000000000002" />
   <origin xyz="3.081470000000e-02 4.649950000000e-05 -2.456960000000e-01" />
   <inertia ixx="0.029563800000000001" ixy="4.4291900000000002e-05" ixz="0.0041424299999999999" iyy="0.029904" iyz="9.4480000000000003e-05" izz="0.0048610800000000003" />
  </inertial>
 </link>
 <joint name="LF_HFE" type="revolute">
  <parent link="LF_HIP" />
  <child link="LF_THIGH" />
  <origin xyz="5.990000000000e-02 -7.258160000000e-02 -4.190500000000e-02" rpy="-3.141586942772e+00 5.236039963493e-01 -1.570794796570e+00" />
  <axis xyz="1.000000000000e+00 0.000000000000e+00 0.000000000000e+00" />
  <limit lower="-9.4247779607693793" upper="9.4247779607693793" velocity="7.4999939550849932" effort="80" />
 </joint>
 <xacro:gz_trans_pos joint_name="LF_HFE" />
 <link name="LF_SHANK">
  <visual>
   <geometry>
    <mesh filename="file:///tmp/_LF_SHANK.dae" />
   </geometry>
  </visual>
  <collision>
   <origin xyz="2.000000000000e-02 1.047219012215e-13 0.000000000000e+00" rpy="1.570796326790e+00 -0.000000000000e+00 -1.570796326790e+00" />
   <geometry>
    <cylinder radius="0.059999999999999998" length="0.040000000000000001" />
   </geometry>
  </collision>
  <collision>
   <origin xyz="2.000000000030e-02 -5.749899999990e-02 0.000000000000e+00" rpy="1.570796326790e+00 -0.000000000000e+00 -1.570796326790e+00" />
   <geometry>
    <box size="1.149980000000e-01 6.750000000000e-02 4.000000000000e-02" />
   </geometry>
  </collision>
  <collision>
   <origin xyz="1.305000000040e-02 -8.794999999990e-02 -1.689850000000e-01" rpy="0.000000000000e+00 -0.000000000000e+00 -1.570796326790e+00" />
   <geometry>
    <cylinder radius="0.017500000000000002" length="0.28250399999999998" />
   </geometry>
  </collision>
  <collision>
   <origin xyz="1.305000000040e-02 -8.794999999990e-02 -3.154700000000e-01" rpy="0.000000000000e+00 -0.000000000000e+00 -1.570796326790e+00" />
   <geometry>
    <sphere radius="0.029999999999999999" />
   </geometry>
  </collision>
  <inertial>
   <mass value="0.58842000000000005" />
   <origin xyz="5.462000000000e-03 -6.125280000000e-02 -8.065980000000e-02" />
   <inertia ixx="0.010161099999999999" ixy="-5.35713e-05" ixz="-2.2660400000000001e-05" iyy="0.0088103799999999996" iyz="-0.00181935" izz="0.00154978" />
  </inertial>
 </link>
 <joint name="LF_KFE" type="revolute">
  <parent link="LF_THIGH" />
  <child link="LF_SHANK" />
  <origin xyz="1.003000000000e-01 4.912429478769e-13 -2.850000000000e-01" rpy="-1.842855702023e-16 -1.598091729105e-16 6.877620602622e-16" />
  <axis xyz="1.000000000000e+00 0.000000000000e+00 0.000000000000e+00" />
  <limit lower="-9.4247779607693793" upper="9.4247779607693793" velocity="7.4999939550849932" effort="80" />
 </joint>
 <xacro:gz_trans_pos joint_name="LF_KFE" />
 <link name="RF_HIP">
  <visual>
   <geometry>
    <mesh filename="file:///tmp/_RF_HIP.dae" />
   </geometry>
  </visual>
  <collision>
   <origin xyz="5.989999999961e-02 1.195981082617e-02 -6.905000000135e-03" rpy="3.141592653586e+00 -1.047197551192e+00 1.570796326793e+00" />
   <geometry>
    <cylinder radius="0.050000000000000003" length="0.14000000000000001" />
   </geometry>
  </collision>
  <inertial>
   <mass value="2.7810000000000001" />
   <origin xyz="5.676330000000e-02 1.529400000000e-02 -8.297840000000e-03" />
   <inertia ixx="0.0032955300000000001" ixy="-1.1005299999999999e-05" ixz="-0.000109121" iyy="0.00504617" iyz="0.000319492" izz="0.0057287199999999996" />
  </inertial>
 </link>
 <joint name="RF_HAA" type="revolute">
  <parent link="base" />
  <child link="RF_HIP" />
  <origin xyz="2.999000000000e-01 -1.040000000000e-01 0.000000000000e+00" rpy="-2.617993877991e+00 -0.000000000000e+00 0.000000000000e+00" />
  <axis xyz="1.000000000000e+00 0.000000000000e+00 0.000000000000e+00" />
  <limit lower="-0.489999442168156" upper="0.7200006763252208" velocity="7.4999939550849932" effort="80" />
 </joint>
 <xacro:gz_trans_pos joint_name="RF_HAA" />
 <link name="RF_THIGH">
  <visual>
   <geometry>
    <mesh filename="file:///tmp/_RF_THIGH.dae" />
   </geometry>
  </visual>
  <collision>
   <origin xyz="4.000000000000e-02 -2.094438024431e-13 0.000000000000e+00" rpy="1.570796326790e+00 -0.000000000000e+00 1.570796326790e+00" />
   <geometry>
    <cylinder radius="0.065000000000000002" length="0.080000000000000002" />
   </geometry>
  </collision>
  <collision>
   <origin xyz="3.000000000000e-02 -1.570828518323e-13 -1.413135000000e-01" rpy="0.000000000000e+00 -0.000000000000e+00 1.570796326790e+00" />
   <geometry>
    <box size="7.500000000000e-02 6.000000000000e-02 2.826270000000e-01" />
   </geometry>
  </collision>
  <collision>
   <origin xyz="3.030000000000e-02 -4.911278626730e-13 -2.850000000000e-01" rpy="-0.000000000000e+00 1.570796326790e+00 0.000000000000e+00" />
   <geometry>
    <cylinder radius="0.050000000000000003" length="0.14000000000000001" />
   </geometry>
  </collision>
  <inertial>
   <mass value="3.0710000000000002" />
   <origin xyz="3.081470000000e-02 4.649950000000e-05 -2.456960000000e-01" />
   <inertia ixx="0.029563800000000001" ixy="4.43959e-05" ixz="0.0041424299999999999" iyy="0.029904" iyz="0.000114794" izz="0.0048610800000000003" />
  </inertial>
 </link>
 <joint name="RF_HFE" type="revolute">
  <parent link="RF_HIP" />
  <child link="RF_THIGH" />
  <origin xyz="5.990000000000e-02 7.258160000000e-02 -4.190500000000e-02" rpy="3.141586942772e+00 5.236039963493e-01 1.570794796570e+00" />
  <axis xyz="-1.000000000000e+00 0.000000000000e+00 0.000000000000e+00" />
  <limit lower="-9.4247779607693793" upper="9.4247779607693793" velocity="7.4999939550849932" effort="80" />
 </joint>
 <xacro:gz_trans_pos joint_name="RF_HFE" />
 <link name="RF_SHANK">
  <visual>
   <geometry>
    <mesh filename="file:///tmp/_RF_SHANK.dae" />
   </geometry>
  </visual>
  <collision>
   <origin xyz="2.000000000000e-02 -1.047219012215e-13 0.000000000000e+00" rpy="1.570796326790e+00 -0.000000000000e+00 1.570796326790e+00" />
   <geometry>
    <cylinder radius="0.059999999999999998" length="0.040000000000000001" />
   </geometry>
  </collision>
  <collision>
   <origin xyz="2.000000000030e-02 5.749899999990e-02 0.000000000000e+00" rpy="1.570796326790e+00 -0.000000000000e+00 1.570796326790e+00" />
   <geometry>
    <box size="1.149980000000e-01 6.750000000000e-02 4.000000000000e-02" />
   </geometry>
  </collision>
  <collision>
   <origin xyz="1.305000000040e-02 8.794999999990e-02 -1.689850000000e-01" rpy="0.000000000000e+00 -0.000000000000e+00 1.570796326790e+00" />
   <geometry>
    <cylinder radius="0.017500000000000002" length="0.28250399999999998" />
   </geometry>
  </collision>
  <collision>
   <origin xyz="1.305000000040e-02 8.794999999990e-02 -3.154700000000e-01" rpy="0.000000000000e+00 -0.000000000000e+00 1.570796326790e+00" />
   <geometry>
    <sphere radius="0.029999999999999999" />
   </geometry>
  </collision>
  <inertial>
   <mass value="0.58842000000000005" />
   <origin xyz="5.462000000000e-03 6.125280000000e-02 -8.065980000000e-02" />
   <inertia ixx="0.010161099999999999" ixy="5.35713e-05" ixz="-2.2660400000000001e-05" iyy="0.0088103799999999996" iyz="0.00181935" izz="0.00154978" />
  </inertial>
 </link>
 <joint name="RF_KFE" type="revolute">
  <parent link="RF_THIGH" />
  <child link="RF_SHANK" />
  <origin xyz="1.003000000000e-01 -4.912429478769e-13 -2.850000000000e-01" rpy="1.842855702023e-16 -1.598091729105e-16 -6.877620602622e-16" />
  <axis xyz="-1.000000000000e+00 0.000000000000e+00 0.000000000000e+00" />
  <limit lower="-9.4247779607693793" upper="9.4247779607693793" velocity="7.4999939550849932" effort="80" />
 </joint>
 <xacro:gz_trans_pos joint_name="RF_KFE" />
 <link name="LH_HIP">
  <visual>
   <geometry>
    <mesh filename="file:///tmp/_LH_HIP.dae" />
   </geometry>
  </visual>
  <collision>
   <origin xyz="5.990000000030e-02 1.195981082622e-02 -6.905000000039e-03" rpy="-3.141592653586e+00 -1.047197551190e+00 1.570796326795e+00" />
   <geometry>
    <cylinder radius="0.050000000000000003" length="0.14000000000000001" />
   </geometry>
  </collision>
  <inertial>
   <mass value="2.7810000000000001" />
   <origin xyz="5.676330000000e-02 1.529400000000e-02 -8.297840000000e-03" />
   <inertia ixx="0.0032955300000000001" ixy="-1.1005299999999999e-05" ixz="-0.000109121" iyy="0.00504617" iyz="0.000319492" izz="0.0057287199999999996" />
  </inertial>
 </link>
 <joint name="LH_HAA" type="revolute">
  <parent link="base" />
  <child link="LH_HIP" />
  <origin xyz="-2.999000000000e-01 1.040000000000e-01 0.000000000000e+00" rpy="-2.617994055042e+00 5.158746483581e-14 3.141592653590e+00" />
  <axis xyz="-1.000000000000e+00 0.000000000000e+00 0.000000000000e+00" />
  <limit lower="-0.7200006763252208" upper="0.489999442168156" velocity="7.4999939550849932" effort="80" />
 </joint>
 <xacro:gz_trans_pos joint_name="LH_HAA" />
 <link name="LH_THIGH">
  <visual>
   <geometry>
    <mesh filename="file:///tmp/_LH_THIGH.dae" />
   </geometry>
  </visual>
  <collision>
   <origin xyz="4.000000000000e-02 2.094438024431e-13 0.000000000000e+00" rpy="1.570796326790e+00 -0.000000000000e+00 -1.570796326790e+00" />
   <geometry>
    <cylinder radius="0.065000000000000002" length="0.080000000000000002" />
   </geometry>
  </collision>
  <collision>
   <origin xyz="3.000000000000e-02 1.570828518323e-13 -1.413135000000e-01" rpy="0.000000000000e+00 -0.000000000000e+00 -1.570796326790e+00" />
   <geometry>
    <box size="7.500000000000e-02 6.000000000000e-02 2.826270000000e-01" />
   </geometry>
  </collision>
  <collision>
   <origin xyz="3.030000000000e-02 4.911278626730e-13 -2.850000000000e-01" rpy="-0.000000000000e+00 1.570796326790e+00 0.000000000000e+00" />
   <geometry>
    <cylinder radius="0.050000000000000003" length="0.14000000000000001" />
   </geometry>
  </collision>
  <inertial>
   <mass value="3.0710000000000002" />
   <origin xyz="3.081470000000e-02 4.649950000000e-05 -2.456960000000e-01" />
   <inertia ixx="0.029563800000000001" ixy="4.43959e-05" ixz="0.0041424299999999999" iyy="0.029904" iyz="0.000114794" izz="0.0048610800000000003" />
  </inertial>
 </link>
 <joint name="LH_HFE" type="revolute">
  <parent link="LH_HIP" />
  <child link="LH_THIGH" />
  <origin xyz="5.990000000000e-02 7.258160000000e-02 -4.190500000000e-02" rpy="3.141586942772e+00 5.236039963493e-01 1.570794796570e+00" />
  <axis xyz="1.000000000000e+00 0.000000000000e+00 0.000000000000e+00" />
  <limit lower="-9.4247779607693793" upper="9.4247779607693793" velocity="7.4999939550849932" effort="80" />
 </joint>
 <xacro:gz_trans_pos joint_name="LH_HFE" />
 <link name="LH_SHANK">
  <visual>
   <geometry>
    <mesh filename="file:///tmp/_LH_SHANK.dae" />
   </geometry>
  </visual>
  <collision>
   <origin xyz="2.000000000000e-02 1.047219012215e-13 0.000000000000e+00" rpy="1.570796326790e+00 -0.000000000000e+00 -1.570796326790e+00" />
   <geometry>
    <cylinder radius="0.059999999999999998" length="0.040000000000000001" />
   </geometry>
  </collision>
  <collision>
   <origin xyz="1.999999999970e-02 5.749900000010e-02 0.000000000000e+00" rpy="1.570796326790e+00 -0.000000000000e+00 -1.570796326790e+00" />
   <geometry>
    <box size="1.149980000000e-01 6.750000000000e-02 4.000000000000e-02" />
   </geometry>
  </collision>
  <collision>
   <origin xyz="1.304999999960e-02 8.795000000010e-02 -1.689850000000e-01" rpy="0.000000000000e+00 -0.000000000000e+00 -1.570796326790e+00" />
   <geometry>
    <cylinder radius="0.017500000000000002" length="0.28250399999999998" />
   </geometry>
  </collision>
  <collision>
   <origin xyz="1.304999999960e-02 8.795000000010e-02 -3.154700000000e-01" rpy="0.000000000000e+00 -0.000000000000e+00 -1.570796326790e+00" />
   <geometry>
    <sphere radius="0.029999999999999999" />
   </geometry>
  </collision>
  <inertial>
   <mass value="0.58842000000000005" />
   <origin xyz="5.462000000000e-03 6.125280000000e-02 -8.065980000000e-02" />
   <inertia ixx="0.010161099999999999" ixy="5.35713e-05" ixz="-2.2660400000000001e-05" iyy="0.0088103799999999996" iyz="0.00181935" izz="0.00154978" />
  </inertial>
 </link>
 <joint name="LH_KFE" type="revolute">
  <parent link="LH_THIGH" />
  <child link="LH_SHANK" />
  <origin xyz="1.003000000000e-01 4.910036504814e-13 -2.850000000000e-01" rpy="1.842864172353e-16 -4.899138483509e-16 -6.877618074939e-16" />
  <axis xyz="1.000000000000e+00 0.000000000000e+00 0.000000000000e+00" />
  <limit lower="-9.4247779607693793" upper="9.4247779607693793" velocity="7.4999939550849932" effort="80" />
 </joint>
 <xacro:gz_trans_pos joint_name="LH_KFE" />
 <link name="RH_HIP">
  <visual>
   <geometry>
    <mesh filename="file:///tmp/_RH_HIP.dae" />
   </geometry>
  </visual>
  <collision>
   <origin xyz="5.990000000039e-02 -1.195981082622e-02 -6.905000000051e-03" rpy="3.141592653585e+00 -1.047197551191e+00 -1.570796326796e+00" />
   <geometry>
    <cylinder radius="0.050000000000000003" length="0.14000000000000001" />
   </geometry>
  </collision>
  <inertial>
   <mass value="2.7810000000000001" />
   <origin xyz="5.666060000000e-02 -1.529400000000e-02 -8.297840000000e-03" />
   <inertia ixx="0.0032955300000000001" ixy="-1.03882e-05" ixz="0.000107062" iyy="0.0050443500000000004" iyz="-0.000319492" izz="0.0057269" />
  </inertial>
 </link>
 <joint name="RH_HAA" type="revolute">
  <parent link="base" />
  <child link="RH_HIP" />
  <origin xyz="-2.999000000000e-01 -1.040000000000e-01 0.000000000000e+00" rpy="2.617994055042e+00 -5.158746483581e-14 3.141592653590e+00" />
  <axis xyz="-1.000000000000e+00 0.000000000000e+00 0.000000000000e+00" />
  <limit lower="-0.489999442168156" upper="0.7200006763252208" velocity="7.4999939550849932" effort="80" />
 </joint>
 <xacro:gz_trans_pos joint_name="RH_HAA" />
 <link name="RH_THIGH">
  <visual>
   <geometry>
    <mesh filename="file:///tmp/_RH_THIGH.dae" />
   </geometry>
  </visual>
  <collision>
   <origin xyz="4.000000000000e-02 -2.094438024431e-13 0.000000000000e+00" rpy="1.570796326790e+00 -0.000000000000e+00 1.570796326790e+00" />
   <geometry>
    <cylinder radius="0.065000000000000002" length="0.080000000000000002" />
   </geometry>
  </collision>
  <collision>
   <origin xyz="3.000000000000e-02 -1.570828518323e-13 -1.413135000000e-01" rpy="0.000000000000e+00 -0.000000000000e+00 1.570796326790e+00" />
   <geometry>
    <box size="7.500000000000e-02 6.000000000000e-02 2.826270000000e-01" />
   </geometry>
  </collision>
  <collision>
   <origin xyz="3.030000000000e-02 -4.911278626730e-13 -2.850000000000e-01" rpy="-0.000000000000e+00 1.570796326790e+00 0.000000000000e+00" />
   <geometry>
    <cylinder radius="0.050000000000000003" length="0.14000000000000001" />
   </geometry>
  </collision>
  <inertial>
   <mass value="3.0710000000000002" />
   <origin xyz="3.081470000000e-02 4.649950000000e-05 -2.456960000000e-01" />
   <inertia ixx="0.029563800000000001" ixy="4.4291900000000002e-05" ixz="0.0041424299999999999" iyy="0.029904" iyz="9.4480000000000003e-05" izz="0.0048610800000000003" />
  </inertial>
 </link>
 <joint name="RH_HFE" type="revolute">
  <parent link="RH_HIP" />
  <child link="RH_THIGH" />
  <origin xyz="5.990000000000e-02 -7.258160000000e-02 -4.190500000000e-02" rpy="-3.141586942772e+00 5.236039963493e-01 -1.570794796570e+00" />
  <axis xyz="-1.000000000000e+00 0.000000000000e+00 0.000000000000e+00" />
  <limit lower="-9.4247779607693793" upper="9.4247779607693793" velocity="7.4999939550849932" effort="80" />
 </joint>
 <xacro:gz_trans_pos joint_name="RH_HFE" />
 <link name="RH_SHANK">
  <visual>
   <geometry>
    <mesh filename="file:///tmp/_RH_SHANK.dae" />
   </geometry>
  </visual>
  <collision>
   <origin xyz="2.000000000000e-02 -1.047219012215e-13 0.000000000000e+00" rpy="1.570796326790e+00 -0.000000000000e+00 1.570796326790e+00" />
   <geometry>
    <cylinder radius="0.059999999999999998" length="0.040000000000000001" />
   </geometry>
  </collision>
  <collision>
   <origin xyz="1.999999999970e-02 -5.749900000010e-02 0.000000000000e+00" rpy="1.570796326790e+00 -0.000000000000e+00 1.570796326790e+00" />
   <geometry>
    <box size="1.149980000000e-01 6.750000000000e-02 4.000000000000e-02" />
   </geometry>
  </collision>
  <collision>
   <origin xyz="1.304999999960e-02 -8.795000000010e-02 -1.689850000000e-01" rpy="0.000000000000e+00 -0.000000000000e+00 1.570796326790e+00" />
   <geometry>
    <cylinder radius="0.017500000000000002" length="0.28250399999999998" />
   </geometry>
  </collision>
  <collision>
   <origin xyz="1.304999999960e-02 -8.795000000010e-02 -3.154700000000e-01" rpy="0.000000000000e+00 -0.000000000000e+00 1.570796326790e+00" />
   <geometry>
    <sphere radius="0.029999999999999999" />
   </geometry>
  </collision>
  <inertial>
   <mass value="0.58842000000000005" />
   <origin xyz="5.462000000000e-03 -6.125280000000e-02 -8.065980000000e-02" />
   <inertia ixx="0.010161099999999999" ixy="-5.35713e-05" ixz="-2.2660400000000001e-05" iyy="0.0088103799999999996" iyz="-0.00181935" izz="0.00154978" />
  </inertial>
 </link>
 <joint name="RH_KFE" type="revolute">
  <parent link="RH_THIGH" />
  <child link="RH_SHANK" />
  <origin xyz="1.003000000000e-01 -4.909945848995e-13 -2.850000000000e-01" rpy="-1.842864172353e-16 -4.918233760558e-16 6.877618144700e-16" />
  <axis xyz="-1.000000000000e+00 0.000000000000e+00 0.000000000000e+00" />
  <limit lower="-9.4247779607693793" upper="9.4247779607693793" velocity="7.4999939550849932" effort="80" />
 </joint>
 <xacro:gz_trans_pos joint_name="RH_KFE" />
</robot>

